Workbook

Sheet Variable_List
B2: Variable | C2: Description | D2: Unit | E2: Comment
B3: Primary Production | C3: Domestic primary production of resources | D3: PJ/yr.
B4: Imports | C4: Imports of energy carriers | D4: PJ/yr.
B5: Exports | C5: Exports of energy carriers | D5: PJ/yr.
B6: Electricity generation | C6: Domestic electricity generation | D6: PJ/yr.
B7: Heat generation from CHPs and heat plants | C7: Domestic heat production from CHPs (District heating CHPs or onsite CHPs) and heat plants | D7: PJ/yr.
B8: Fuel input for electricity generation | C8: Fuel input allocated to domestic electricity generation only | D8: PJ/yr.
B9: Fuel input for heat generation from CHPs and heat plants | C9: Fuel input allocated to domestic heat production from CHPs and heat plants only | D9: PJ/yr.
B10: Efficiency of power plants (electric) | C10: Average annual efficiency of power plants and CHPs for electricity production only | D10: % | E10: The thermal efficiency of CHPs can be inferred from the Heat to Electricity production ratio, but it can also be provided; the average efficiency differs from the technical efficiency as it includes efficiency losses due to part load operation
B11: Efficiency of heat plants (thermal) | C11: Average annual efficiency of heat plants | D11: % | E11: It is the annual marketed efficiency including part load efficiency losses and differs from the full load nominal technical efficiency; for heat pumps refers to COP
B12: Domestic biodiesel production | C12: Domestic production of biodiesel | D12: PJ/yr.
B13: Heat from domestic biodiesel production | C13: Heat produced as byproduct from biodiesel production and fed into the district heating network | D13: PJ/yr.
B14: Fuel input for domestic biodiesel production | C14: Fuel input for the domestic production of biodiesel | D14: PJ/yr.
B15: Efficiency for domestic biodiesel production | C15: Average annual efficiency for biodiesel and heat production | D15: %
B16: Domestic ethanol production | C16: Domestic production of ethanol | D16: PJ/yr.
B17: Fuel input for domestic ethanol production | C17: Fuel input for the domestic production of ethanol | D17: PJ/yr.
B18: Efficiency for domestic ethanol production | C18: Average annual efficiency for domestic production of ethanol | D18: %
B19: Domestic biogas production | C19: Domestic production of biogas and biogenic syngas | D19: PJ/yr.
B20: Electricity from domestic biogas production | C20: Electriicty produced as byproduct from biogas production and fed into the grid | D20: PJ/yr.
B21: Heat from domestic biogas production | C21: Heat produced as byproduct from biogas production and fed into the district heating network | D21: PJ/yr.
B22: Fuel input for domestic biogas production | C22: Fuel input for domestic biogas production | D22: PJ/yr.
B23: Efficiency for domestic biogas production | C23: Average annual efficiency for biogas production (accounting for byproduct production) | D23: %
... B25: Fuel input for hydrogen production | C25: Fuel input for deomstic hydrogen production | D25: PJ/yr.
B26: Efficiency for hydrogen production | C26: Average annual efficiency for hydrogen production | D26: % | E26: Including losses due to part load operation
B27: Biomethane production from biogas upgrade | C27: Production of domestic biomethane from biogas | D27: PJ/yr. | E27: One technology only fuel output is biomethane
B28: Fuel input for biogas upgrade to biomethane | C28: Use of biogas for upgrade to biomethane | D28: PJ/yr. | E28: One technology only fuel input is biogas
B29: Efficiency for biomethane production from biogas upgrade | C29: Average annual efficiency of biogas to biomethane upgrade | D29: PJ/yr. | E29: One technology only fuel input is biogas, fuel output is biomethane
B30: Domestic PtG and PtL production | C30: Domestic production of power-to-gas and power-to-liquids | D30: PJ/yr.
B31: Fuel input for domestic PtG and PtL production | C31: Fuel used for domestic PtG and PtL production (excl. CO2) | D31: PJ/yr.
B32: Efficiency for domestic PtG and PtL production | C32: Average annual efficiency for PtG and PtL processes (excl. CO2 consumption) | D32: %
B33: CO2 input for domestic PtG and PtL production | C33: CO2 input for domestic PtG and PtL production | D33: Mt/yr. | E33: The distinction of the source of CO2 (biogenic or fossil) is also provided and can be proportionally allocated to the technologies for PtG and PtL
B34: Domestic wood to pellet production | C34: Wood conversion to pellet domestic production output | D34: PJ/yr. | E34: One technology only , input is wood output is pellet
B35: Fuel input for wood to pellet production | C35: Wood conversion to pellet domestic production - input wood required | D35: PJ/yr. | E35: One technology only , input is wood output is pellet
B36: Efficiency for wood to pellet production | C36: Average annual efficiency of wood to pellet conversion | D36: %
B37: Fuel consumption in industry sectors | C37: Fuel consumption in industry by fuel and technology | D37: PJ/yr. | E37: This unfortunately it will change when the new industrial sectors will be integrated into STEM
B38: Process and space heating production in industry sectors | C38: Energy service demand provided in the form of process and space heating in industry | D38: PJ/yr. | E38: This unfortunately it will change when the new industrial sectors will be integrated into STEM
B39: Efficiency in industry sectors | C39: Boilers efficiency and COP of heat pumps in the industrial sectors | D39: % | E39: This unfortunately it will change when the new industrial sectors will be integrated into STEM
B40: Fuel consumption in Services sectors | C40: Fuel consumption in services sectors by fuel and technology | D40: PJ/yr.
B41: Space water and process heat production in Services sectors | C41: Production of energy service demand for space, water and process heat in Services sectors | D41: PJ/yr.
B42: Efficiency in Services sectors | C42: Boilers efficiency and COP of heat pumps in the Services sectors | D42: %
...

Sheet SPS4
A1: Model | B1: Scenario | C1: Region | D1: Variable | E1: Unit | F1: 2020 | G1: 2022 | H1: 2025 | I1: 2030 | J1: 2040 | K1: 2050
A2: STEM | B2: SPS4 | C2: CH | D2: Primary Production | E2: PJ/yr. | F2: =F3+F8+F11+F12+F16+F17+F18+F19 -> 300.18639 | G2: =G3+G8+G11+G12+G16+G17+G18+G19 -> 294.04758 | H2: =H3+H8+H11+H12+H16+H17+H18+H19 -> 370.47746 | I2: =I3+I8+I11+I12+I16+I17+I18+I19 -> 361.01552 | J2: =J3+J8+J11+J12+J16+J17+J18+J19 -> 404.5204 | K2: =K3+K8+K11+K12+K16+K17+K18+K19 -> 448.78003
A3: =A2 -> STEM | B3: =B2 -> SPS4 | C3: =C2 -> CH | D3: Primary Production|Wood | E3: PJ/yr. | F3: =SUM(F4:F7) -> 44.97247 | G3: =SUM(G4:G7) -> 48.190497 | H3: =SUM(H4:H7) -> 48.637978 | I3: =SUM(I4:I7) -> 48.638701 | J3: =SUM(J4:J7) -> 50.459886 | K3: =SUM(K4:K7) -> 51.034782
A4: =A3 -> STEM | B4: =B3 -> SPS4 | C4: =C3 -> CH | D4: Primary Production|Wood|Waste wood | E4: PJ/yr. | F4: {=SUMPRODUCT(("RNWWOD1"=[1]OUT_PrimaryEnergyCons!$A$1:$A$1000)*1,[1]OUT_PrimaryEnergyCons!D$1:D$1000)} -> 11.111887 | G4: {=SUMPRODUCT(("RNWWOD1"=[1]OUT_PrimaryEnergyCons!$A$1:$A$1000)*1,[1]OUT_PrimaryEnergyCons!E$1:E$1000)} -> 11.952894 | H4: {=SUMPRODUCT(("RNWWOD1"=[1]OUT_PrimaryEnergyCons!$A$1:$A$1000)*1,[1]OUT_PrimaryEnergyCons!F$1:F$1000)} -> 13.214396 | I4: {=SUMPRODUCT(("RNWWOD1"=[1]OUT_PrimaryEnergyCons!$A$1:$A$1000)*1,[1]OUT_PrimaryEnergyCons!G$1:G$1000)} -> 15.316914 | J4: {=SUMPRODUCT(("RNWWOD1"=[1]OUT_PrimaryEnergyCons!$A$1:$A$1000)*1,[1]OUT_PrimaryEnergyCons!H$1:H$1000)} -> 16.2664 | K4: {=SUMPRODUCT(("RNWWOD1"=[1]OUT_PrimaryEnergyCons!$A$1:$A$1000)*1,[1]OUT_PrimaryEnergyCons!I$1:I$1000)} -> 16.956998
A5: =A4 -> STEM | B5: =B4 -> SPS4 | C5: =C4 -> CH | D5: Primary Production|Wood|Wood residues | E5: PJ/yr. | F5: {=SUMPRODUCT(("RNWWOD2"=[1]OUT_PrimaryEnergyCons!$A$1:$A$1000)*1,[1]OUT_PrimaryEnergyCons!D$1:D$1000)} -> 7.5116807 | G5: {=SUMPRODUCT(("RNWWOD2"=[1]OUT_PrimaryEnergyCons!$A$1:$A$1000)*1,[1]OUT_PrimaryEnergyCons!E$1:E$1000)} -> 7.5431527 | H5: {=SUMPRODUCT(("RNWWOD2"=[1]OUT_PrimaryEnergyCons!$A$1:$A$1000)*1,[1]OUT_PrimaryEnergyCons!F$1:F$1000)} -> 7.5903521 | I5: {=SUMPRODUCT(("RNWWOD2"=[1]OUT_PrimaryEnergyCons!$A$1:$A$1000)*1,[1]OUT_PrimaryEnergyCons!G$1:G$1000)} -> 7.6690318 | J5: {=SUMPRODUCT(("RNWWOD2"=[1]OUT_PrimaryEnergyCons!$A$1:$A$1000)*1,[1]OUT_PrimaryEnergyCons!H$1:H$1000)} -> 7.6690315 | K5: {=SUMPRODUCT(("RNWWOD2"=[1]OUT_PrimaryEnergyCons!$A$1:$A$1000)*1,[1]OUT_PrimaryEnergyCons!I$1:I$1000)} -> 7.6690319
A6: =A5 -> STEM | B6: =B5 -> SPS4 | C6: =C5 -> CH | D6: Primary Production|Wood|Wood from landscape maintenance | E6: PJ/yr. | F6: {=SUMPRODUCT(("RNWWOD3"=[1]OUT_PrimaryEnergyCons!$A$1:$A$1000)*1,[1]OUT_PrimaryEnergyCons!D$1:D$1000)} -> 3.168255 | G6: {=SUMPRODUCT(("RNWWOD3"=[1]OUT_PrimaryEnergyCons!$A$1:$A$1000)*1,[1]OUT_PrimaryEnergyCons!E$1:E$1000)} -> 3.4956774 | H6: {=SUMPRODUCT(("RNWWOD3"=[1]OUT_PrimaryEnergyCons!$A$1:$A$1000)*1,[1]OUT_PrimaryEnergyCons!F$1:F$1000)} -> 3.9868189 | I6: {=SUMPRODUCT(("RNWWOD3"=[1]OUT_PrimaryEnergyCons!$A$1:$A$1000)*1,[1]OUT_PrimaryEnergyCons!G$1:G$1000)} -> 4.8053882 | J6: {=SUMPRODUCT(("RNWWOD3"=[1]OUT_PrimaryEnergyCons!$A$1:$A$1000)*1,[1]OUT_PrimaryEnergyCons!H$1:H$1000)} -> 4.8053877 | K6: {=SUMPRODUCT(("RNWWOD3"=[1]OUT_PrimaryEnergyCons!$A$1:$A$1000)*1,[1]OUT_PrimaryEnergyCons!I$1:I$1000)} -> 4.8053883
A7: =A6 -> STEM | B7: =B6 -> SPS4 | C7: =C6 -> CH | D7: Primary Production|Wood|Wood from Forest (hard wood) | E7: PJ/yr. | F7: {=SUMPRODUCT(("RNWWOD4"=[1]OUT_PrimaryEnergyCons!$A$1:$A$1000)*1+("RNWWOD5"=[1]OUT_PrimaryEnergyCons!$A$1:$A$1000)*1,[1]OUT_PrimaryEnergyCons!D$1:D$1000)} -> 23.180647 | G7: {=SUMPRODUCT(("RNWWOD4"=[1]OUT_PrimaryEnergyCons!$A$1:$A$1000)*1+("RNWWOD5"=[1]OUT_PrimaryEnergyCons!$A$1:$A$1000)*1,[1]OUT_PrimaryEnergyCons!E$1:E$1000)} -> 25.198773 | H7: {=SUMPRODUCT(("RNWWOD4"=[1]OUT_PrimaryEnergyCons!$A$1:$A$1000)*1+("RNWWOD5"=[1]OUT_PrimaryEnergyCons!$A$1:$A$1000)*1,[1]OUT_PrimaryEnergyCons!F$1:F$1000)} -> 23.846411 | I7: {=SUMPRODUCT(("RNWWOD4"=[1]OUT_PrimaryEnergyCons!$A$1:$A$1000)*1+("RNWWOD5"=[1]OUT_PrimaryEnergyCons!$A$1:$A$1000)*1,[1]OUT_PrimaryEnergyCons!G$1:G$1000)} -> 20.847367 | J7: {=SUMPRODUCT(("RNWWOD4"=[1]OUT_PrimaryEnergyCons!$A$1:$A$1000)*1+("RNWWOD5"=[1]OUT_PrimaryEnergyCons!$A$1:$A$1000)*1,[1]OUT_PrimaryEnergyCons!H$1:H$1000)} -> 21.719066 | K7: {=SUMPRODUCT(("RNWWOD4"=[1]OUT_PrimaryEnergyCons!$A$1:$A$1000)*1+("RNWWOD5"=[1]OUT_PrimaryEnergyCons!$A$1:$A$1000)*1,[1]OUT_PrimaryEnergyCons!I$1:I$1000)} -> 21.603365
A8: =A7 -> STEM | B8: =B7 -> SPS4 | C8: =C7 -> CH | D8: Primary Production|Waste | E8: PJ/yr. | F8: =SUM(F9:F10) -> 70.031584 | G8: =SUM(G9:G10) -> 70.696312 | H8: =SUM(H9:H10) -> 70.303401 | I8: =SUM(I9:I10) -> 69.853894 | J8: =SUM(J9:J10) -> 69.982193 | K8: =SUM(K9:K10) -> 75.481916
A9: =A8 -> STEM | B9: =B8 -> SPS4 | C9: =C8 -> CH | D9: Primary Production|Waste|Non renewable waste | E9: PJ/yr. | F9: {=SUMPRODUCT(("RNNWWST1"=[1]OUT_PrimaryEnergyCons!$A$1:$A$1000)*1,[1]OUT_PrimaryEnergyCons!D$1:D$1000)} -> 35.931127 | G9: {=SUMPRODUCT(("RNNWWST1"=[1]OUT_PrimaryEnergyCons!$A$1:$A$1000)*1,[1]OUT_PrimaryEnergyCons!E$1:E$1000)} -> 35.882388 | H9: {=SUMPRODUCT(("RNNWWST1"=[1]OUT_PrimaryEnergyCons!$A$1:$A$1000)*1,[1]OUT_PrimaryEnergyCons!F$1:F$1000)} -> 35.489465 | I9: {=SUMPRODUCT(("RNNWWST1"=[1]OUT_PrimaryEnergyCons!$A$1:$A$1000)*1,[1]OUT_PrimaryEnergyCons!G$1:G$1000)} -> 35.039966 | J9: {=SUMPRODUCT(("RNNWWST1"=[1]OUT_PrimaryEnergyCons!$A$1:$A$1000)*1,[1]OUT_PrimaryEnergyCons!H$1:H$1000)} -> 35.159452 | K9: {=SUMPRODUCT(("RNNWWST1"=[1]OUT_PrimaryEnergyCons!$A$1:$A$1000)*1,[1]OUT_PrimaryEnergyCons!I$1:I$1000)} -> 35.603176
A10: =A9 -> STEM | B10: =B9 -> SPS4 | C10: =C9 -> CH | D10: Primary Production|Waste|Renewable waste | E10: PJ/yr. | F10: {=SUMPRODUCT(("RNWWST1"=[1]OUT_PrimaryEnergyCons!$A$1:$A$1000)*1,[1]OUT_PrimaryEnergyCons!D$1:D$1000)} -> 34.100457 | G10: {=SUMPRODUCT(("RNWWST1"=[1]OUT_PrimaryEnergyCons!$A$1:$A$1000)*1,[1]OUT_PrimaryEnergyCons!E$1:E$1000)} -> 34.813924 | H10: {=SUMPRODUCT(("RNWWST1"=[1]OUT_PrimaryEnergyCons!$A$1:$A$1000)*1,[1]OUT_PrimaryEnergyCons!F$1:F$1000)} -> 34.813936 | I10: {=SUMPRODUCT(("RNWWST1"=[1]OUT_PrimaryEnergyCons!$A$1:$A$1000)*1,[1]OUT_PrimaryEnergyCons!G$1:G$1000)} -> 34.813928 | J10: {=SUMPRODUCT(("RNWWST1"=[1]OUT_PrimaryEnergyCons!$A$1:$A$1000)*1,[1]OUT_PrimaryEnergyCons!H$1:H$1000)} -> 34.822741 | K10: {=SUMPRODUCT(("RNWWST1"=[1]OUT_PrimaryEnergyCons!$A$1:$A$1000)*1,[1]OUT_PrimaryEnergyCons!I$1:I$1000)} -> 39.87874
A11: =A10 -> STEM | B11: =B10 -> SPS4 | C11: =C10 -> CH | D11: Primary Production|Manure | E11: PJ/yr. | F11: {=SUMPRODUCT(("mnr"=[1]OUT_PrimaryEnergyCons!$C$1:$C$1000)*1,[1]OUT_PrimaryEnergyCons!D$1:D$1000)} -> 3.7981061 | G11: {=SUMPRODUCT(("mnr"=[1]OUT_PrimaryEnergyCons!$C$1:$C$1000)*1,[1]OUT_PrimaryEnergyCons!E$1:E$1000)} -> 10.707989 | H11: {=SUMPRODUCT(("mnr"=[1]OUT_PrimaryEnergyCons!$C$1:$C$1000)*1,[1]OUT_PrimaryEnergyCons!F$1:F$1000)} -> 12.540099 | I11: {=SUMPRODUCT(("mnr"=[1]OUT_PrimaryEnergyCons!$C$1:$C$1000)*1,[1]OUT_PrimaryEnergyCons!G$1:G$1000)} -> 12.540427 | J11: {=SUMPRODUCT(("mnr"=[1]OUT_PrimaryEnergyCons!$C$1:$C$1000)*1,[1]OUT_PrimaryEnergyCons!H$1:H$1000)} -> 14.623727 | K11: {=SUMPRODUCT(("mnr"=[1]OUT_PrimaryEnergyCons!$C$1:$C$1000)*1,[1]OUT_PrimaryEnergyCons!I$1:I$1000)} -> 18.811312
A12: =A11 -> STEM | B12: =B11 -> SPS4 | C12: =C11 -> CH | D12: Primary Production|Hydro | E12: PJ/yr. | F12: =SUM(F13:F15) -> 149.43049 | G12: =SUM(G13:G15) -> 125.60595 | H12: =SUM(H13:H15) -> 177.6524 | I12: =SUM(I13:I15) -> 150.46034 | J12: =SUM(J13:J15) -> 150.73421 | K12: =SUM(K13:K15) -> 150.96379
A13: =A12 -> STEM | B13: =B12 -> SPS4 | C13: =C12 -> CH | D13: Primary Production|Hydro|Large hydro | E13: PJ/yr. | F13: {=SUMPRODUCT(ISNUMBER(SEARCH("EHYD-DAM",[1]OUT_Electricity_CHP!$B$1:$B$10000))*1,([1]OUT_Electricity_CHP!$C$1:$C$10000="Var_Fout")*1,ISNUMBER(SEARCH("ELC",[1]OUT_Electricity_CHP!$D$1:$D$10000))*1,[1]OUT_Electricity_CHP!E$1:E$10000)} -> 66.74568 | G13: {=SUMPRODUCT(ISNUMBER(SEARCH("EHYD-DAM",[1]OUT_Electricity_CHP!$B$1:$B$10000))*1,([1]OUT_Electricity_CHP!$C$1:$C$10000="Var_Fout")*1,ISNUMBER(SEARCH("ELC",[1]OUT_Electricity_CHP!$D$1:$D$10000))*1,[1]OUT_Electricity_CHP!F$1:F$10000)} -> 49.798802 | H13: {=SUMPRODUCT(ISNUMBER(SEARCH("EHYD-DAM",[1]OUT_Electricity_CHP!$B$1:$B$10000))*1,([1]OUT_Electricity_CHP!$C$1:$C$10000="Var_Fout")*1,ISNUMBER(SEARCH("ELC",[1]OUT_Electricity_CHP!$D$1:$D$10000))*1,[1]OUT_Electricity_CHP!G$1:G$10000)} -> 68.534388 | I13: {=SUMPRODUCT(ISNUMBER(SEARCH("EHYD-DAM",[1]OUT_Electricity_CHP!$B$1:$B$10000))*1,([1]OUT_Electricity_CHP!$C$1:$C$10000="Var_Fout")*1,ISNUMBER(SEARCH("ELC",[1]OUT_Electricity_CHP!$D$1:$D$10000))*1,[1]OUT_Electricity_CHP!H$1:H$10000)} -> 70.342916 | J13: {=SUMPRODUCT(ISNUMBER(SEARCH("EHYD-DAM",[1]OUT_Electricity_CHP!$B$1:$B$10000))*1,([1]OUT_Electricity_CHP!$C$1:$C$10000="Var_Fout")*1,ISNUMBER(SEARCH("ELC",[1]OUT_Electricity_CHP!$D$1:$D$10000))*1,[1]OUT_Electricity_CHP!I$1:I$10000)} -> 72.511307 | K13: {=SUMPRODUCT(ISNUMBER(SEARCH("EHYD-DAM",[1]OUT_Electricity_CHP!$B$1:$B$10000))*1,([1]OUT_Electricity_CHP!$C$1:$C$10000="Var_Fout")*1,ISNUMBER(SEARCH("ELC",[1]OUT_Electricity_CHP!$D$1:$D$10000))*1,[1]OUT_Electricity_CHP!J$1:J$10000)} -> 74.680996
A14: =A13 -> STEM | B14: =B13 -> SPS4 | C14: =C13 -> CH | D14: Primary Production|Hydro|Run-of-river hydro | E14: PJ/yr. | F14: {=SUMPRODUCT(ISNUMBER(SEARCH("EHYD-RUN",[1]OUT_Electricity_CHP!$B$1:$B$10000))*1,([1]OUT_Electricity_CHP!$C$1:$C$10000="Var_Fout")*1,ISNUMBER(SEARCH("ELC",[1]OUT_Electricity_CHP!$D$1:$D$10000))*1,[1]OUT_Electricity_CHP!E$1:E$10000)} -> 66.632401 | G14: {=SUMPRODUCT(ISNUMBER(SEARCH("EHYD-RUN",[1]OUT_Electricity_CHP!$B$1:$B$10000))*1,([1]OUT_Electricity_CHP!$C$1:$C$10000="Var_Fout")*1,ISNUMBER(SEARCH("ELC",[1]OUT_Electricity_CHP!$D$1:$D$10000))*1,[1]OUT_Electricity_CHP!F$1:F$10000)} -> 55.764005 | H14: {=SUMPRODUCT(ISNUMBER(SEARCH("EHYD-RUN",[1]OUT_Electricity_CHP!$B$1:$B$10000))*1,([1]OUT_Electricity_CHP!$C$1:$C$10000="Var_Fout")*1,ISNUMBER(SEARCH("ELC",[1]OUT_Electricity_CHP!$D$1:$D$10000))*1,[1]OUT_Electricity_CHP!G$1:G$10000)} -> 65.550962 | I14: {=SUMPRODUCT(ISNUMBER(SEARCH("EHYD-RUN",[1]OUT_Electricity_CHP!$B$1:$B$10000))*1,([1]OUT_Electricity_CHP!$C$1:$C$10000="Var_Fout")*1,ISNUMBER(SEARCH("ELC",[1]OUT_Electricity_CHP!$D$1:$D$10000))*1,[1]OUT_Electricity_CHP!H$1:H$10000)} -> 64.468038 | J14: {=SUMPRODUCT(ISNUMBER(SEARCH("EHYD-RUN",[1]OUT_Electricity_CHP!$B$1:$B$10000))*1,([1]OUT_Electricity_CHP!$C$1:$C$10000="Var_Fout")*1,ISNUMBER(SEARCH("ELC",[1]OUT_Electricity_CHP!$D$1:$D$10000))*1,[1]OUT_Electricity_CHP!I$1:I$10000)} -> 62.299669 | K14: {=SUMPRODUCT(ISNUMBER(SEARCH("EHYD-RUN",[1]OUT_Electricity_CHP!$B$1:$B$10000))*1,([1]OUT_Electricity_CHP!$C$1:$C$10000="Var_Fout")*1,ISNUMBER(SEARCH("ELC",[1]OUT_Electricity_CHP!$D$1:$D$10000))*1,[1]OUT_Electricity_CHP!J$1:J$10000)} -> 60.129977
A15: =A14 -> STEM | B15: =B14 -> SPS4 | C15: =C14 -> CH | D15: Primary Production|Hydro|Pump storage | E15: PJ/yr. | F15: {=SUMPRODUCT(ISNUMBER(SEARCH("EHYD-PUM",[1]OUT_Electricity_CHP!$B$1:$B$10000))*1,([1]OUT_Electricity_CHP!$C$1:$C$10000="Var_Fin")*1,ISNUMBER(SEARCH("elc",[1]OUT_Electricity_CHP!$D$1:$D$10000))*1,[1]OUT_Electricity_CHP!E$1:E$10000)} -> 16.052406 | G15: {=SUMPRODUCT(ISNUMBER(SEARCH("EHYD-PUM",[1]OUT_Electricity_CHP!$B$1:$B$10000))*1,([1]OUT_Electricity_CHP!$C$1:$C$10000="Var_Fin")*1,ISNUMBER(SEARCH("elc",[1]OUT_Electricity_CHP!$D$1:$D$10000))*1,[1]OUT_Electricity_CHP!F$1:F$10000)} -> 20.043139 | H15: {=SUMPRODUCT(ISNUMBER(SEARCH("EHYD-PUM",[1]OUT_Electricity_CHP!$B$1:$B$10000))*1,([1]OUT_Electricity_CHP!$C$1:$C$10000="Var_Fin")*1,ISNUMBER(SEARCH("elc",[1]OUT_Electricity_CHP!$D$1:$D$10000))*1,[1]OUT_Electricity_CHP!G$1:G$10000)} -> 43.56705 | I15: {=SUMPRODUCT(ISNUMBER(SEARCH("EHYD-PUM",[1]OUT_Electricity_CHP!$B$1:$B$10000))*1,([1]OUT_Electricity_CHP!$C$1:$C$10000="Var_Fin")*1,ISNUMBER(SEARCH("elc",[1]OUT_Electricity_CHP!$D$1:$D$10000))*1,[1]OUT_Electricity_CHP!H$1:H$10000)} -> 15.649389 | J15: {=SUMPRODUCT(ISNUMBER(SEARCH("EHYD-PUM",[1]OUT_Electricity_CHP!$B$1:$B$10000))*1,([1]OUT_Electricity_CHP!$C$1:$C$10000="Var_Fin")*1,ISNUMBER(SEARCH("elc",[1]OUT_Electricity_CHP!$D$1:$D$10000))*1,[1]OUT_Electricity_CHP!I$1:I$10000)} -> 15.923232 | K15: {=SUMPRODUCT(ISNUMBER(SEARCH("EHYD-PUM",[1]OUT_Electricity_CHP!$B$1:$B$10000))*1,([1]OUT_Electricity_CHP!$C$1:$C$10000="Var_Fin")*1,ISNUMBER(SEARCH("elc",[1]OUT_Electricity_CHP!$D$1:$D$10000))*1,[1]OUT_Electricity_CHP!J$1:J$10000)} -> 16.152819
A16: =A15 -> STEM | B16: =B15 -> SPS4 | C16: =C15 -> CH | D16: Primary Production|Solar | E16: PJ/yr. | F16: {=SUMPRODUCT(ISNUMBER(SEARCH("SOL",[1]OUT_PrimaryEnergyCons!$C$1:$C$1000))*1,[1]OUT_PrimaryEnergyCons!D$1:D$1000)} -> 12.556533 | G16: {=SUMPRODUCT(ISNUMBER(SEARCH("SOL",[1]OUT_PrimaryEnergyCons!$C$1:$C$1000))*1,[1]OUT_PrimaryEnergyCons!E$1:E$1000)} -> 16.523564 | H16: {=SUMPRODUCT(ISNUMBER(SEARCH("SOL",[1]OUT_PrimaryEnergyCons!$C$1:$C$1000))*1,[1]OUT_PrimaryEnergyCons!F$1:F$1000)} -> 30.349278 | I16: {=SUMPRODUCT(ISNUMBER(SEARCH("SOL",[1]OUT_PrimaryEnergyCons!$C$1:$C$1000))*1,[1]OUT_PrimaryEnergyCons!G$1:G$1000)} -> 32.983451 | J16: {=SUMPRODUCT(ISNUMBER(SEARCH("SOL",[1]OUT_PrimaryEnergyCons!$C$1:$C$1000))*1,[1]OUT_PrimaryEnergyCons!H$1:H$1000)} -> 53.078283 | K16: {=SUMPRODUCT(ISNUMBER(SEARCH("SOL",[1]OUT_PrimaryEnergyCons!$C$1:$C$1000))*1,[1]OUT_PrimaryEnergyCons!I$1:I$1000)} -> 67.519132
A17: =A16 -> STEM | B17: =B16 -> SPS4 | C17: =C16 -> CH | D17: Primary Production|Wind | E17: PJ/yr. | F17: {=SUMPRODUCT(ISNUMBER(SEARCH("wnd",[1]OUT_PrimaryEnergyCons!$C$1:$C$1000))*1,[1]OUT_PrimaryEnergyCons!D$1:D$1000)} -> 0.5240291 | G17: {=SUMPRODUCT(ISNUMBER(SEARCH("wnd",[1]OUT_PrimaryEnergyCons!$C$1:$C$1000))*1,[1]OUT_PrimaryEnergyCons!E$1:E$1000)} -> 0.54529607 | H17: {=SUMPRODUCT(ISNUMBER(SEARCH("wnd",[1]OUT_PrimaryEnergyCons!$C$1:$C$1000))*1,[1]OUT_PrimaryEnergyCons!F$1:F$1000)} -> 0.50316867 | I17: {=SUMPRODUCT(ISNUMBER(SEARCH("wnd",[1]OUT_PrimaryEnergyCons!$C$1:$C$1000))*1,[1]OUT_PrimaryEnergyCons!G$1:G$1000)} -> 0.88472649 | J17: {=SUMPRODUCT(ISNUMBER(SEARCH("wnd",[1]OUT_PrimaryEnergyCons!$C$1:$C$1000))*1,[1]OUT_PrimaryEnergyCons!H$1:H$1000)} -> 0.79253689 | K17: {=SUMPRODUCT(ISNUMBER(SEARCH("wnd",[1]OUT_PrimaryEnergyCons!$C$1:$C$1000))*1,[1]OUT_PrimaryEnergyCons!I$1:I$1000)} -> 3.187155
A18: =A17 -> STEM | B18: =B17 -> SPS4 | C18: =C17 -> CH | D18: Primary Production|Ambient heat | E18: PJ/yr. | F18: =[1]Overview!B$9-F19 -> 18.873179 | G18: =[1]Overview!C$9-G19 -> 21.777979 | H18: =[1]Overview!D$9-H19 -> 30.491133 | I18: =[1]Overview!E$9-I19 -> 45.653976 | J18: =[1]Overview!F$9-J19 -> 64.824973 | K18: =[1]Overview!G$9-K19 -> 81.625331
A19: =A18 -> STEM | B19: =B18 -> SPS4 | C19: =C18 -> CH | D19: Primary Production|Geothermal | E19: PJ/yr. | F19: =+[1]Overview!B$28 -> 0 | G19: =+[1]Overview!C$28 -> 0 | H19: =+[1]Overview!D$28 -> 0 | I19: =+[1]Overview!E$28 -> 0 | J19: =+[1]Overview!F$28 -> 0.024592488 | K19: =+[1]Overview!G$28 -> 0.15660538
A20: =A19 -> STEM | B20: =B19 -> SPS4 | C20: =C19 -> CH | D20: Imports | E20: PJ/yr. | F20: =SUM(F21:F22,F39,F48:F49,F54) -> 779.50558 | G20: =SUM(G21:G22,G39,G48:G49,G54) -> 702.13551 | H20: =SUM(H21:H22,H39,H48:H49,H54) -> 629.06586 | I20: =SUM(I21:I22,I39,I48:I49,I54) -> 569.10916 | J20: =SUM(J21:J22,J39,J48:J49,J54) -> 370.77429 | K20: =SUM(K21:K22,K39,K48:K49,K54) -> 236.54661
A21: =A20 -> STEM | B21: =B20 -> SPS4 | C21: =C20 -> CH | D21: Imports|Coal | E21: PJ/yr. | F21: {=SUMPRODUCT(("COA"=[1]OUT_PrimaryEnergyCons!$C$4:$C$10000)*1,[1]OUT_PrimaryEnergyCons!D$4:D$10000)} -> 3.6600242 | G21: {=SUMPRODUCT(("COA"=[1]OUT_PrimaryEnergyCons!$C$4:$C$10000)*1,[1]OUT_PrimaryEnergyCons!E$4:E$10000)} -> 3.5647235 | H21: {=SUMPRODUCT(("COA"=[1]OUT_PrimaryEnergyCons!$C$4:$C$10000)*1,[1]OUT_PrimaryEnergyCons!F$4:F$10000)} -> 3.2533416 | I21: {=SUMPRODUCT(("COA"=[1]OUT_PrimaryEnergyCons!$C$4:$C$10000)*1,[1]OUT_PrimaryEnergyCons!G$4:G$10000)} -> 0.0067059312 | J21: {=SUMPRODUCT(("COA"=[1]OUT_PrimaryEnergyCons!$C$4:$C$10000)*1,[1]OUT_PrimaryEnergyCons!H$4:H$10000)} -> 0.00063286741 | K21: {=SUMPRODUCT(("COA"=[1]OUT_PrimaryEnergyCons!$C$4:$C$10000)*1,[1]OUT_PrimaryEnergyCons!I$4:I$10000)} -> 0.00034793621
A22: =A21 -> STEM | B22: =B21 -> SPS4 | C22: =C21 -> CH | D22: Imports|Oil | E22: PJ/yr. | F22: =F23+F29 -> 310.65474 | G22: =G23+G29 -> 287.759 | H22: =H23+H29 -> 263.34573 | I22: =I23+I29 -> 201.77973 | J22: =J23+J29 -> 131.57517 | K22: =K23+K29 -> 99.259028
A23: =A22 -> STEM | B23: =B22 -> SPS4 | C23: =C22 -> CH | D23: Imports|Oil|Fossil liquids | E23: PJ/yr. | F23: =SUM(F24:F28) -> 303.87158 | G23: =SUM(G24:G28) -> 280.98437 | H23: =SUM(H24:H28) -> 256.05488 | I23: =SUM(I24:I28) -> 189.96463 | J23: =SUM(J24:J28) -> 119.79585 | K23: =SUM(K24:K28) -> 88.040874
A24: =A22 -> STEM | B24: =B23 -> SPS4 | C24: =C22 -> CH | D24: Imports|Oil|Fossil liquids|Light fuel oil | E24: PJ/yr. | F24: {=SUMPRODUCT(("LFO"=[1]OUT_PrimaryEnergyCons!$C$4:$C$10000)*1,[1]OUT_PrimaryEnergyCons!D$4:D$10000)} -> 101.74113 | G24: {=SUMPRODUCT(("LFO"=[1]OUT_PrimaryEnergyCons!$C$4:$C$10000)*1,[1]OUT_PrimaryEnergyCons!E$4:E$10000)} -> 88.340537 | H24: {=SUMPRODUCT(("LFO"=[1]OUT_PrimaryEnergyCons!$C$4:$C$10000)*1,[1]OUT_PrimaryEnergyCons!F$4:F$10000)} -> 85.82086 | I24: {=SUMPRODUCT(("LFO"=[1]OUT_PrimaryEnergyCons!$C$4:$C$10000)*1,[1]OUT_PrimaryEnergyCons!G$4:G$10000)} -> 59.651706 | J24: {=SUMPRODUCT(("LFO"=[1]OUT_PrimaryEnergyCons!$C$4:$C$10000)*1,[1]OUT_PrimaryEnergyCons!H$4:H$10000)} -> 31.795464 | K24: {=SUMPRODUCT(("LFO"=[1]OUT_PrimaryEnergyCons!$C$4:$C$10000)*1,[1]OUT_PrimaryEnergyCons!I$4:I$10000)} -> 11.092309
A25: =A24 -> STEM | B25: =B24 -> SPS4 | C25: =C24 -> CH | D25: Imports|Oil|Fossil liquids|Heavy fuel oil | E25: PJ/yr. | F25: {=SUMPRODUCT(("HFO"=[1]OUT_PrimaryEnergyCons!$C$4:$C$10000)*1,[1]OUT_PrimaryEnergyCons!D$4:D$10000)} -> 2.7763884 | G25: {=SUMPRODUCT(("HFO"=[1]OUT_PrimaryEnergyCons!$C$4:$C$10000)*1,[1]OUT_PrimaryEnergyCons!E$4:E$10000)} -> 2.6376027 | H25: {=SUMPRODUCT(("HFO"=[1]OUT_PrimaryEnergyCons!$C$4:$C$10000)*1,[1]OUT_PrimaryEnergyCons!F$4:F$10000)} -> 0.0032777617 | I25: {=SUMPRODUCT(("HFO"=[1]OUT_PrimaryEnergyCons!$C$4:$C$10000)*1,[1]OUT_PrimaryEnergyCons!G$4:G$10000)} -> 0.00059545448 | J25: {=SUMPRODUCT(("HFO"=[1]OUT_PrimaryEnergyCons!$C$4:$C$10000)*1,[1]OUT_PrimaryEnergyCons!H$4:H$10000)} -> 0.00070543166 | K25: {=SUMPRODUCT(("HFO"=[1]OUT_PrimaryEnergyCons!$C$4:$C$10000)*1,[1]OUT_PrimaryEnergyCons!I$4:I$10000)} -> 0
A26: =A25 -> STEM | B26: =B25 -> SPS4 | C26: =C25 -> CH | D26: Imports|Oil|Fossil liquids|Motor Diesel | E26: PJ/yr. | F26: {=SUMPRODUCT(("DSL"=[1]OUT_PrimaryEnergyCons!$C$4:$C$10000)*1,[1]OUT_PrimaryEnergyCons!D$4:D$10000)} -> 118.3678 | G26: {=SUMPRODUCT(("DSL"=[1]OUT_PrimaryEnergyCons!$C$4:$C$10000)*1,[1]OUT_PrimaryEnergyCons!E$4:E$10000)} -> 112.68604 | H26: {=SUMPRODUCT(("DSL"=[1]OUT_PrimaryEnergyCons!$C$4:$C$10000)*1,[1]OUT_PrimaryEnergyCons!F$4:F$10000)} -> 96.183443 | I26: {=SUMPRODUCT(("DSL"=[1]OUT_PrimaryEnergyCons!$C$4:$C$10000)*1,[1]OUT_PrimaryEnergyCons!G$4:G$10000)} -> 72.099065 | J26: {=SUMPRODUCT(("DSL"=[1]OUT_PrimaryEnergyCons!$C$4:$C$10000)*1,[1]OUT_PrimaryEnergyCons!H$4:H$10000)} -> 48.97925 | K26: {=SUMPRODUCT(("DSL"=[1]OUT_PrimaryEnergyCons!$C$4:$C$10000)*1,[1]OUT_PrimaryEnergyCons!I$4:I$10000)} -> 48.013922
A27: =A26 -> STEM | B27: =B26 -> SPS4 | C27: =C26 -> CH | D27: Imports|Oil|Fossil liquids|Motor Gasoline | E27: PJ/yr. | F27: {=SUMPRODUCT(("GSL"=[1]OUT_PrimaryEnergyCons!$C$4:$C$10000)*1,[1]OUT_PrimaryEnergyCons!D$4:D$10000)} -> 79.877962 | G27: {=SUMPRODUCT(("GSL"=[1]OUT_PrimaryEnergyCons!$C$4:$C$10000)*1,[1]OUT_PrimaryEnergyCons!E$4:E$10000)} -> 75.914995 | H27: {=SUMPRODUCT(("GSL"=[1]OUT_PrimaryEnergyCons!$C$4:$C$10000)*1,[1]OUT_PrimaryEnergyCons!F$4:F$10000)} -> 72.199644 | I27: {=SUMPRODUCT(("GSL"=[1]OUT_PrimaryEnergyCons!$C$4:$C$10000)*1,[1]OUT_PrimaryEnergyCons!G$4:G$10000)} -> 55.649079 | J27: {=SUMPRODUCT(("GSL"=[1]OUT_PrimaryEnergyCons!$C$4:$C$10000)*1,[1]OUT_PrimaryEnergyCons!H$4:H$10000)} -> 37.863787 | K27: {=SUMPRODUCT(("GSL"=[1]OUT_PrimaryEnergyCons!$C$4:$C$10000)*1,[1]OUT_PrimaryEnergyCons!I$4:I$10000)} -> 28.179487
A28: =A27 -> STEM | B28: =B27 -> SPS4 | C28: =C27 -> CH | D28: Imports|Oil|Fossil liquids|Kerosene (excl. international aviation) | E28: PJ/yr. | F28: {=SUMPRODUCT(("KER"=[1]OUT_PrimaryEnergyCons!$C$4:$C$10000)*1,[1]OUT_PrimaryEnergyCons!D$4:D$10000)} -> 1.1082891 | G28: {=SUMPRODUCT(("KER"=[1]OUT_PrimaryEnergyCons!$C$4:$C$10000)*1,[1]OUT_PrimaryEnergyCons!E$4:E$10000)} -> 1.4051978 | H28: {=SUMPRODUCT(("KER"=[1]OUT_PrimaryEnergyCons!$C$4:$C$10000)*1,[1]OUT_PrimaryEnergyCons!F$4:F$10000)} -> 1.8476578 | I28: {=SUMPRODUCT(("KER"=[1]OUT_PrimaryEnergyCons!$C$4:$C$10000)*1,[1]OUT_PrimaryEnergyCons!G$4:G$10000)} -> 2.5641854 | J28: {=SUMPRODUCT(("KER"=[1]OUT_PrimaryEnergyCons!$C$4:$C$10000)*1,[1]OUT_PrimaryEnergyCons!H$4:H$10000)} -> 1.1566401 | K28: {=SUMPRODUCT(("KER"=[1]OUT_PrimaryEnergyCons!$C$4:$C$10000)*1,[1]OUT_PrimaryEnergyCons!I$4:I$10000)} -> 0.7551565
A29: =A48 -> STEM | B29: =B28 -> SPS4 | C29: =C48 -> CH | D29: Imports|Oil|Synthetic liquids | E29: PJ/yr. | F29: =SUM(F30:F31) -> 6.7831657 | G29: =SUM(G30:G31) -> 6.7746315 | H29: =SUM(H30:H31) -> 7.2908516 | I29: =SUM(I30:I31) -> 11.815097 | J29: =SUM(J30:J31) -> 11.779319 | K29: =SUM(K30:K31) -> 11.218154
A30: =A35 -> STEM | B30: =B29 -> SPS4 | C30: =C35 -> CH | D30: Imports|Oil|Synthetic liquids|Total|Motor diesel | E30: PJ/yr. | F30: {=SUMPRODUCT(ISNUMBER(SEARCH("IMPBDS",[1]OUT_SyntheticFuels!$C$4:$C$1000))*1,("Var_Fout"=[1]OUT_SyntheticFuels!$B$4:$B$1000)*1,[1]OUT_SyntheticFuels!E$4:E$1000)} -> 2.3490129 | G30: {=SUMPRODUCT(ISNUMBER(SEARCH("IMPBDS",[1]OUT_SyntheticFuels!$C$4:$C$1000))*1,("Var_Fout"=[1]OUT_SyntheticFuels!$B$4:$B$1000)*1,[1]OUT_SyntheticFuels!F$4:F$1000)} -> 2.3780131 | H30: {=SUMPRODUCT(ISNUMBER(SEARCH("IMPBDS",[1]OUT_SyntheticFuels!$C$4:$C$1000))*1,("Var_Fout"=[1]OUT_SyntheticFuels!$B$4:$B$1000)*1,[1]OUT_SyntheticFuels!G$4:G$1000)} -> 3.3165252 | I30: {=SUMPRODUCT(ISNUMBER(SEARCH("IMPBDS",[1]OUT_SyntheticFuels!$C$4:$C$1000))*1,("Var_Fout"=[1]OUT_SyntheticFuels!$B$4:$B$1000)*1,[1]OUT_SyntheticFuels!H$4:H$1000)} -> 8.5905973 | J30: {=SUMPRODUCT(ISNUMBER(SEARCH("IMPBDS",[1]OUT_SyntheticFuels!$C$4:$C$1000))*1,("Var_Fout"=[1]OUT_SyntheticFuels!$B$4:$B$1000)*1,[1]OUT_SyntheticFuels!I$4:I$1000)} -> 9.5861026 | K30: {=SUMPRODUCT(ISNUMBER(SEARCH("IMPBDS",[1]OUT_SyntheticFuels!$C$4:$C$1000))*1,("Var_Fout"=[1]OUT_SyntheticFuels!$B$4:$B$1000)*1,[1]OUT_SyntheticFuels!J$4:J$1000)} -> 9.5857773
A31: =A30 -> STEM | B31: =B30 -> SPS4 | C31: =C30 -> CH | D31: Imports|Oil|Synthetic liquids|Total|Motor Gasoline | E31: PJ/yr. | F31: {=SUMPRODUCT(ISNUMBER(SEARCH("IMPeth",[1]OUT_SyntheticFuels!$C$4:$C$1000))*1,("Var_Fout"=[1]OUT_SyntheticFuels!$B$4:$B$1000)*1,[1]OUT_SyntheticFuels!E$4:E$1000)} -> 4.4341528 | G31: {=SUMPRODUCT(ISNUMBER(SEARCH("IMPeth",[1]OUT_SyntheticFuels!$C$4:$C$1000))*1,("Var_Fout"=[1]OUT_SyntheticFuels!$B$4:$B$1000)*1,[1]OUT_SyntheticFuels!F$4:F$1000)} -> 4.3966184 | H31: {=SUMPRODUCT(ISNUMBER(SEARCH("IMPeth",[1]OUT_SyntheticFuels!$C$4:$C$1000))*1,("Var_Fout"=[1]OUT_SyntheticFuels!$B$4:$B$1000)*1,[1]OUT_SyntheticFuels!G$4:G$1000)} -> 3.9743264 | I31: {=SUMPRODUCT(ISNUMBER(SEARCH("IMPeth",[1]OUT_SyntheticFuels!$C$4:$C$1000))*1,("Var_Fout"=[1]OUT_SyntheticFuels!$B$4:$B$1000)*1,[1]OUT_SyntheticFuels!H$4:H$1000)} -> 3.2245001 | J31: {=SUMPRODUCT(ISNUMBER(SEARCH("IMPeth",[1]OUT_SyntheticFuels!$C$4:$C$1000))*1,("Var_Fout"=[1]OUT_SyntheticFuels!$B$4:$B$1000)*1,[1]OUT_SyntheticFuels!I$4:I$1000)} -> 2.1932164 | K31: {=SUMPRODUCT(ISNUMBER(SEARCH("IMPeth",[1]OUT_SyntheticFuels!$C$4:$C$1000))*1,("Var_Fout"=[1]OUT_SyntheticFuels!$B$4:$B$1000)*1,[1]OUT_SyntheticFuels!J$4:J$1000)} -> 1.6323764
A32: =A29 -> STEM | B32: =B31 -> SPS4 | C32: =C29 -> CH | D32: Imports|Oil|Synthetic liquids|Bioliquids|Total | E32: PJ/yr. | F32: =SUM(F33:F34) -> 6.7831657 | G32: =SUM(G33:G34) -> 6.7746315 | H32: =SUM(H33:H34) -> 7.2908516 | I32: =SUM(I33:I34) -> 11.815097 | J32: =SUM(J33:J34) -> 10.783814 | K32: =SUM(K33:K34) -> 11.218154
A33: =A31 -> STEM | B33: =B32 -> SPS4 | C33: =C31 -> CH | D33: Imports|Oil|Synthetic liquids|Bioliquids|Biodiesel | E33: PJ/yr. | F33: =F30 -> 2.3490129 | G33: =G30 -> 2.3780131 | H33: =H30 -> 3.3165252 | I33: =I30 -> 8.5905973 | J33: =IF(J30-MAX(F30:I30)<0,J30,MAX(F30:I30)) -> 8.5905973 | K33: =IF(K30-MAX(F30:J30)<0,K30,MAX(F30:J30)) -> 9.5857773
A34: =A33 -> STEM | B34: =B33 -> SPS4 | C34: =C33 -> CH | D34: Imports|Oil|Synthetic liquids|Bioliquids|Ethanol | E34: PJ/yr. | F34: =F31 -> 4.4341528 | G34: =G31 -> 4.3966184 | H34: =H31 -> 3.9743264 | I34: =I31 -> 3.2245001 | J34: =IF(J31-MAX(F31:I31)<0,J31,MAX(F31:I31)) -> 2.1932164 | K34: =IF(K31-MAX(F31:J31)<0,K31,MAX(F31:J31)) -> 1.6323764
A35: =A32 -> STEM | B35: =B34 -> SPS4 | C35: =C32 -> CH | D35: Imports|Oil|Synthetic liquids|PtL | E35: PJ/yr. | F35: =SUM(F36:F37) -> 0 | G35: =SUM(G36:G37) -> 0 | H35: =SUM(H36:H37) -> 0 | I35: =SUM(I36:I37) -> 0 | J35: =SUM(J36:J37) -> 0.99550526 | K35: =SUM(K36:K37) -> 0
A36: =A34 -> STEM | B36: =B35 -> SPS4 | C36: =C34 -> CH | D36: Imports|Oil|Synthetic liquids|PtL|PtL Diesel | E36: PJ/yr. | F36: 0 | G36: 0 | H36: 0 | I36: 0 | J36: =J30-J33 -> 0.99550526 | K36: =K30-K33 -> 0
A37: =A36 -> STEM | B37: =B36 -> SPS4 | C37: =C36 -> CH | D37: Imports|Oil|Synthetic liquids|PtL|PtL Gasoline | E37: PJ/yr. | F37: 0 | G37: 0 | H37: 0 | I37: 0 | J37: =J31-J34 -> 0 | K37: =K31-K34 -> 0
B38: =B37 -> SPS4 | C38: =C37 -> CH | D38: Imports|Oil|Synthetic liquids|PtL|PtL Kerosene | E38: PJ/yr. | F38: 0 | G38: 0 | H38: 0 | I38: 0 | J38: 0 | K38: 0
A39: =A28 -> STEM | B39: =B38 -> SPS4 | C39: =C28 -> CH | D39: Imports|Gas | E39: PJ/yr. | F39: =F40+F43 -> 117.08258 | G39: =G40+G43 -> 107.23651 | H39: =H40+H43 -> 105.92888 | I39: =I40+I43 -> 104.68228 | J39: =J40+J43 -> 97.067455 | K39: =K40+K43 -> 100.07798
A40: =A29 -> STEM | B40: =B39 -> SPS4 | C40: =C29 -> CH | D40: Imports|Gas|Fossil gases|Total | E40: PJ/yr. | F40: =F41+F42 -> 117.08258 | G40: =G41+G42 -> 106.72 | H40: =H41+H42 -> 105.92844 | I40: =I41+I42 -> 102.03024 | J40: =J41+J42 -> 94.203114 | K40: =K41+K42 -> 96.652185
...

Sheet check
C2: 2020 | D2: 2022 | E2: 2025 | F2: 2030 | G2: 2040 | H2: 2050
B3: Final energy consumption | C3: =SUM(C4:C7) -> 716.18668 | D3: =SUM(D4:D7) -> 703.77454 | E3: =SUM(E4:E7) -> 687.20693 | F3: =SUM(F4:F7) -> 643.84259 | G3: =SUM(G4:G7) -> 594.54946 | H3: =SUM(H4:H7) -> 566.27644
B4: Industry | C4: ='SPS4'!F761 -> 142.21776 | D4: ='SPS4'!G761 -> 141.18303 | E4: ='SPS4'!H761 -> 142.8753 | F4: ='SPS4'!I761 -> 144.16666 | G4: ='SPS4'!J761 -> 141.26249 | H4: ='SPS4'!K761 -> 139.64054
B5: Services | C5: ='SPS4'!F880 -> 140.10121 | D5: ='SPS4'!G880 -> 139.64794 | E5: ='SPS4'!H880 -> 133.57022 | F5: ='SPS4'!I880 -> 128.7842 | G5: ='SPS4'!J880 -> 121.33778 | H5: ='SPS4'!K880 -> 113.62549
B6: Residential | C6: ='SPS4'!F970 -> 219.89495 | D6: ='SPS4'!G970 -> 217.37167 | E6: ='SPS4'!H970 -> 220.43392 | F6: ='SPS4'!I970 -> 211.31444 | G6: ='SPS4'!J970 -> 199.89894 | H6: ='SPS4'!K970 -> 190.99293
B7: Transport | C7: ='SPS4'!F1134+'SPS4'!F1313+'SPS4'!F1397+'SPS4'!F1481+'SPS4'!F1488+'SPS4'!F1495+'SPS4'!F1544+'SPS4'!F1591+'SPS4'!F1638 -> 213.97275 | D7: ='SPS4'!G1134+'SPS4'!G1313+'SPS4'!G1397+'SPS4'!G1481+'SPS4'!G1488+'SPS4'!G1495+'SPS4'!G1544+'SPS4'!G1591+'SPS4'!G1638 -> 205.5719 | E7: ='SPS4'!H1134+'SPS4'!H1313+'SPS4'!H1397+'SPS4'!H1481+'SPS4'!H1488+'SPS4'!H1495+'SPS4'!H1544+'SPS4'!H1591+'SPS4'!H1638 -> 190.32748 | F7: ='SPS4'!I1134+'SPS4'!I1313+'SPS4'!I1397+'SPS4'!I1481+'SPS4'!I1488+'SPS4'!I1495+'SPS4'!I1544+'SPS4'!I1591+'SPS4'!I1638 -> 159.57728 | G7: ='SPS4'!J1134+'SPS4'!J1313+'SPS4'!J1397+'SPS4'!J1481+'SPS4'!J1488+'SPS4'!J1495+'SPS4'!J1544+'SPS4'!J1591+'SPS4'!J1638 -> 132.05025 | H7: ='SPS4'!K1134+'SPS4'!K1313+'SPS4'!K1397+'SPS4'!K1481+'SPS4'!K1488+'SPS4'!K1495+'SPS4'!K1544+'SPS4'!K1591+'SPS4'!K1638 -> 122.01748
B8: Fuel input to energy conversion and DAC | C8: =SUM(C9:C12) -> 509.62637 | D8: =SUM(D9:D12) -> 498.78589 | E8: =SUM(E9:E12) -> 522.66119 | F8: =SUM(F9:F12) -> 506.88997 | G8: =SUM(G9:G12) -> 431.51534 | H8: =SUM(H9:H12) -> 390.47036
B9: Electricity and heat | C9: ='SPS4'!F289+'SPS4'!F407 -> 493.47802 | D9: ='SPS4'!G289+'SPS4'!G407 -> 475.48484 | E9: ='SPS4'!H289+'SPS4'!H407 -> 495.45878 | F9: ='SPS4'!I289+'SPS4'!I407 -> 483.62285 | G9: ='SPS4'!J289+'SPS4'!J407 -> 406.21936 | H9: ='SPS4'!K289+'SPS4'!K407 -> 356.49655
B10: Biofuel production | C10: ='SPS4'!F588+'SPS4'!F602+'SPS4'!F642 -> 16.143487 | D10: ='SPS4'!G588+'SPS4'!G602+'SPS4'!G642 -> 23.293874 | E10: ='SPS4'!H588+'SPS4'!H602+'SPS4'!H642 -> 27.190851 | F10: ='SPS4'!I588+'SPS4'!I602+'SPS4'!I642 -> 23.233443 | G10: ='SPS4'!J588+'SPS4'!J602+'SPS4'!J642 -> 25.028291 | H10: ='SPS4'!K588+'SPS4'!K602+'SPS4'!K642 -> 33.718931
B11: Hydrogen production | C11: ='SPS4'!F677 -> 0.0048622588 | D11: ='SPS4'!G677 -> 0.0071721669 | E11: ='SPS4'!H677 -> 0.011555902 | F11: ='SPS4'!I677 -> 0.033668204 | G11: ='SPS4'!J677 -> 0.26768877 | H11: ='SPS4'!K677 -> 0.25487824
B12: DAC | C12: ='SPS4'!F1702 -> 0 | D12: ='SPS4'!G1702 -> 0 | E12: ='SPS4'!H1702 -> 0 | F12: ='SPS4'!I1702 -> 0 | G12: ='SPS4'!J1702 -> 0 | H12: ='SPS4'!K1702 -> 0
B13: Total Primary energy consumption | C13: ='SPS4'!F2+'SPS4'!F20-'SPS4'!F55 -> 962.52194 | D13: ='SPS4'!G2+'SPS4'!G20-'SPS4'!G55 -> 960.71259 | E13: ='SPS4'!H2+'SPS4'!H20-'SPS4'!H55 -> 944.75748 | F13: ='SPS4'!I2+'SPS4'!I20-'SPS4'!I55 -> 874.46565 | G13: ='SPS4'!J2+'SPS4'!J20-'SPS4'!J55 -> 755.59896 | H13: ='SPS4'!K2+'SPS4'!K20-'SPS4'!K55 -> 671.19023
B14: Domestic production | C14: ='SPS4'!F2 -> 300.18639 | D14: ='SPS4'!G2 -> 294.04758 | E14: ='SPS4'!H2 -> 370.47746 | F14: ='SPS4'!I2 -> 361.01552 | G14: ='SPS4'!J2 -> 404.5204 | H14: ='SPS4'!K2 -> 448.78003
B15: Imports | C15: ='SPS4'!F20 -> 779.50558 | D15: ='SPS4'!G20 -> 702.13551 | E15: ='SPS4'!H20 -> 629.06586 | F15: ='SPS4'!I20 -> 569.10916 | G15: ='SPS4'!J20 -> 370.77429 | H15: ='SPS4'!K20 -> 236.54661
B16: Exports | C16: ='SPS4'!F55 -> 117.17002 | D16: ='SPS4'!G55 -> 35.470499 | E16: ='SPS4'!H55 -> 54.785838 | F16: ='SPS4'!I55 -> 55.659035 | G16: ='SPS4'!J55 -> 19.695736 | H16: ='SPS4'!K55 -> 14.136407
