Workbook

Sheet Variable_List
B2: Variable | C2: Description | D2: Unit | E2: Comment
B3: Primary Production | C3: Domestic primary production of resources | D3: PJ/yr.
B4: Imports | C4: Imports of energy carriers | D4: PJ/yr.
B5: Exports | C5: Exports of energy carriers | D5: PJ/yr.
B6: Electricity generation | C6: Domestic electricity generation | D6: PJ/yr.
B7: Heat generation from CHPs and heat plants | C7: Domestic heat production from CHPs (District heating CHPs or onsite CHPs) and heat plants | D7: PJ/yr.
B8: Fuel input for electricity generation | C8: Fuel input allocated to domestic electricity generation only | D8: PJ/yr.
B9: Fuel input for heat generation from CHPs and heat plants | C9: Fuel input allocated to domestic heat production from CHPs and heat plants only | D9: PJ/yr.
B10: Efficiency of power plants (electric) | C10: Average annual efficiency of power plants and CHPs for electricity production only | D10: % | E10: The thermal efficiency of CHPs can be inferred from the Heat to Electricity production ratio, but it can also be provided; the average efficiency differs from the technical efficiency as it includes efficiency losses due to part load operation
B11: Efficiency of heat plants (thermal) | C11: Average annual efficiency of heat plants | D11: % | E11: It is the annual marketed efficiency including part load efficiency losses and differs from the full load nominal technical efficiency; for heat pumps refers to COP
B12: Domestic biodiesel production | C12: Domestic production of biodiesel | D12: PJ/yr.
B13: Heat from domestic biodiesel production | C13: Heat produced as byproduct from biodiesel production and fed into the district heating network | D13: PJ/yr.
B14: Fuel input for domestic biodiesel production | C14: Fuel input for the domestic production of biodiesel | D14: PJ/yr.
B15: Efficiency for domestic biodiesel production | C15: Average annual efficiency for biodiesel and heat production | D15: %
B16: Domestic ethanol production | C16: Domestic production of ethanol | D16: PJ/yr.
B17: Fuel input for domestic ethanol production | C17: Fuel input for the domestic production of ethanol | D17: PJ/yr.
B18: Efficiency for domestic ethanol production | C18: Average annual efficiency for domestic production of ethanol | D18: %
B19: Domestic biogas production | C19: Domestic production of biogas and biogenic syngas | D19: PJ/yr.
B20: Electricity from domestic biogas production | C20: Electriicty produced as byproduct from biogas production and fed into the grid | D20: PJ/yr.
B21: Heat from domestic biogas production | C21: Heat produced as byproduct from biogas production and fed into the district heating network | D21: PJ/yr.
B22: Fuel input for domestic biogas production | C22: Fuel input for domestic biogas production | D22: PJ/yr.
B23: Efficiency for domestic biogas production | C23: Average annual efficiency for biogas production (accounting for byproduct production) | D23: %
... B25: Fuel input for hydrogen production | C25: Fuel input for deomstic hydrogen production | D25: PJ/yr.
B26: Efficiency for hydrogen production | C26: Average annual efficiency for hydrogen production | D26: % | E26: Including losses due to part load operation
B27: Biomethane production from biogas upgrade | C27: Production of domestic biomethane from biogas | D27: PJ/yr. | E27: One technology only fuel output is biomethane
B28: Fuel input for biogas upgrade to biomethane | C28: Use of biogas for upgrade to biomethane | D28: PJ/yr. | E28: One technology only fuel input is biogas
B29: Efficiency for biomethane production from biogas upgrade | C29: Average annual efficiency of biogas to biomethane upgrade | D29: PJ/yr. | E29: One technology only fuel input is biogas, fuel output is biomethane
B30: Domestic PtG and PtL production | C30: Domestic production of power-to-gas and power-to-liquids | D30: PJ/yr.
B31: Fuel input for domestic PtG and PtL production | C31: Fuel used for domestic PtG and PtL production (excl. CO2) | D31: PJ/yr.
B32: Efficiency for domestic PtG and PtL production | C32: Average annual efficiency for PtG and PtL processes (excl. CO2 consumption) | D32: %
B33: CO2 input for domestic PtG and PtL production | C33: CO2 input for domestic PtG and PtL production | D33: Mt/yr. | E33: The distinction of the source of CO2 (biogenic or fossil) is also provided and can be proportionally allocated to the technologies for PtG and PtL
B34: Domestic wood to pellet production | C34: Wood conversion to pellet domestic production output | D34: PJ/yr. | E34: One technology only , input is wood output is pellet
B35: Fuel input for wood to pellet production | C35: Wood conversion to pellet domestic production - input wood required | D35: PJ/yr. | E35: One technology only , input is wood output is pellet
B36: Efficiency for wood to pellet production | C36: Average annual efficiency of wood to pellet conversion | D36: %
B37: Fuel consumption in industry sectors | C37: Fuel consumption in industry by fuel and technology | D37: PJ/yr. | E37: This unfortunately it will change when the new industrial sectors will be integrated into STEM
B38: Process and space heating production in industry sectors | C38: Energy service demand provided in the form of process and space heating in industry | D38: PJ/yr. | E38: This unfortunately it will change when the new industrial sectors will be integrated into STEM
B39: Efficiency in industry sectors | C39: Boilers efficiency and COP of heat pumps in the industrial sectors | D39: % | E39: This unfortunately it will change when the new industrial sectors will be integrated into STEM
B40: Fuel consumption in Services sectors | C40: Fuel consumption in services sectors by fuel and technology | D40: PJ/yr.
B41: Space water and process heat production in Services sectors | C41: Production of energy service demand for space, water and process heat in Services sectors | D41: PJ/yr.
B42: Efficiency in Services sectors | C42: Boilers efficiency and COP of heat pumps in the Services sectors | D42: %
...

Sheet SPS2
A1: Model | B1: Scenario | C1: Region | D1: Variable | E1: Unit | F1: 2020 | G1: 2022 | H1: 2025 | I1: 2030 | J1: 2040 | K1: 2050
A2: STEM | B2: SPS2 | C2: CH | D2: Primary Production | E2: PJ/yr. | F2: =F3+F8+F11+F12+F16+F17+F18+F19 -> 301.54828 | G2: =G3+G8+G11+G12+G16+G17+G18+G19 -> 297.81097 | H2: =H3+H8+H11+H12+H16+H17+H18+H19 -> 343.8724 | I2: =I3+I8+I11+I12+I16+I17+I18+I19 -> 446.49207 | J2: =J3+J8+J11+J12+J16+J17+J18+J19 -> 527.73722 | K2: =K3+K8+K11+K12+K16+K17+K18+K19 -> 609.55557
A3: =A2 -> STEM | B3: =B2 -> SPS2 | C3: =C2 -> CH | D3: Primary Production|Wood | E3: PJ/yr. | F3: =SUM(F4:F7) -> 46.333865 | G3: =SUM(G4:G7) -> 50.490525 | H3: =SUM(H4:H7) -> 53.867907 | I3: =SUM(I4:I7) -> 53.868286 | J3: =SUM(J4:J7) -> 63.096 | K3: =SUM(K4:K7) -> 71.309367
A4: =A3 -> STEM | B4: =B3 -> SPS2 | C4: =C3 -> CH | D4: Primary Production|Wood|Waste wood | E4: PJ/yr. | F4: {=SUMPRODUCT(("RNWWOD1"=[1]OUT_PrimaryEnergyCons!$A$1:$A$1000)*1,[1]OUT_PrimaryEnergyCons!D$1:D$1000)} -> 11.111903 | G4: {=SUMPRODUCT(("RNWWOD1"=[1]OUT_PrimaryEnergyCons!$A$1:$A$1000)*1,[1]OUT_PrimaryEnergyCons!E$1:E$1000)} -> 11.952908 | H4: {=SUMPRODUCT(("RNWWOD1"=[1]OUT_PrimaryEnergyCons!$A$1:$A$1000)*1,[1]OUT_PrimaryEnergyCons!F$1:F$1000)} -> 13.357204 | I4: {=SUMPRODUCT(("RNWWOD1"=[1]OUT_PrimaryEnergyCons!$A$1:$A$1000)*1,[1]OUT_PrimaryEnergyCons!G$1:G$1000)} -> 15.656169 | J4: {=SUMPRODUCT(("RNWWOD1"=[1]OUT_PrimaryEnergyCons!$A$1:$A$1000)*1,[1]OUT_PrimaryEnergyCons!H$1:H$1000)} -> 17.113653 | K4: {=SUMPRODUCT(("RNWWOD1"=[1]OUT_PrimaryEnergyCons!$A$1:$A$1000)*1,[1]OUT_PrimaryEnergyCons!I$1:I$1000)} -> 18.429692
A5: =A4 -> STEM | B5: =B4 -> SPS2 | C5: =C4 -> CH | D5: Primary Production|Wood|Wood residues | E5: PJ/yr. | F5: {=SUMPRODUCT(("RNWWOD2"=[1]OUT_PrimaryEnergyCons!$A$1:$A$1000)*1,[1]OUT_PrimaryEnergyCons!D$1:D$1000)} -> 7.5116965 | G5: {=SUMPRODUCT(("RNWWOD2"=[1]OUT_PrimaryEnergyCons!$A$1:$A$1000)*1,[1]OUT_PrimaryEnergyCons!E$1:E$1000)} -> 7.5431656 | H5: {=SUMPRODUCT(("RNWWOD2"=[1]OUT_PrimaryEnergyCons!$A$1:$A$1000)*1,[1]OUT_PrimaryEnergyCons!F$1:F$1000)} -> 7.5903571 | I5: {=SUMPRODUCT(("RNWWOD2"=[1]OUT_PrimaryEnergyCons!$A$1:$A$1000)*1,[1]OUT_PrimaryEnergyCons!G$1:G$1000)} -> 7.6690381 | J5: {=SUMPRODUCT(("RNWWOD2"=[1]OUT_PrimaryEnergyCons!$A$1:$A$1000)*1,[1]OUT_PrimaryEnergyCons!H$1:H$1000)} -> 7.6690375 | K5: {=SUMPRODUCT(("RNWWOD2"=[1]OUT_PrimaryEnergyCons!$A$1:$A$1000)*1,[1]OUT_PrimaryEnergyCons!I$1:I$1000)} -> 7.6690479
A6: =A5 -> STEM | B6: =B5 -> SPS2 | C6: =C5 -> CH | D6: Primary Production|Wood|Wood from landscape maintenance | E6: PJ/yr. | F6: {=SUMPRODUCT(("RNWWOD3"=[1]OUT_PrimaryEnergyCons!$A$1:$A$1000)*1,[1]OUT_PrimaryEnergyCons!D$1:D$1000)} -> 3.1682706 | G6: {=SUMPRODUCT(("RNWWOD3"=[1]OUT_PrimaryEnergyCons!$A$1:$A$1000)*1,[1]OUT_PrimaryEnergyCons!E$1:E$1000)} -> 3.4956823 | H6: {=SUMPRODUCT(("RNWWOD3"=[1]OUT_PrimaryEnergyCons!$A$1:$A$1000)*1,[1]OUT_PrimaryEnergyCons!F$1:F$1000)} -> 3.9868229 | I6: {=SUMPRODUCT(("RNWWOD3"=[1]OUT_PrimaryEnergyCons!$A$1:$A$1000)*1,[1]OUT_PrimaryEnergyCons!G$1:G$1000)} -> 4.8053901 | J6: {=SUMPRODUCT(("RNWWOD3"=[1]OUT_PrimaryEnergyCons!$A$1:$A$1000)*1,[1]OUT_PrimaryEnergyCons!H$1:H$1000)} -> 4.8053965 | K6: {=SUMPRODUCT(("RNWWOD3"=[1]OUT_PrimaryEnergyCons!$A$1:$A$1000)*1,[1]OUT_PrimaryEnergyCons!I$1:I$1000)} -> 4.8053924
A7: =A6 -> STEM | B7: =B6 -> SPS2 | C7: =C6 -> CH | D7: Primary Production|Wood|Wood from Forest (hard wood) | E7: PJ/yr. | F7: {=SUMPRODUCT(("RNWWOD4"=[1]OUT_PrimaryEnergyCons!$A$1:$A$1000)*1+("RNWWOD5"=[1]OUT_PrimaryEnergyCons!$A$1:$A$1000)*1,[1]OUT_PrimaryEnergyCons!D$1:D$1000)} -> 24.541995 | G7: {=SUMPRODUCT(("RNWWOD4"=[1]OUT_PrimaryEnergyCons!$A$1:$A$1000)*1+("RNWWOD5"=[1]OUT_PrimaryEnergyCons!$A$1:$A$1000)*1,[1]OUT_PrimaryEnergyCons!E$1:E$1000)} -> 27.49877 | H7: {=SUMPRODUCT(("RNWWOD4"=[1]OUT_PrimaryEnergyCons!$A$1:$A$1000)*1+("RNWWOD5"=[1]OUT_PrimaryEnergyCons!$A$1:$A$1000)*1,[1]OUT_PrimaryEnergyCons!F$1:F$1000)} -> 28.933524 | I7: {=SUMPRODUCT(("RNWWOD4"=[1]OUT_PrimaryEnergyCons!$A$1:$A$1000)*1+("RNWWOD5"=[1]OUT_PrimaryEnergyCons!$A$1:$A$1000)*1,[1]OUT_PrimaryEnergyCons!G$1:G$1000)} -> 25.737689 | J7: {=SUMPRODUCT(("RNWWOD4"=[1]OUT_PrimaryEnergyCons!$A$1:$A$1000)*1+("RNWWOD5"=[1]OUT_PrimaryEnergyCons!$A$1:$A$1000)*1,[1]OUT_PrimaryEnergyCons!H$1:H$1000)} -> 33.507913 | K7: {=SUMPRODUCT(("RNWWOD4"=[1]OUT_PrimaryEnergyCons!$A$1:$A$1000)*1+("RNWWOD5"=[1]OUT_PrimaryEnergyCons!$A$1:$A$1000)*1,[1]OUT_PrimaryEnergyCons!I$1:I$1000)} -> 40.405235
A8: =A7 -> STEM | B8: =B7 -> SPS2 | C8: =C7 -> CH | D8: Primary Production|Waste | E8: PJ/yr. | F8: =SUM(F9:F10) -> 70.031705 | G8: =SUM(G9:G10) -> 70.319901 | H8: =SUM(H9:H10) -> 70.133321 | I8: =SUM(I9:I10) -> 74.600169 | J8: =SUM(J9:J10) -> 79.195771 | K8: =SUM(K9:K10) -> 83.828059
A9: =A8 -> STEM | B9: =B8 -> SPS2 | C9: =C8 -> CH | D9: Primary Production|Waste|Non renewable waste | E9: PJ/yr. | F9: {=SUMPRODUCT(("RNNWWST1"=[1]OUT_PrimaryEnergyCons!$A$1:$A$1000)*1,[1]OUT_PrimaryEnergyCons!D$1:D$1000)} -> 35.93121 | G9: {=SUMPRODUCT(("RNNWWST1"=[1]OUT_PrimaryEnergyCons!$A$1:$A$1000)*1,[1]OUT_PrimaryEnergyCons!E$1:E$1000)} -> 36.218777 | H9: {=SUMPRODUCT(("RNNWWST1"=[1]OUT_PrimaryEnergyCons!$A$1:$A$1000)*1,[1]OUT_PrimaryEnergyCons!F$1:F$1000)} -> 36.032188 | I9: {=SUMPRODUCT(("RNNWWST1"=[1]OUT_PrimaryEnergyCons!$A$1:$A$1000)*1,[1]OUT_PrimaryEnergyCons!G$1:G$1000)} -> 37.19809 | J9: {=SUMPRODUCT(("RNNWWST1"=[1]OUT_PrimaryEnergyCons!$A$1:$A$1000)*1,[1]OUT_PrimaryEnergyCons!H$1:H$1000)} -> 38.082534 | K9: {=SUMPRODUCT(("RNNWWST1"=[1]OUT_PrimaryEnergyCons!$A$1:$A$1000)*1,[1]OUT_PrimaryEnergyCons!I$1:I$1000)} -> 39.221671
A10: =A9 -> STEM | B10: =B9 -> SPS2 | C10: =C9 -> CH | D10: Primary Production|Waste|Renewable waste | E10: PJ/yr. | F10: {=SUMPRODUCT(("RNWWST1"=[1]OUT_PrimaryEnergyCons!$A$1:$A$1000)*1,[1]OUT_PrimaryEnergyCons!D$1:D$1000)} -> 34.100495 | G10: {=SUMPRODUCT(("RNWWST1"=[1]OUT_PrimaryEnergyCons!$A$1:$A$1000)*1,[1]OUT_PrimaryEnergyCons!E$1:E$1000)} -> 34.101124 | H10: {=SUMPRODUCT(("RNWWST1"=[1]OUT_PrimaryEnergyCons!$A$1:$A$1000)*1,[1]OUT_PrimaryEnergyCons!F$1:F$1000)} -> 34.101133 | I10: {=SUMPRODUCT(("RNWWST1"=[1]OUT_PrimaryEnergyCons!$A$1:$A$1000)*1,[1]OUT_PrimaryEnergyCons!G$1:G$1000)} -> 37.402079 | J10: {=SUMPRODUCT(("RNWWST1"=[1]OUT_PrimaryEnergyCons!$A$1:$A$1000)*1,[1]OUT_PrimaryEnergyCons!H$1:H$1000)} -> 41.113237 | K10: {=SUMPRODUCT(("RNWWST1"=[1]OUT_PrimaryEnergyCons!$A$1:$A$1000)*1,[1]OUT_PrimaryEnergyCons!I$1:I$1000)} -> 44.606388
A11: =A10 -> STEM | B11: =B10 -> SPS2 | C11: =C10 -> CH | D11: Primary Production|Manure | E11: PJ/yr. | F11: {=SUMPRODUCT(("mnr"=[1]OUT_PrimaryEnergyCons!$C$1:$C$1000)*1,[1]OUT_PrimaryEnergyCons!D$1:D$1000)} -> 3.7981374 | G11: {=SUMPRODUCT(("mnr"=[1]OUT_PrimaryEnergyCons!$C$1:$C$1000)*1,[1]OUT_PrimaryEnergyCons!E$1:E$1000)} -> 12.54043 | H11: {=SUMPRODUCT(("mnr"=[1]OUT_PrimaryEnergyCons!$C$1:$C$1000)*1,[1]OUT_PrimaryEnergyCons!F$1:F$1000)} -> 12.540447 | I11: {=SUMPRODUCT(("mnr"=[1]OUT_PrimaryEnergyCons!$C$1:$C$1000)*1,[1]OUT_PrimaryEnergyCons!G$1:G$1000)} -> 12.540468 | J11: {=SUMPRODUCT(("mnr"=[1]OUT_PrimaryEnergyCons!$C$1:$C$1000)*1,[1]OUT_PrimaryEnergyCons!H$1:H$1000)} -> 17.360275 | K11: {=SUMPRODUCT(("mnr"=[1]OUT_PrimaryEnergyCons!$C$1:$C$1000)*1,[1]OUT_PrimaryEnergyCons!I$1:I$1000)} -> 18.829755
A12: =A11 -> STEM | B12: =B11 -> SPS2 | C12: =C11 -> CH | D12: Primary Production|Hydro | E12: PJ/yr. | F12: =SUM(F13:F15) -> 149.43051 | G12: =SUM(G13:G15) -> 125.611 | H12: =SUM(H13:H15) -> 144.60422 | I12: =SUM(I13:I15) -> 184.76924 | J12: =SUM(J13:J15) -> 155.06378 | K12: =SUM(K13:K15) -> 159.23144
A13: =A12 -> STEM | B13: =B12 -> SPS2 | C13: =C12 -> CH | D13: Primary Production|Hydro|Large hydro | E13: PJ/yr. | F13: {=SUMPRODUCT(ISNUMBER(SEARCH("EHYD-DAM",[1]OUT_Electricity_CHP!$B$1:$B$10000))*1,([1]OUT_Electricity_CHP!$C$1:$C$10000="Var_Fout")*1,ISNUMBER(SEARCH("ELC",[1]OUT_Electricity_CHP!$D$1:$D$10000))*1,[1]OUT_Electricity_CHP!E$1:E$10000)} -> 66.745681 | G13: {=SUMPRODUCT(ISNUMBER(SEARCH("EHYD-DAM",[1]OUT_Electricity_CHP!$B$1:$B$10000))*1,([1]OUT_Electricity_CHP!$C$1:$C$10000="Var_Fout")*1,ISNUMBER(SEARCH("ELC",[1]OUT_Electricity_CHP!$D$1:$D$10000))*1,[1]OUT_Electricity_CHP!F$1:F$10000)} -> 49.798798 | H13: {=SUMPRODUCT(ISNUMBER(SEARCH("EHYD-DAM",[1]OUT_Electricity_CHP!$B$1:$B$10000))*1,([1]OUT_Electricity_CHP!$C$1:$C$10000="Var_Fout")*1,ISNUMBER(SEARCH("ELC",[1]OUT_Electricity_CHP!$D$1:$D$10000))*1,[1]OUT_Electricity_CHP!G$1:G$10000)} -> 68.519822 | I13: {=SUMPRODUCT(ISNUMBER(SEARCH("EHYD-DAM",[1]OUT_Electricity_CHP!$B$1:$B$10000))*1,([1]OUT_Electricity_CHP!$C$1:$C$10000="Var_Fout")*1,ISNUMBER(SEARCH("ELC",[1]OUT_Electricity_CHP!$D$1:$D$10000))*1,[1]OUT_Electricity_CHP!H$1:H$10000)} -> 68.564273 | J13: {=SUMPRODUCT(ISNUMBER(SEARCH("EHYD-DAM",[1]OUT_Electricity_CHP!$B$1:$B$10000))*1,([1]OUT_Electricity_CHP!$C$1:$C$10000="Var_Fout")*1,ISNUMBER(SEARCH("ELC",[1]OUT_Electricity_CHP!$D$1:$D$10000))*1,[1]OUT_Electricity_CHP!I$1:I$10000)} -> 71.347195 | K13: {=SUMPRODUCT(ISNUMBER(SEARCH("EHYD-DAM",[1]OUT_Electricity_CHP!$B$1:$B$10000))*1,([1]OUT_Electricity_CHP!$C$1:$C$10000="Var_Fout")*1,ISNUMBER(SEARCH("ELC",[1]OUT_Electricity_CHP!$D$1:$D$10000))*1,[1]OUT_Electricity_CHP!J$1:J$10000)} -> 74.836062
A14: =A13 -> STEM | B14: =B13 -> SPS2 | C14: =C13 -> CH | D14: Primary Production|Hydro|Run-of-river hydro | E14: PJ/yr. | F14: {=SUMPRODUCT(ISNUMBER(SEARCH("EHYD-RUN",[1]OUT_Electricity_CHP!$B$1:$B$10000))*1,([1]OUT_Electricity_CHP!$C$1:$C$10000="Var_Fout")*1,ISNUMBER(SEARCH("ELC",[1]OUT_Electricity_CHP!$D$1:$D$10000))*1,[1]OUT_Electricity_CHP!E$1:E$10000)} -> 66.632411 | G14: {=SUMPRODUCT(ISNUMBER(SEARCH("EHYD-RUN",[1]OUT_Electricity_CHP!$B$1:$B$10000))*1,([1]OUT_Electricity_CHP!$C$1:$C$10000="Var_Fout")*1,ISNUMBER(SEARCH("ELC",[1]OUT_Electricity_CHP!$D$1:$D$10000))*1,[1]OUT_Electricity_CHP!F$1:F$10000)} -> 55.764007 | H14: {=SUMPRODUCT(ISNUMBER(SEARCH("EHYD-RUN",[1]OUT_Electricity_CHP!$B$1:$B$10000))*1,([1]OUT_Electricity_CHP!$C$1:$C$10000="Var_Fout")*1,ISNUMBER(SEARCH("ELC",[1]OUT_Electricity_CHP!$D$1:$D$10000))*1,[1]OUT_Electricity_CHP!G$1:G$10000)} -> 65.566171 | I14: {=SUMPRODUCT(ISNUMBER(SEARCH("EHYD-RUN",[1]OUT_Electricity_CHP!$B$1:$B$10000))*1,([1]OUT_Electricity_CHP!$C$1:$C$10000="Var_Fout")*1,ISNUMBER(SEARCH("ELC",[1]OUT_Electricity_CHP!$D$1:$D$10000))*1,[1]OUT_Electricity_CHP!H$1:H$10000)} -> 66.917163 | J14: {=SUMPRODUCT(ISNUMBER(SEARCH("EHYD-RUN",[1]OUT_Electricity_CHP!$B$1:$B$10000))*1,([1]OUT_Electricity_CHP!$C$1:$C$10000="Var_Fout")*1,ISNUMBER(SEARCH("ELC",[1]OUT_Electricity_CHP!$D$1:$D$10000))*1,[1]OUT_Electricity_CHP!I$1:I$10000)} -> 66.967455 | K14: {=SUMPRODUCT(ISNUMBER(SEARCH("EHYD-RUN",[1]OUT_Electricity_CHP!$B$1:$B$10000))*1,([1]OUT_Electricity_CHP!$C$1:$C$10000="Var_Fout")*1,ISNUMBER(SEARCH("ELC",[1]OUT_Electricity_CHP!$D$1:$D$10000))*1,[1]OUT_Electricity_CHP!J$1:J$10000)} -> 67.135005
A15: =A14 -> STEM | B15: =B14 -> SPS2 | C15: =C14 -> CH | D15: Primary Production|Hydro|Pump storage | E15: PJ/yr. | F15: {=SUMPRODUCT(ISNUMBER(SEARCH("EHYD-PUM",[1]OUT_Electricity_CHP!$B$1:$B$10000))*1,([1]OUT_Electricity_CHP!$C$1:$C$10000="Var_Fin")*1,ISNUMBER(SEARCH("elc",[1]OUT_Electricity_CHP!$D$1:$D$10000))*1,[1]OUT_Electricity_CHP!E$1:E$10000)} -> 16.052418 | G15: {=SUMPRODUCT(ISNUMBER(SEARCH("EHYD-PUM",[1]OUT_Electricity_CHP!$B$1:$B$10000))*1,([1]OUT_Electricity_CHP!$C$1:$C$10000="Var_Fin")*1,ISNUMBER(SEARCH("elc",[1]OUT_Electricity_CHP!$D$1:$D$10000))*1,[1]OUT_Electricity_CHP!F$1:F$10000)} -> 20.048191 | H15: {=SUMPRODUCT(ISNUMBER(SEARCH("EHYD-PUM",[1]OUT_Electricity_CHP!$B$1:$B$10000))*1,([1]OUT_Electricity_CHP!$C$1:$C$10000="Var_Fin")*1,ISNUMBER(SEARCH("elc",[1]OUT_Electricity_CHP!$D$1:$D$10000))*1,[1]OUT_Electricity_CHP!G$1:G$10000)} -> 10.518226 | I15: {=SUMPRODUCT(ISNUMBER(SEARCH("EHYD-PUM",[1]OUT_Electricity_CHP!$B$1:$B$10000))*1,([1]OUT_Electricity_CHP!$C$1:$C$10000="Var_Fin")*1,ISNUMBER(SEARCH("elc",[1]OUT_Electricity_CHP!$D$1:$D$10000))*1,[1]OUT_Electricity_CHP!H$1:H$10000)} -> 49.287806 | J15: {=SUMPRODUCT(ISNUMBER(SEARCH("EHYD-PUM",[1]OUT_Electricity_CHP!$B$1:$B$10000))*1,([1]OUT_Electricity_CHP!$C$1:$C$10000="Var_Fin")*1,ISNUMBER(SEARCH("elc",[1]OUT_Electricity_CHP!$D$1:$D$10000))*1,[1]OUT_Electricity_CHP!I$1:I$10000)} -> 16.749133 | K15: {=SUMPRODUCT(ISNUMBER(SEARCH("EHYD-PUM",[1]OUT_Electricity_CHP!$B$1:$B$10000))*1,([1]OUT_Electricity_CHP!$C$1:$C$10000="Var_Fin")*1,ISNUMBER(SEARCH("elc",[1]OUT_Electricity_CHP!$D$1:$D$10000))*1,[1]OUT_Electricity_CHP!J$1:J$10000)} -> 17.260376
A16: =A15 -> STEM | B16: =B15 -> SPS2 | C16: =C15 -> CH | D16: Primary Production|Solar | E16: PJ/yr. | F16: {=SUMPRODUCT(ISNUMBER(SEARCH("SOL",[1]OUT_PrimaryEnergyCons!$C$1:$C$1000))*1,[1]OUT_PrimaryEnergyCons!D$1:D$1000)} -> 12.556629 | G16: {=SUMPRODUCT(ISNUMBER(SEARCH("SOL",[1]OUT_PrimaryEnergyCons!$C$1:$C$1000))*1,[1]OUT_PrimaryEnergyCons!E$1:E$1000)} -> 16.524079 | H16: {=SUMPRODUCT(ISNUMBER(SEARCH("SOL",[1]OUT_PrimaryEnergyCons!$C$1:$C$1000))*1,[1]OUT_PrimaryEnergyCons!F$1:F$1000)} -> 30.408888 | I16: {=SUMPRODUCT(ISNUMBER(SEARCH("SOL",[1]OUT_PrimaryEnergyCons!$C$1:$C$1000))*1,[1]OUT_PrimaryEnergyCons!G$1:G$1000)} -> 64.437687 | J16: {=SUMPRODUCT(ISNUMBER(SEARCH("SOL",[1]OUT_PrimaryEnergyCons!$C$1:$C$1000))*1,[1]OUT_PrimaryEnergyCons!H$1:H$1000)} -> 124.43248 | K16: {=SUMPRODUCT(ISNUMBER(SEARCH("SOL",[1]OUT_PrimaryEnergyCons!$C$1:$C$1000))*1,[1]OUT_PrimaryEnergyCons!I$1:I$1000)} -> 160.45518
A17: =A16 -> STEM | B17: =B16 -> SPS2 | C17: =C16 -> CH | D17: Primary Production|Wind | E17: PJ/yr. | F17: {=SUMPRODUCT(ISNUMBER(SEARCH("wnd",[1]OUT_PrimaryEnergyCons!$C$1:$C$1000))*1,[1]OUT_PrimaryEnergyCons!D$1:D$1000)} -> 0.52406099 | G17: {=SUMPRODUCT(ISNUMBER(SEARCH("wnd",[1]OUT_PrimaryEnergyCons!$C$1:$C$1000))*1,[1]OUT_PrimaryEnergyCons!E$1:E$1000)} -> 0.54530604 | H17: {=SUMPRODUCT(ISNUMBER(SEARCH("wnd",[1]OUT_PrimaryEnergyCons!$C$1:$C$1000))*1,[1]OUT_PrimaryEnergyCons!F$1:F$1000)} -> 0.50317864 | I17: {=SUMPRODUCT(ISNUMBER(SEARCH("wnd",[1]OUT_PrimaryEnergyCons!$C$1:$C$1000))*1,[1]OUT_PrimaryEnergyCons!G$1:G$1000)} -> 2.0503199 | J17: {=SUMPRODUCT(ISNUMBER(SEARCH("wnd",[1]OUT_PrimaryEnergyCons!$C$1:$C$1000))*1,[1]OUT_PrimaryEnergyCons!H$1:H$1000)} -> 7.1993963 | K17: {=SUMPRODUCT(ISNUMBER(SEARCH("wnd",[1]OUT_PrimaryEnergyCons!$C$1:$C$1000))*1,[1]OUT_PrimaryEnergyCons!I$1:I$1000)} -> 26.771463
A18: =A17 -> STEM | B18: =B17 -> SPS2 | C18: =C17 -> CH | D18: Primary Production|Ambient heat | E18: PJ/yr. | F18: =[1]Overview!B$9-F19 -> 18.873374 | G18: =[1]Overview!C$9-G19 -> 21.779739 | H18: =[1]Overview!D$9-H19 -> 31.814435 | I18: =[1]Overview!E$9-I19 -> 54.225898 | J18: =[1]Overview!F$9-J19 -> 81.301876 | K18: =[1]Overview!G$9-K19 -> 88.575822
A19: =A18 -> STEM | B19: =B18 -> SPS2 | C19: =C18 -> CH | D19: Primary Production|Geothermal | E19: PJ/yr. | F19: =+[1]Overview!B$28 -> 0 | G19: =+[1]Overview!C$28 -> 0 | H19: =+[1]Overview!D$28 -> 0 | I19: =+[1]Overview!E$28 -> 0 | J19: =+[1]Overview!F$28 -> 0.087642834 | K19: =+[1]Overview!G$28 -> 0.55448157
A20: =A19 -> STEM | B20: =B19 -> SPS2 | C20: =C19 -> CH | D20: Imports | E20: PJ/yr. | F20: =SUM(F21:F22,F39,F48:F49,F54) -> 780.77715 | G20: =SUM(G21:G22,G39,G48:G49,G54) -> 701.3693 | H20: =SUM(H21:H22,H39,H48:H49,H54) -> 619.37916 | I20: =SUM(I21:I22,I39,I48:I49,I54) -> 492.31757 | J20: =SUM(J21:J22,J39,J48:J49,J54) -> 214.36869 | K20: =SUM(K21:K22,K39,K48:K49,K54) -> 88.108549
A21: =A20 -> STEM | B21: =B20 -> SPS2 | C21: =C20 -> CH | D21: Imports|Coal | E21: PJ/yr. | F21: {=SUMPRODUCT(("COA"=[1]OUT_PrimaryEnergyCons!$C$4:$C$10000)*1,[1]OUT_PrimaryEnergyCons!D$4:D$10000)} -> 3.6601003 | G21: {=SUMPRODUCT(("COA"=[1]OUT_PrimaryEnergyCons!$C$4:$C$10000)*1,[1]OUT_PrimaryEnergyCons!E$4:E$10000)} -> 3.5647439 | H21: {=SUMPRODUCT(("COA"=[1]OUT_PrimaryEnergyCons!$C$4:$C$10000)*1,[1]OUT_PrimaryEnergyCons!F$4:F$10000)} -> 3.2455495 | I21: {=SUMPRODUCT(("COA"=[1]OUT_PrimaryEnergyCons!$C$4:$C$10000)*1,[1]OUT_PrimaryEnergyCons!G$4:G$10000)} -> 0.00087668908 | J21: {=SUMPRODUCT(("COA"=[1]OUT_PrimaryEnergyCons!$C$4:$C$10000)*1,[1]OUT_PrimaryEnergyCons!H$4:H$10000)} -> 0.0010123174 | K21: {=SUMPRODUCT(("COA"=[1]OUT_PrimaryEnergyCons!$C$4:$C$10000)*1,[1]OUT_PrimaryEnergyCons!I$4:I$10000)} -> 2.4086008e-05
A22: =A21 -> STEM | B22: =B21 -> SPS2 | C22: =C21 -> CH | D22: Imports|Oil | E22: PJ/yr. | F22: =F23+F29 -> 311.75784 | G22: =G23+G29 -> 287.50764 | H22: =H23+H29 -> 260.57945 | I22: =I23+I29 -> 152.17607 | J22: =J23+J29 -> 70.32072 | K22: =K23+K29 -> 69.861852
A23: =A22 -> STEM | B23: =B22 -> SPS2 | C23: =C22 -> CH | D23: Imports|Oil|Fossil liquids | E23: PJ/yr. | F23: =SUM(F24:F28) -> 305.79769 | G23: =SUM(G24:G28) -> 281.54797 | H23: =SUM(H24:H28) -> 254.61973 | I23: =SUM(I24:I28) -> 142.52468 | J23: =SUM(J24:J28) -> 39.375931 | K23: =SUM(K24:K28) -> 0
A24: =A22 -> STEM | B24: =B23 -> SPS2 | C24: =C22 -> CH | D24: Imports|Oil|Fossil liquids|Light fuel oil | E24: PJ/yr. | F24: {=SUMPRODUCT(("LFO"=[1]OUT_PrimaryEnergyCons!$C$4:$C$10000)*1,[1]OUT_PrimaryEnergyCons!D$4:D$10000)} -> 101.79822 | G24: {=SUMPRODUCT(("LFO"=[1]OUT_PrimaryEnergyCons!$C$4:$C$10000)*1,[1]OUT_PrimaryEnergyCons!E$4:E$10000)} -> 88.320908 | H24: {=SUMPRODUCT(("LFO"=[1]OUT_PrimaryEnergyCons!$C$4:$C$10000)*1,[1]OUT_PrimaryEnergyCons!F$4:F$10000)} -> 83.346079 | I24: {=SUMPRODUCT(("LFO"=[1]OUT_PrimaryEnergyCons!$C$4:$C$10000)*1,[1]OUT_PrimaryEnergyCons!G$4:G$10000)} -> 46.240763 | J24: {=SUMPRODUCT(("LFO"=[1]OUT_PrimaryEnergyCons!$C$4:$C$10000)*1,[1]OUT_PrimaryEnergyCons!H$4:H$10000)} -> 14.143513 | K24: {=SUMPRODUCT(("LFO"=[1]OUT_PrimaryEnergyCons!$C$4:$C$10000)*1,[1]OUT_PrimaryEnergyCons!I$4:I$10000)} -> 0
A25: =A24 -> STEM | B25: =B24 -> SPS2 | C25: =C24 -> CH | D25: Imports|Oil|Fossil liquids|Heavy fuel oil | E25: PJ/yr. | F25: {=SUMPRODUCT(("HFO"=[1]OUT_PrimaryEnergyCons!$C$4:$C$10000)*1,[1]OUT_PrimaryEnergyCons!D$4:D$10000)} -> 2.7764107 | G25: {=SUMPRODUCT(("HFO"=[1]OUT_PrimaryEnergyCons!$C$4:$C$10000)*1,[1]OUT_PrimaryEnergyCons!E$4:E$10000)} -> 2.6594468 | H25: {=SUMPRODUCT(("HFO"=[1]OUT_PrimaryEnergyCons!$C$4:$C$10000)*1,[1]OUT_PrimaryEnergyCons!F$4:F$10000)} -> 0.011123702 | I25: {=SUMPRODUCT(("HFO"=[1]OUT_PrimaryEnergyCons!$C$4:$C$10000)*1,[1]OUT_PrimaryEnergyCons!G$4:G$10000)} -> 0.00066164722 | J25: {=SUMPRODUCT(("HFO"=[1]OUT_PrimaryEnergyCons!$C$4:$C$10000)*1,[1]OUT_PrimaryEnergyCons!H$4:H$10000)} -> 0.0010107088 | K25: {=SUMPRODUCT(("HFO"=[1]OUT_PrimaryEnergyCons!$C$4:$C$10000)*1,[1]OUT_PrimaryEnergyCons!I$4:I$10000)} -> 0
A26: =A25 -> STEM | B26: =B25 -> SPS2 | C26: =C25 -> CH | D26: Imports|Oil|Fossil liquids|Motor Diesel | E26: PJ/yr. | F26: {=SUMPRODUCT(("DSL"=[1]OUT_PrimaryEnergyCons!$C$4:$C$10000)*1,[1]OUT_PrimaryEnergyCons!D$4:D$10000)} -> 121.64759 | G26: {=SUMPRODUCT(("DSL"=[1]OUT_PrimaryEnergyCons!$C$4:$C$10000)*1,[1]OUT_PrimaryEnergyCons!E$4:E$10000)} -> 112.68599 | H26: {=SUMPRODUCT(("DSL"=[1]OUT_PrimaryEnergyCons!$C$4:$C$10000)*1,[1]OUT_PrimaryEnergyCons!F$4:F$10000)} -> 96.478283 | I26: {=SUMPRODUCT(("DSL"=[1]OUT_PrimaryEnergyCons!$C$4:$C$10000)*1,[1]OUT_PrimaryEnergyCons!G$4:G$10000)} -> 55.499007 | J26: {=SUMPRODUCT(("DSL"=[1]OUT_PrimaryEnergyCons!$C$4:$C$10000)*1,[1]OUT_PrimaryEnergyCons!H$4:H$10000)} -> 20.445675 | K26: {=SUMPRODUCT(("DSL"=[1]OUT_PrimaryEnergyCons!$C$4:$C$10000)*1,[1]OUT_PrimaryEnergyCons!I$4:I$10000)} -> 0
A27: =A26 -> STEM | B27: =B26 -> SPS2 | C27: =C26 -> CH | D27: Imports|Oil|Fossil liquids|Motor Gasoline | E27: PJ/yr. | F27: {=SUMPRODUCT(("GSL"=[1]OUT_PrimaryEnergyCons!$C$4:$C$10000)*1,[1]OUT_PrimaryEnergyCons!D$4:D$10000)} -> 78.466105 | G27: {=SUMPRODUCT(("GSL"=[1]OUT_PrimaryEnergyCons!$C$4:$C$10000)*1,[1]OUT_PrimaryEnergyCons!E$4:E$10000)} -> 76.476615 | H27: {=SUMPRODUCT(("GSL"=[1]OUT_PrimaryEnergyCons!$C$4:$C$10000)*1,[1]OUT_PrimaryEnergyCons!F$4:F$10000)} -> 72.940811 | I27: {=SUMPRODUCT(("GSL"=[1]OUT_PrimaryEnergyCons!$C$4:$C$10000)*1,[1]OUT_PrimaryEnergyCons!G$4:G$10000)} -> 38.214028 | J27: {=SUMPRODUCT(("GSL"=[1]OUT_PrimaryEnergyCons!$C$4:$C$10000)*1,[1]OUT_PrimaryEnergyCons!H$4:H$10000)} -> 2.676546 | K27: {=SUMPRODUCT(("GSL"=[1]OUT_PrimaryEnergyCons!$C$4:$C$10000)*1,[1]OUT_PrimaryEnergyCons!I$4:I$10000)} -> 0
A28: =A27 -> STEM | B28: =B27 -> SPS2 | C28: =C27 -> CH | D28: Imports|Oil|Fossil liquids|Kerosene (excl. international aviation) | E28: PJ/yr. | F28: {=SUMPRODUCT(("KER"=[1]OUT_PrimaryEnergyCons!$C$4:$C$10000)*1,[1]OUT_PrimaryEnergyCons!D$4:D$10000)} -> 1.1093666 | G28: {=SUMPRODUCT(("KER"=[1]OUT_PrimaryEnergyCons!$C$4:$C$10000)*1,[1]OUT_PrimaryEnergyCons!E$4:E$10000)} -> 1.4050063 | H28: {=SUMPRODUCT(("KER"=[1]OUT_PrimaryEnergyCons!$C$4:$C$10000)*1,[1]OUT_PrimaryEnergyCons!F$4:F$10000)} -> 1.8434315 | I28: {=SUMPRODUCT(("KER"=[1]OUT_PrimaryEnergyCons!$C$4:$C$10000)*1,[1]OUT_PrimaryEnergyCons!G$4:G$10000)} -> 2.57022 | J28: {=SUMPRODUCT(("KER"=[1]OUT_PrimaryEnergyCons!$C$4:$C$10000)*1,[1]OUT_PrimaryEnergyCons!H$4:H$10000)} -> 2.1091871 | K28: {=SUMPRODUCT(("KER"=[1]OUT_PrimaryEnergyCons!$C$4:$C$10000)*1,[1]OUT_PrimaryEnergyCons!I$4:I$10000)} -> 0
A29: =A48 -> STEM | B29: =B28 -> SPS2 | C29: =C48 -> CH | D29: Imports|Oil|Synthetic liquids | E29: PJ/yr. | F29: =SUM(F30:F31) -> 5.9601413 | G29: =SUM(G30:G31) -> 5.9596731 | H29: =SUM(H30:H31) -> 5.9597177 | I29: =SUM(I30:I31) -> 9.6513884 | J29: =SUM(J30:J31) -> 30.944788 | K29: =SUM(K30:K31) -> 69.861852
A30: =A35 -> STEM | B30: =B29 -> SPS2 | C30: =C35 -> CH | D30: Imports|Oil|Synthetic liquids|Total|Motor diesel | E30: PJ/yr. | F30: {=SUMPRODUCT(ISNUMBER(SEARCH("IMPBDS",[1]OUT_SyntheticFuels!$C$4:$C$1000))*1,("Var_Fout"=[1]OUT_SyntheticFuels!$B$4:$B$1000)*1,[1]OUT_SyntheticFuels!E$4:E$1000)} -> 2.8772619 | G30: {=SUMPRODUCT(ISNUMBER(SEARCH("IMPBDS",[1]OUT_SyntheticFuels!$C$4:$C$1000))*1,("Var_Fout"=[1]OUT_SyntheticFuels!$B$4:$B$1000)*1,[1]OUT_SyntheticFuels!F$4:F$1000)} -> 1.8120741 | H30: {=SUMPRODUCT(ISNUMBER(SEARCH("IMPBDS",[1]OUT_SyntheticFuels!$C$4:$C$1000))*1,("Var_Fout"=[1]OUT_SyntheticFuels!$B$4:$B$1000)*1,[1]OUT_SyntheticFuels!G$4:G$1000)} -> 3.3314785 | I30: {=SUMPRODUCT(ISNUMBER(SEARCH("IMPBDS",[1]OUT_SyntheticFuels!$C$4:$C$1000))*1,("Var_Fout"=[1]OUT_SyntheticFuels!$B$4:$B$1000)*1,[1]OUT_SyntheticFuels!H$4:H$1000)} -> 6.5379602 | J30: {=SUMPRODUCT(ISNUMBER(SEARCH("IMPBDS",[1]OUT_SyntheticFuels!$C$4:$C$1000))*1,("Var_Fout"=[1]OUT_SyntheticFuels!$B$4:$B$1000)*1,[1]OUT_SyntheticFuels!I$4:I$1000)} -> 26.856526 | K30: {=SUMPRODUCT(ISNUMBER(SEARCH("IMPBDS",[1]OUT_SyntheticFuels!$C$4:$C$1000))*1,("Var_Fout"=[1]OUT_SyntheticFuels!$B$4:$B$1000)*1,[1]OUT_SyntheticFuels!J$4:J$1000)} -> 69.782923
A31: =A30 -> STEM | B31: =B30 -> SPS2 | C31: =C30 -> CH | D31: Imports|Oil|Synthetic liquids|Total|Motor Gasoline | E31: PJ/yr. | F31: {=SUMPRODUCT(ISNUMBER(SEARCH("IMPeth",[1]OUT_SyntheticFuels!$C$4:$C$1000))*1,("Var_Fout"=[1]OUT_SyntheticFuels!$B$4:$B$1000)*1,[1]OUT_SyntheticFuels!E$4:E$1000)} -> 3.0828794 | G31: {=SUMPRODUCT(ISNUMBER(SEARCH("IMPeth",[1]OUT_SyntheticFuels!$C$4:$C$1000))*1,("Var_Fout"=[1]OUT_SyntheticFuels!$B$4:$B$1000)*1,[1]OUT_SyntheticFuels!F$4:F$1000)} -> 4.147599 | H31: {=SUMPRODUCT(ISNUMBER(SEARCH("IMPeth",[1]OUT_SyntheticFuels!$C$4:$C$1000))*1,("Var_Fout"=[1]OUT_SyntheticFuels!$B$4:$B$1000)*1,[1]OUT_SyntheticFuels!G$4:G$1000)} -> 2.6282392 | I31: {=SUMPRODUCT(ISNUMBER(SEARCH("IMPeth",[1]OUT_SyntheticFuels!$C$4:$C$1000))*1,("Var_Fout"=[1]OUT_SyntheticFuels!$B$4:$B$1000)*1,[1]OUT_SyntheticFuels!H$4:H$1000)} -> 3.1134281 | J31: {=SUMPRODUCT(ISNUMBER(SEARCH("IMPeth",[1]OUT_SyntheticFuels!$C$4:$C$1000))*1,("Var_Fout"=[1]OUT_SyntheticFuels!$B$4:$B$1000)*1,[1]OUT_SyntheticFuels!I$4:I$1000)} -> 4.0882628 | K31: {=SUMPRODUCT(ISNUMBER(SEARCH("IMPeth",[1]OUT_SyntheticFuels!$C$4:$C$1000))*1,("Var_Fout"=[1]OUT_SyntheticFuels!$B$4:$B$1000)*1,[1]OUT_SyntheticFuels!J$4:J$1000)} -> 0.078928227
A32: =A29 -> STEM | B32: =B31 -> SPS2 | C32: =C29 -> CH | D32: Imports|Oil|Synthetic liquids|Bioliquids|Total | E32: PJ/yr. | F32: =SUM(F33:F34) -> 5.9601413 | G32: =SUM(G33:G34) -> 5.9596731 | H32: =SUM(H33:H34) -> 5.9597177 | I32: =SUM(I33:I34) -> 9.6513884 | J32: =SUM(J33:J34) -> 10.626223 | K32: =SUM(K33:K34) -> 26.935454
A33: =A31 -> STEM | B33: =B32 -> SPS2 | C33: =C31 -> CH | D33: Imports|Oil|Synthetic liquids|Bioliquids|Biodiesel | E33: PJ/yr. | F33: =F30 -> 2.8772619 | G33: =G30 -> 1.8120741 | H33: =H30 -> 3.3314785 | I33: =I30 -> 6.5379602 | J33: =IF(J30-MAX(F30:I30)<0,J30,MAX(F30:I30)) -> 6.5379602 | K33: =IF(K30-MAX(F30:J30)<0,K30,MAX(F30:J30)) -> 26.856526
A34: =A33 -> STEM | B34: =B33 -> SPS2 | C34: =C33 -> CH | D34: Imports|Oil|Synthetic liquids|Bioliquids|Ethanol | E34: PJ/yr. | F34: =F31 -> 3.0828794 | G34: =G31 -> 4.147599 | H34: =H31 -> 2.6282392 | I34: =I31 -> 3.1134281 | J34: =IF(J31-MAX(F31:I31)<0,J31,MAX(F31:I31)) -> 4.0882628 | K34: =IF(K31-MAX(F31:J31)<0,K31,MAX(F31:J31)) -> 0.078928227
A35: =A32 -> STEM | B35: =B34 -> SPS2 | C35: =C32 -> CH | D35: Imports|Oil|Synthetic liquids|PtL | E35: PJ/yr. | F35: =SUM(F36:F37) -> 0 | G35: =SUM(G36:G37) -> 0 | H35: =SUM(H36:H37) -> 0 | I35: =SUM(I36:I37) -> 0 | J35: =SUM(J36:J37) -> 20.318565 | K35: =SUM(K36:K37) -> 42.926398
A36: =A34 -> STEM | B36: =B35 -> SPS2 | C36: =C34 -> CH | D36: Imports|Oil|Synthetic liquids|PtL|PtL Diesel | E36: PJ/yr. | F36: 0 | G36: 0 | H36: 0 | I36: 0 | J36: =J30-J33 -> 20.318565 | K36: =K30-K33 -> 42.926398
A37: =A36 -> STEM | B37: =B36 -> SPS2 | C37: =C36 -> CH | D37: Imports|Oil|Synthetic liquids|PtL|PtL Gasoline | E37: PJ/yr. | F37: 0 | G37: 0 | H37: 0 | I37: 0 | J37: =J31-J34 -> 0 | K37: =K31-K34 -> 0
B38: =B37 -> SPS2 | C38: =C37 -> CH | D38: Imports|Oil|Synthetic liquids|PtL|PtL Kerosene | E38: PJ/yr. | F38: 0 | G38: 0 | H38: 0 | I38: 0 | J38: 0 | K38: 0
A39: =A28 -> STEM | B39: =B38 -> SPS2 | C39: =C28 -> CH | D39: Imports|Gas | E39: PJ/yr. | F39: =F40+F43 -> 117.25084 | G39: =G40+G43 -> 106.72049 | H39: =H40+H43 -> 99.004319 | I39: =I40+I43 -> 77.594714 | J39: =J40+J43 -> 21.980535 | K39: =K40+K43 -> 0.0002825932
A40: =A29 -> STEM | B40: =B39 -> SPS2 | C40: =C29 -> CH | D40: Imports|Gas|Fossil gases|Total | E40: PJ/yr. | F40: =F41+F42 -> 117.25084 | G40: =G41+G42 -> 106.72002 | H40: =H41+H42 -> 99.003901 | I40: =I41+I42 -> 77.076659 | J40: =J41+J42 -> 21.583239 | K40: =K41+K42 -> 9.5034919e-05
...

Sheet check
C2: 2020 | D2: 2022 | E2: 2025 | F2: 2030 | G2: 2040 | H2: 2050
B3: Final energy consumption | C3: =SUM(C4:C7) -> 717.92514 | D3: =SUM(D4:D7) -> 703.77663 | E3: =SUM(E4:E7) -> 686.47551 | F3: =SUM(F4:F7) -> 605.1475 | G3: =SUM(G4:G7) -> 525.81739 | H3: =SUM(H4:H7) -> 491.19853
B4: Industry | C4: ='SPS2'!F761 -> 142.2183 | D4: ='SPS2'!G761 -> 141.18716 | E4: ='SPS2'!H761 -> 142.48673 | F4: ='SPS2'!I761 -> 142.18006 | G4: ='SPS2'!J761 -> 134.8659 | H4: ='SPS2'!K761 -> 136.64848
B5: Services | C5: ='SPS2'!F880 -> 140.10141 | D5: ='SPS2'!G880 -> 136.78087 | E5: ='SPS2'!H880 -> 132.81978 | F5: ='SPS2'!I880 -> 121.51968 | G5: ='SPS2'!J880 -> 108.63169 | H5: ='SPS2'!K880 -> 95.251825
B6: Residential | C6: ='SPS2'!F970 -> 219.86601 | D6: ='SPS2'!G970 -> 219.55138 | E6: ='SPS2'!H970 -> 219.77457 | F6: ='SPS2'!I970 -> 200.53782 | G6: ='SPS2'!J970 -> 182.1031 | H6: ='SPS2'!K970 -> 164.52148
B7: Transport | C7: ='SPS2'!F1134+'SPS2'!F1313+'SPS2'!F1397+'SPS2'!F1481+'SPS2'!F1488+'SPS2'!F1495+'SPS2'!F1544+'SPS2'!F1591+'SPS2'!F1638 -> 215.73943 | D7: ='SPS2'!G1134+'SPS2'!G1313+'SPS2'!G1397+'SPS2'!G1481+'SPS2'!G1488+'SPS2'!G1495+'SPS2'!G1544+'SPS2'!G1591+'SPS2'!G1638 -> 206.25722 | E7: ='SPS2'!H1134+'SPS2'!H1313+'SPS2'!H1397+'SPS2'!H1481+'SPS2'!H1488+'SPS2'!H1495+'SPS2'!H1544+'SPS2'!H1591+'SPS2'!H1638 -> 191.39443 | F7: ='SPS2'!I1134+'SPS2'!I1313+'SPS2'!I1397+'SPS2'!I1481+'SPS2'!I1488+'SPS2'!I1495+'SPS2'!I1544+'SPS2'!I1591+'SPS2'!I1638 -> 140.90995 | G7: ='SPS2'!J1134+'SPS2'!J1313+'SPS2'!J1397+'SPS2'!J1481+'SPS2'!J1488+'SPS2'!J1495+'SPS2'!J1544+'SPS2'!J1591+'SPS2'!J1638 -> 100.21669 | H7: ='SPS2'!K1134+'SPS2'!K1313+'SPS2'!K1397+'SPS2'!K1481+'SPS2'!K1488+'SPS2'!K1495+'SPS2'!K1544+'SPS2'!K1591+'SPS2'!K1638 -> 94.77675
B8: Fuel input to energy conversion and DAC | C8: =SUM(C9:C12) -> 513.29077 | D8: =SUM(D9:D12) -> 502.29267 | E8: =SUM(E9:E12) -> 493.82685 | F8: =SUM(F9:F12) -> 580.69418 | G8: =SUM(G9:G12) -> 565.71876 | H8: =SUM(H9:H12) -> 602.12255
B9: Electricity and heat | C9: ='SPS2'!F289+'SPS2'!F407 -> 493.95424 | D9: ='SPS2'!G289+'SPS2'!G407 -> 475.32654 | E9: ='SPS2'!H289+'SPS2'!H407 -> 462.70052 | F9: ='SPS2'!I289+'SPS2'!I407 -> 547.19562 | G9: ='SPS2'!J289+'SPS2'!J407 -> 482.66736 | H9: ='SPS2'!K289+'SPS2'!K407 -> 470.0578
B10: Biofuel production | C10: ='SPS2'!F588+'SPS2'!F602+'SPS2'!F642 -> 19.330441 | D10: ='SPS2'!G588+'SPS2'!G602+'SPS2'!G642 -> 26.955968 | E10: ='SPS2'!H588+'SPS2'!H602+'SPS2'!H642 -> 31.116014 | F10: ='SPS2'!I588+'SPS2'!I602+'SPS2'!I642 -> 33.456444 | G10: ='SPS2'!J588+'SPS2'!J602+'SPS2'!J642 -> 40.15665 | H10: ='SPS2'!K588+'SPS2'!K602+'SPS2'!K642 -> 53.825253
B11: Hydrogen production | C11: ='SPS2'!F677 -> 0.0060905152 | D11: ='SPS2'!G677 -> 0.0101612 | E11: ='SPS2'!H677 -> 0.010315079 | F11: ='SPS2'!I677 -> 0.042123892 | G11: ='SPS2'!J677 -> 42.894639 | H11: ='SPS2'!K677 -> 78.014343
B12: DAC | C12: ='SPS2'!F1702 -> 0 | D12: ='SPS2'!G1702 -> 0 | E12: ='SPS2'!H1702 -> 0 | F12: ='SPS2'!I1702 -> 0 | G12: ='SPS2'!J1702 -> 0.00012023822 | H12: ='SPS2'!K1702 -> 0.22515223
B13: Total Primary energy consumption | C13: ='SPS2'!F2+'SPS2'!F20-'SPS2'!F55 -> 965.15535 | D13: ='SPS2'!G2+'SPS2'!G20-'SPS2'!G55 -> 964.07854 | E13: ='SPS2'!H2+'SPS2'!H20-'SPS2'!H55 -> 908.36174 | F13: ='SPS2'!I2+'SPS2'!I20-'SPS2'!I55 -> 886.08781 | G13: ='SPS2'!J2+'SPS2'!J20-'SPS2'!J55 -> 717.24999 | H13: ='SPS2'!K2+'SPS2'!K20-'SPS2'!K55 -> 677.41777
B14: Domestic production | C14: ='SPS2'!F2 -> 301.54828 | D14: ='SPS2'!G2 -> 297.81097 | E14: ='SPS2'!H2 -> 343.8724 | F14: ='SPS2'!I2 -> 446.49207 | G14: ='SPS2'!J2 -> 527.73722 | H14: ='SPS2'!K2 -> 609.55557
B15: Imports | C15: ='SPS2'!F20 -> 780.77715 | D15: ='SPS2'!G20 -> 701.3693 | E15: ='SPS2'!H20 -> 619.37916 | F15: ='SPS2'!I20 -> 492.31757 | G15: ='SPS2'!J20 -> 214.36869 | H15: ='SPS2'!K20 -> 88.108549
B16: Exports | C16: ='SPS2'!F55 -> 117.17008 | D16: ='SPS2'!G55 -> 35.101729 | E16: ='SPS2'!H55 -> 54.889819 | F16: ='SPS2'!I55 -> 52.721833 | G16: ='SPS2'!J55 -> 24.855918 | H16: ='SPS2'!K55 -> 20.246346
