Workbook

Sheet Variable_List
B2: Variable | C2: Description | D2: Unit | E2: Comment
B3: Primary Production | C3: Domestic primary production of resources | D3: PJ/yr.
B4: Imports | C4: Imports of energy carriers | D4: PJ/yr.
B5: Exports | C5: Exports of energy carriers | D5: PJ/yr.
B6: Electricity generation | C6: Domestic electricity generation | D6: PJ/yr.
B7: Heat generation from CHPs and heat plants | C7: Domestic heat production from CHPs (District heating CHPs or onsite CHPs) and heat plants | D7: PJ/yr.
B8: Fuel input for electricity generation | C8: Fuel input allocated to domestic electricity generation only | D8: PJ/yr.
B9: Fuel input for heat generation from CHPs and heat plants | C9: Fuel input allocated to domestic heat production from CHPs and heat plants only | D9: PJ/yr.
B10: Efficiency of power plants (electric) | C10: Average annual efficiency of power plants and CHPs for electricity production only | D10: % | E10: The thermal efficiency of CHPs can be inferred from the Heat to Electricity production ratio, but it can also be provided; the average efficiency differs from the technical efficiency as it includes efficiency losses due to part load operation
B11: Efficiency of heat plants (thermal) | C11: Average annual efficiency of heat plants | D11: % | E11: It is the annual marketed efficiency including part load efficiency losses and differs from the full load nominal technical efficiency; for heat pumps refers to COP
B12: Domestic biodiesel production | C12: Domestic production of biodiesel | D12: PJ/yr.
B13: Heat from domestic biodiesel production | C13: Heat produced as byproduct from biodiesel production and fed into the district heating network | D13: PJ/yr.
B14: Fuel input for domestic biodiesel production | C14: Fuel input for the domestic production of biodiesel | D14: PJ/yr.
B15: Efficiency for domestic biodiesel production | C15: Average annual efficiency for biodiesel and heat production | D15: %
B16: Domestic ethanol production | C16: Domestic production of ethanol | D16: PJ/yr.
B17: Fuel input for domestic ethanol production | C17: Fuel input for the domestic production of ethanol | D17: PJ/yr.
B18: Efficiency for domestic ethanol production | C18: Average annual efficiency for domestic production of ethanol | D18: %
B19: Domestic biogas production | C19: Domestic production of biogas and biogenic syngas | D19: PJ/yr.
B20: Electricity from domestic biogas production | C20: Electriicty produced as byproduct from biogas production and fed into the grid | D20: PJ/yr.
B21: Heat from domestic biogas production | C21: Heat produced as byproduct from biogas production and fed into the district heating network | D21: PJ/yr.
B22: Fuel input for domestic biogas production | C22: Fuel input for domestic biogas production | D22: PJ/yr.
B23: Efficiency for domestic biogas production | C23: Average annual efficiency for biogas production (accounting for byproduct production) | D23: %
... B25: Fuel input for hydrogen production | C25: Fuel input for deomstic hydrogen production | D25: PJ/yr.
B26: Efficiency for hydrogen production | C26: Average annual efficiency for hydrogen production | D26: % | E26: Including losses due to part load operation
B27: Biomethane production from biogas upgrade | C27: Production of domestic biomethane from biogas | D27: PJ/yr. | E27: One technology only fuel output is biomethane
B28: Fuel input for biogas upgrade to biomethane | C28: Use of biogas for upgrade to biomethane | D28: PJ/yr. | E28: One technology only fuel input is biogas
B29: Efficiency for biomethane production from biogas upgrade | C29: Average annual efficiency of biogas to biomethane upgrade | D29: PJ/yr. | E29: One technology only fuel input is biogas, fuel output is biomethane
B30: Domestic PtG and PtL production | C30: Domestic production of power-to-gas and power-to-liquids | D30: PJ/yr.
B31: Fuel input for domestic PtG and PtL production | C31: Fuel used for domestic PtG and PtL production (excl. CO2) | D31: PJ/yr.
B32: Efficiency for domestic PtG and PtL production | C32: Average annual efficiency for PtG and PtL processes (excl. CO2 consumption) | D32: %
B33: CO2 input for domestic PtG and PtL production | C33: CO2 input for domestic PtG and PtL production | D33: Mt/yr. | E33: The distinction of the source of CO2 (biogenic or fossil) is also provided and can be proportionally allocated to the technologies for PtG and PtL
B34: Domestic wood to pellet production | C34: Wood conversion to pellet domestic production output | D34: PJ/yr. | E34: One technology only , input is wood output is pellet
B35: Fuel input for wood to pellet production | C35: Wood conversion to pellet domestic production - input wood required | D35: PJ/yr. | E35: One technology only , input is wood output is pellet
B36: Efficiency for wood to pellet production | C36: Average annual efficiency of wood to pellet conversion | D36: %
B37: Fuel consumption in industry sectors | C37: Fuel consumption in industry by fuel and technology | D37: PJ/yr. | E37: This unfortunately it will change when the new industrial sectors will be integrated into STEM
B38: Process and space heating production in industry sectors | C38: Energy service demand provided in the form of process and space heating in industry | D38: PJ/yr. | E38: This unfortunately it will change when the new industrial sectors will be integrated into STEM
B39: Efficiency in industry sectors | C39: Boilers efficiency and COP of heat pumps in the industrial sectors | D39: % | E39: This unfortunately it will change when the new industrial sectors will be integrated into STEM
B40: Fuel consumption in Services sectors | C40: Fuel consumption in services sectors by fuel and technology | D40: PJ/yr.
B41: Space water and process heat production in Services sectors | C41: Production of energy service demand for space, water and process heat in Services sectors | D41: PJ/yr.
B42: Efficiency in Services sectors | C42: Boilers efficiency and COP of heat pumps in the Services sectors | D42: %
...

Sheet SPS3
A1: Model | B1: Scenario | C1: Region | D1: Variable | E1: Unit | F1: 2020 | G1: 2022 | H1: 2025 | I1: 2030 | J1: 2040 | K1: 2050
A2: STEM | B2: SPS3 | C2: CH | D2: Primary Production | E2: PJ/yr. | F2: =F3+F8+F11+F12+F16+F17+F18+F19 -> 300.18678 | G2: =G3+G8+G11+G12+G16+G17+G18+G19 -> 295.40443 | H2: =H3+H8+H11+H12+H16+H17+H18+H19 -> 336.83425 | I2: =I3+I8+I11+I12+I16+I17+I18+I19 -> 417.25182 | J2: =J3+J8+J11+J12+J16+J17+J18+J19 -> 453.7564 | K2: =K3+K8+K11+K12+K16+K17+K18+K19 -> 501.77096
A3: =A2 -> STEM | B3: =B2 -> SPS3 | C3: =C2 -> CH | D3: Primary Production|Wood | E3: PJ/yr. | F3: =SUM(F4:F7) -> 44.972527 | G3: =SUM(G4:G7) -> 47.710066 | H3: =SUM(H4:H7) -> 47.710043 | I3: =SUM(I4:I7) -> 47.710031 | J3: =SUM(J4:J7) -> 47.71004 | K3: =SUM(K4:K7) -> 48.190118
A4: =A3 -> STEM | B4: =B3 -> SPS3 | C4: =C3 -> CH | D4: Primary Production|Wood|Waste wood | E4: PJ/yr. | F4: {=SUMPRODUCT(("RNWWOD1"=[1]OUT_PrimaryEnergyCons!$A$1:$A$1000)*1,[1]OUT_PrimaryEnergyCons!D$1:D$1000)} -> 11.111898 | G4: {=SUMPRODUCT(("RNWWOD1"=[1]OUT_PrimaryEnergyCons!$A$1:$A$1000)*1,[1]OUT_PrimaryEnergyCons!E$1:E$1000)} -> 11.952902 | H4: {=SUMPRODUCT(("RNWWOD1"=[1]OUT_PrimaryEnergyCons!$A$1:$A$1000)*1,[1]OUT_PrimaryEnergyCons!F$1:F$1000)} -> 13.2144 | I4: {=SUMPRODUCT(("RNWWOD1"=[1]OUT_PrimaryEnergyCons!$A$1:$A$1000)*1,[1]OUT_PrimaryEnergyCons!G$1:G$1000)} -> 15.316918 | J4: {=SUMPRODUCT(("RNWWOD1"=[1]OUT_PrimaryEnergyCons!$A$1:$A$1000)*1,[1]OUT_PrimaryEnergyCons!H$1:H$1000)} -> 16.266401 | K4: {=SUMPRODUCT(("RNWWOD1"=[1]OUT_PrimaryEnergyCons!$A$1:$A$1000)*1,[1]OUT_PrimaryEnergyCons!I$1:I$1000)} -> 16.957002
A5: =A4 -> STEM | B5: =B4 -> SPS3 | C5: =C4 -> CH | D5: Primary Production|Wood|Wood residues | E5: PJ/yr. | F5: {=SUMPRODUCT(("RNWWOD2"=[1]OUT_PrimaryEnergyCons!$A$1:$A$1000)*1,[1]OUT_PrimaryEnergyCons!D$1:D$1000)} -> 7.5116913 | G5: {=SUMPRODUCT(("RNWWOD2"=[1]OUT_PrimaryEnergyCons!$A$1:$A$1000)*1,[1]OUT_PrimaryEnergyCons!E$1:E$1000)} -> 7.5431597 | H5: {=SUMPRODUCT(("RNWWOD2"=[1]OUT_PrimaryEnergyCons!$A$1:$A$1000)*1,[1]OUT_PrimaryEnergyCons!F$1:F$1000)} -> 7.5903552 | I5: {=SUMPRODUCT(("RNWWOD2"=[1]OUT_PrimaryEnergyCons!$A$1:$A$1000)*1,[1]OUT_PrimaryEnergyCons!G$1:G$1000)} -> 7.6690358 | J5: {=SUMPRODUCT(("RNWWOD2"=[1]OUT_PrimaryEnergyCons!$A$1:$A$1000)*1,[1]OUT_PrimaryEnergyCons!H$1:H$1000)} -> 7.6690343 | K5: {=SUMPRODUCT(("RNWWOD2"=[1]OUT_PrimaryEnergyCons!$A$1:$A$1000)*1,[1]OUT_PrimaryEnergyCons!I$1:I$1000)} -> 7.6690366
A6: =A5 -> STEM | B6: =B5 -> SPS3 | C6: =C5 -> CH | D6: Primary Production|Wood|Wood from landscape maintenance | E6: PJ/yr. | F6: {=SUMPRODUCT(("RNWWOD3"=[1]OUT_PrimaryEnergyCons!$A$1:$A$1000)*1,[1]OUT_PrimaryEnergyCons!D$1:D$1000)} -> 3.1682653 | G6: {=SUMPRODUCT(("RNWWOD3"=[1]OUT_PrimaryEnergyCons!$A$1:$A$1000)*1,[1]OUT_PrimaryEnergyCons!E$1:E$1000)} -> 3.4956787 | H6: {=SUMPRODUCT(("RNWWOD3"=[1]OUT_PrimaryEnergyCons!$A$1:$A$1000)*1,[1]OUT_PrimaryEnergyCons!F$1:F$1000)} -> 3.9868214 | I6: {=SUMPRODUCT(("RNWWOD3"=[1]OUT_PrimaryEnergyCons!$A$1:$A$1000)*1,[1]OUT_PrimaryEnergyCons!G$1:G$1000)} -> 4.8053889 | J6: {=SUMPRODUCT(("RNWWOD3"=[1]OUT_PrimaryEnergyCons!$A$1:$A$1000)*1,[1]OUT_PrimaryEnergyCons!H$1:H$1000)} -> 4.8053927 | K6: {=SUMPRODUCT(("RNWWOD3"=[1]OUT_PrimaryEnergyCons!$A$1:$A$1000)*1,[1]OUT_PrimaryEnergyCons!I$1:I$1000)} -> 4.8053893
A7: =A6 -> STEM | B7: =B6 -> SPS3 | C7: =C6 -> CH | D7: Primary Production|Wood|Wood from Forest (hard wood) | E7: PJ/yr. | F7: {=SUMPRODUCT(("RNWWOD4"=[1]OUT_PrimaryEnergyCons!$A$1:$A$1000)*1+("RNWWOD5"=[1]OUT_PrimaryEnergyCons!$A$1:$A$1000)*1,[1]OUT_PrimaryEnergyCons!D$1:D$1000)} -> 23.180672 | G7: {=SUMPRODUCT(("RNWWOD4"=[1]OUT_PrimaryEnergyCons!$A$1:$A$1000)*1+("RNWWOD5"=[1]OUT_PrimaryEnergyCons!$A$1:$A$1000)*1,[1]OUT_PrimaryEnergyCons!E$1:E$1000)} -> 24.718326 | H7: {=SUMPRODUCT(("RNWWOD4"=[1]OUT_PrimaryEnergyCons!$A$1:$A$1000)*1+("RNWWOD5"=[1]OUT_PrimaryEnergyCons!$A$1:$A$1000)*1,[1]OUT_PrimaryEnergyCons!F$1:F$1000)} -> 22.918467 | I7: {=SUMPRODUCT(("RNWWOD4"=[1]OUT_PrimaryEnergyCons!$A$1:$A$1000)*1+("RNWWOD5"=[1]OUT_PrimaryEnergyCons!$A$1:$A$1000)*1,[1]OUT_PrimaryEnergyCons!G$1:G$1000)} -> 19.918689 | J7: {=SUMPRODUCT(("RNWWOD4"=[1]OUT_PrimaryEnergyCons!$A$1:$A$1000)*1+("RNWWOD5"=[1]OUT_PrimaryEnergyCons!$A$1:$A$1000)*1,[1]OUT_PrimaryEnergyCons!H$1:H$1000)} -> 18.969212 | K7: {=SUMPRODUCT(("RNWWOD4"=[1]OUT_PrimaryEnergyCons!$A$1:$A$1000)*1+("RNWWOD5"=[1]OUT_PrimaryEnergyCons!$A$1:$A$1000)*1,[1]OUT_PrimaryEnergyCons!I$1:I$1000)} -> 18.75869
A8: =A7 -> STEM | B8: =B7 -> SPS3 | C8: =C7 -> CH | D8: Primary Production|Waste | E8: PJ/yr. | F8: =SUM(F9:F10) -> 70.031667 | G8: =SUM(G9:G10) -> 70.69702 | H8: =SUM(H9:H10) -> 70.304087 | I8: =SUM(I9:I10) -> 69.854565 | J8: =SUM(J9:J10) -> 74.776081 | K8: =SUM(K9:K10) -> 78.277377
A9: =A8 -> STEM | B9: =B8 -> SPS3 | C9: =C8 -> CH | D9: Primary Production|Waste|Non renewable waste | E9: PJ/yr. | F9: {=SUMPRODUCT(("RNNWWST1"=[1]OUT_PrimaryEnergyCons!$A$1:$A$1000)*1,[1]OUT_PrimaryEnergyCons!D$1:D$1000)} -> 35.931183 | G9: {=SUMPRODUCT(("RNNWWST1"=[1]OUT_PrimaryEnergyCons!$A$1:$A$1000)*1,[1]OUT_PrimaryEnergyCons!E$1:E$1000)} -> 35.882407 | H9: {=SUMPRODUCT(("RNNWWST1"=[1]OUT_PrimaryEnergyCons!$A$1:$A$1000)*1,[1]OUT_PrimaryEnergyCons!F$1:F$1000)} -> 35.489472 | I9: {=SUMPRODUCT(("RNNWWST1"=[1]OUT_PrimaryEnergyCons!$A$1:$A$1000)*1,[1]OUT_PrimaryEnergyCons!G$1:G$1000)} -> 35.039961 | J9: {=SUMPRODUCT(("RNNWWST1"=[1]OUT_PrimaryEnergyCons!$A$1:$A$1000)*1,[1]OUT_PrimaryEnergyCons!H$1:H$1000)} -> 35.511079 | K9: {=SUMPRODUCT(("RNNWWST1"=[1]OUT_PrimaryEnergyCons!$A$1:$A$1000)*1,[1]OUT_PrimaryEnergyCons!I$1:I$1000)} -> 35.959242
A10: =A9 -> STEM | B10: =B9 -> SPS3 | C10: =C9 -> CH | D10: Primary Production|Waste|Renewable waste | E10: PJ/yr. | F10: {=SUMPRODUCT(("RNWWST1"=[1]OUT_PrimaryEnergyCons!$A$1:$A$1000)*1,[1]OUT_PrimaryEnergyCons!D$1:D$1000)} -> 34.100484 | G10: {=SUMPRODUCT(("RNWWST1"=[1]OUT_PrimaryEnergyCons!$A$1:$A$1000)*1,[1]OUT_PrimaryEnergyCons!E$1:E$1000)} -> 34.814613 | H10: {=SUMPRODUCT(("RNWWST1"=[1]OUT_PrimaryEnergyCons!$A$1:$A$1000)*1,[1]OUT_PrimaryEnergyCons!F$1:F$1000)} -> 34.814615 | I10: {=SUMPRODUCT(("RNWWST1"=[1]OUT_PrimaryEnergyCons!$A$1:$A$1000)*1,[1]OUT_PrimaryEnergyCons!G$1:G$1000)} -> 34.814604 | J10: {=SUMPRODUCT(("RNWWST1"=[1]OUT_PrimaryEnergyCons!$A$1:$A$1000)*1,[1]OUT_PrimaryEnergyCons!H$1:H$1000)} -> 39.265003 | K10: {=SUMPRODUCT(("RNWWST1"=[1]OUT_PrimaryEnergyCons!$A$1:$A$1000)*1,[1]OUT_PrimaryEnergyCons!I$1:I$1000)} -> 42.318135
A11: =A10 -> STEM | B11: =B10 -> SPS3 | C11: =C10 -> CH | D11: Primary Production|Manure | E11: PJ/yr. | F11: {=SUMPRODUCT(("mnr"=[1]OUT_PrimaryEnergyCons!$C$1:$C$1000)*1,[1]OUT_PrimaryEnergyCons!D$1:D$1000)} -> 3.7981273 | G11: {=SUMPRODUCT(("mnr"=[1]OUT_PrimaryEnergyCons!$C$1:$C$1000)*1,[1]OUT_PrimaryEnergyCons!E$1:E$1000)} -> 12.540463 | H11: {=SUMPRODUCT(("mnr"=[1]OUT_PrimaryEnergyCons!$C$1:$C$1000)*1,[1]OUT_PrimaryEnergyCons!F$1:F$1000)} -> 12.540463 | I11: {=SUMPRODUCT(("mnr"=[1]OUT_PrimaryEnergyCons!$C$1:$C$1000)*1,[1]OUT_PrimaryEnergyCons!G$1:G$1000)} -> 12.540446 | J11: {=SUMPRODUCT(("mnr"=[1]OUT_PrimaryEnergyCons!$C$1:$C$1000)*1,[1]OUT_PrimaryEnergyCons!H$1:H$1000)} -> 17.360317 | K11: {=SUMPRODUCT(("mnr"=[1]OUT_PrimaryEnergyCons!$C$1:$C$1000)*1,[1]OUT_PrimaryEnergyCons!I$1:I$1000)} -> 27.000023
A12: =A11 -> STEM | B12: =B11 -> SPS3 | C12: =C11 -> CH | D12: Primary Production|Hydro | E12: PJ/yr. | F12: =SUM(F13:F15) -> 149.4305 | G12: =SUM(G13:G15) -> 125.6091 | H12: =SUM(H13:H15) -> 141.33592 | I12: =SUM(I13:I15) -> 190.54838 | J12: =SUM(J13:J15) -> 152.08346 | K12: =SUM(K13:K15) -> 152.52844
A13: =A12 -> STEM | B13: =B12 -> SPS3 | C13: =C12 -> CH | D13: Primary Production|Hydro|Large hydro | E13: PJ/yr. | F13: {=SUMPRODUCT(ISNUMBER(SEARCH("EHYD-DAM",[1]OUT_Electricity_CHP!$B$1:$B$10000))*1,([1]OUT_Electricity_CHP!$C$1:$C$10000="Var_Fout")*1,ISNUMBER(SEARCH("ELC",[1]OUT_Electricity_CHP!$D$1:$D$10000))*1,[1]OUT_Electricity_CHP!E$1:E$10000)} -> 66.745681 | G13: {=SUMPRODUCT(ISNUMBER(SEARCH("EHYD-DAM",[1]OUT_Electricity_CHP!$B$1:$B$10000))*1,([1]OUT_Electricity_CHP!$C$1:$C$10000="Var_Fout")*1,ISNUMBER(SEARCH("ELC",[1]OUT_Electricity_CHP!$D$1:$D$10000))*1,[1]OUT_Electricity_CHP!F$1:F$10000)} -> 49.798798 | H13: {=SUMPRODUCT(ISNUMBER(SEARCH("EHYD-DAM",[1]OUT_Electricity_CHP!$B$1:$B$10000))*1,([1]OUT_Electricity_CHP!$C$1:$C$10000="Var_Fout")*1,ISNUMBER(SEARCH("ELC",[1]OUT_Electricity_CHP!$D$1:$D$10000))*1,[1]OUT_Electricity_CHP!G$1:G$10000)} -> 68.746653 | I13: {=SUMPRODUCT(ISNUMBER(SEARCH("EHYD-DAM",[1]OUT_Electricity_CHP!$B$1:$B$10000))*1,([1]OUT_Electricity_CHP!$C$1:$C$10000="Var_Fout")*1,ISNUMBER(SEARCH("ELC",[1]OUT_Electricity_CHP!$D$1:$D$10000))*1,[1]OUT_Electricity_CHP!H$1:H$10000)} -> 69.70798 | J13: {=SUMPRODUCT(ISNUMBER(SEARCH("EHYD-DAM",[1]OUT_Electricity_CHP!$B$1:$B$10000))*1,([1]OUT_Electricity_CHP!$C$1:$C$10000="Var_Fout")*1,ISNUMBER(SEARCH("ELC",[1]OUT_Electricity_CHP!$D$1:$D$10000))*1,[1]OUT_Electricity_CHP!I$1:I$10000)} -> 72.137442 | K13: {=SUMPRODUCT(ISNUMBER(SEARCH("EHYD-DAM",[1]OUT_Electricity_CHP!$B$1:$B$10000))*1,([1]OUT_Electricity_CHP!$C$1:$C$10000="Var_Fout")*1,ISNUMBER(SEARCH("ELC",[1]OUT_Electricity_CHP!$D$1:$D$10000))*1,[1]OUT_Electricity_CHP!J$1:J$10000)} -> 68.851437
A14: =A13 -> STEM | B14: =B13 -> SPS3 | C14: =C13 -> CH | D14: Primary Production|Hydro|Run-of-river hydro | E14: PJ/yr. | F14: {=SUMPRODUCT(ISNUMBER(SEARCH("EHYD-RUN",[1]OUT_Electricity_CHP!$B$1:$B$10000))*1,([1]OUT_Electricity_CHP!$C$1:$C$10000="Var_Fout")*1,ISNUMBER(SEARCH("ELC",[1]OUT_Electricity_CHP!$D$1:$D$10000))*1,[1]OUT_Electricity_CHP!E$1:E$10000)} -> 66.632409 | G14: {=SUMPRODUCT(ISNUMBER(SEARCH("EHYD-RUN",[1]OUT_Electricity_CHP!$B$1:$B$10000))*1,([1]OUT_Electricity_CHP!$C$1:$C$10000="Var_Fout")*1,ISNUMBER(SEARCH("ELC",[1]OUT_Electricity_CHP!$D$1:$D$10000))*1,[1]OUT_Electricity_CHP!F$1:F$10000)} -> 55.764006 | H14: {=SUMPRODUCT(ISNUMBER(SEARCH("EHYD-RUN",[1]OUT_Electricity_CHP!$B$1:$B$10000))*1,([1]OUT_Electricity_CHP!$C$1:$C$10000="Var_Fout")*1,ISNUMBER(SEARCH("ELC",[1]OUT_Electricity_CHP!$D$1:$D$10000))*1,[1]OUT_Electricity_CHP!G$1:G$10000)} -> 65.562601 | I14: {=SUMPRODUCT(ISNUMBER(SEARCH("EHYD-RUN",[1]OUT_Electricity_CHP!$B$1:$B$10000))*1,([1]OUT_Electricity_CHP!$C$1:$C$10000="Var_Fout")*1,ISNUMBER(SEARCH("ELC",[1]OUT_Electricity_CHP!$D$1:$D$10000))*1,[1]OUT_Electricity_CHP!H$1:H$10000)} -> 64.934025 | J14: {=SUMPRODUCT(ISNUMBER(SEARCH("EHYD-RUN",[1]OUT_Electricity_CHP!$B$1:$B$10000))*1,([1]OUT_Electricity_CHP!$C$1:$C$10000="Var_Fout")*1,ISNUMBER(SEARCH("ELC",[1]OUT_Electricity_CHP!$D$1:$D$10000))*1,[1]OUT_Electricity_CHP!I$1:I$10000)} -> 63.848999 | K14: {=SUMPRODUCT(ISNUMBER(SEARCH("EHYD-RUN",[1]OUT_Electricity_CHP!$B$1:$B$10000))*1,([1]OUT_Electricity_CHP!$C$1:$C$10000="Var_Fout")*1,ISNUMBER(SEARCH("ELC",[1]OUT_Electricity_CHP!$D$1:$D$10000))*1,[1]OUT_Electricity_CHP!J$1:J$10000)} -> 67.134994
A15: =A14 -> STEM | B15: =B14 -> SPS3 | C15: =C14 -> CH | D15: Primary Production|Hydro|Pump storage | E15: PJ/yr. | F15: {=SUMPRODUCT(ISNUMBER(SEARCH("EHYD-PUM",[1]OUT_Electricity_CHP!$B$1:$B$10000))*1,([1]OUT_Electricity_CHP!$C$1:$C$10000="Var_Fin")*1,ISNUMBER(SEARCH("elc",[1]OUT_Electricity_CHP!$D$1:$D$10000))*1,[1]OUT_Electricity_CHP!E$1:E$10000)} -> 16.052414 | G15: {=SUMPRODUCT(ISNUMBER(SEARCH("EHYD-PUM",[1]OUT_Electricity_CHP!$B$1:$B$10000))*1,([1]OUT_Electricity_CHP!$C$1:$C$10000="Var_Fin")*1,ISNUMBER(SEARCH("elc",[1]OUT_Electricity_CHP!$D$1:$D$10000))*1,[1]OUT_Electricity_CHP!F$1:F$10000)} -> 20.046299 | H15: {=SUMPRODUCT(ISNUMBER(SEARCH("EHYD-PUM",[1]OUT_Electricity_CHP!$B$1:$B$10000))*1,([1]OUT_Electricity_CHP!$C$1:$C$10000="Var_Fin")*1,ISNUMBER(SEARCH("elc",[1]OUT_Electricity_CHP!$D$1:$D$10000))*1,[1]OUT_Electricity_CHP!G$1:G$10000)} -> 7.0266629 | I15: {=SUMPRODUCT(ISNUMBER(SEARCH("EHYD-PUM",[1]OUT_Electricity_CHP!$B$1:$B$10000))*1,([1]OUT_Electricity_CHP!$C$1:$C$10000="Var_Fin")*1,ISNUMBER(SEARCH("elc",[1]OUT_Electricity_CHP!$D$1:$D$10000))*1,[1]OUT_Electricity_CHP!H$1:H$10000)} -> 55.906373 | J15: {=SUMPRODUCT(ISNUMBER(SEARCH("EHYD-PUM",[1]OUT_Electricity_CHP!$B$1:$B$10000))*1,([1]OUT_Electricity_CHP!$C$1:$C$10000="Var_Fin")*1,ISNUMBER(SEARCH("elc",[1]OUT_Electricity_CHP!$D$1:$D$10000))*1,[1]OUT_Electricity_CHP!I$1:I$10000)} -> 16.097022 | K15: {=SUMPRODUCT(ISNUMBER(SEARCH("EHYD-PUM",[1]OUT_Electricity_CHP!$B$1:$B$10000))*1,([1]OUT_Electricity_CHP!$C$1:$C$10000="Var_Fin")*1,ISNUMBER(SEARCH("elc",[1]OUT_Electricity_CHP!$D$1:$D$10000))*1,[1]OUT_Electricity_CHP!J$1:J$10000)} -> 16.542013
A16: =A15 -> STEM | B16: =B15 -> SPS3 | C16: =C15 -> CH | D16: Primary Production|Solar | E16: PJ/yr. | F16: {=SUMPRODUCT(ISNUMBER(SEARCH("SOL",[1]OUT_PrimaryEnergyCons!$C$1:$C$1000))*1,[1]OUT_PrimaryEnergyCons!D$1:D$1000)} -> 12.556596 | G16: {=SUMPRODUCT(ISNUMBER(SEARCH("SOL",[1]OUT_PrimaryEnergyCons!$C$1:$C$1000))*1,[1]OUT_PrimaryEnergyCons!E$1:E$1000)} -> 16.523694 | H16: {=SUMPRODUCT(ISNUMBER(SEARCH("SOL",[1]OUT_PrimaryEnergyCons!$C$1:$C$1000))*1,[1]OUT_PrimaryEnergyCons!F$1:F$1000)} -> 30.509166 | I16: {=SUMPRODUCT(ISNUMBER(SEARCH("SOL",[1]OUT_PrimaryEnergyCons!$C$1:$C$1000))*1,[1]OUT_PrimaryEnergyCons!G$1:G$1000)} -> 35.879015 | J16: {=SUMPRODUCT(ISNUMBER(SEARCH("SOL",[1]OUT_PrimaryEnergyCons!$C$1:$C$1000))*1,[1]OUT_PrimaryEnergyCons!H$1:H$1000)} -> 66.288291 | K16: {=SUMPRODUCT(ISNUMBER(SEARCH("SOL",[1]OUT_PrimaryEnergyCons!$C$1:$C$1000))*1,[1]OUT_PrimaryEnergyCons!I$1:I$1000)} -> 96.031483
A17: =A16 -> STEM | B17: =B16 -> SPS3 | C17: =C16 -> CH | D17: Primary Production|Wind | E17: PJ/yr. | F17: {=SUMPRODUCT(ISNUMBER(SEARCH("wnd",[1]OUT_PrimaryEnergyCons!$C$1:$C$1000))*1,[1]OUT_PrimaryEnergyCons!D$1:D$1000)} -> 0.52405024 | G17: {=SUMPRODUCT(ISNUMBER(SEARCH("wnd",[1]OUT_PrimaryEnergyCons!$C$1:$C$1000))*1,[1]OUT_PrimaryEnergyCons!E$1:E$1000)} -> 0.54529958 | H17: {=SUMPRODUCT(ISNUMBER(SEARCH("wnd",[1]OUT_PrimaryEnergyCons!$C$1:$C$1000))*1,[1]OUT_PrimaryEnergyCons!F$1:F$1000)} -> 0.50317218 | I17: {=SUMPRODUCT(ISNUMBER(SEARCH("wnd",[1]OUT_PrimaryEnergyCons!$C$1:$C$1000))*1,[1]OUT_PrimaryEnergyCons!G$1:G$1000)} -> 2.0503093 | J17: {=SUMPRODUCT(ISNUMBER(SEARCH("wnd",[1]OUT_PrimaryEnergyCons!$C$1:$C$1000))*1,[1]OUT_PrimaryEnergyCons!H$1:H$1000)} -> 3.5228653 | K17: {=SUMPRODUCT(ISNUMBER(SEARCH("wnd",[1]OUT_PrimaryEnergyCons!$C$1:$C$1000))*1,[1]OUT_PrimaryEnergyCons!I$1:I$1000)} -> 6.1200322
A18: =A17 -> STEM | B18: =B17 -> SPS3 | C18: =C17 -> CH | D18: Primary Production|Ambient heat | E18: PJ/yr. | F18: =[1]Overview!B$9-F19 -> 18.873312 | G18: =[1]Overview!C$9-G19 -> 21.778784 | H18: =[1]Overview!D$9-H19 -> 33.931402 | I18: =[1]Overview!E$9-I19 -> 58.669076 | J18: =[1]Overview!F$9-J19 -> 88.987107 | K18: =[1]Overview!G$9-K19 -> 87.572869
A19: =A18 -> STEM | B19: =B18 -> SPS3 | C19: =C18 -> CH | D19: Primary Production|Geothermal | E19: PJ/yr. | F19: =+[1]Overview!B$28 -> 0 | G19: =+[1]Overview!C$28 -> 0 | H19: =+[1]Overview!D$28 -> 0 | I19: =+[1]Overview!E$28 -> 0 | J19: =+[1]Overview!F$28 -> 3.0282378 | K19: =+[1]Overview!G$28 -> 6.0506097
A20: =A19 -> STEM | B20: =B19 -> SPS3 | C20: =C19 -> CH | D20: Imports | E20: PJ/yr. | F20: =SUM(F21:F22,F39,F48:F49,F54) -> 780.4271 | G20: =SUM(G21:G22,G39,G48:G49,G54) -> 705.94703 | H20: =SUM(H21:H22,H39,H48:H49,H54) -> 599.3344 | I20: =SUM(I21:I22,I39,I48:I49,I54) -> 508.1469 | J20: =SUM(J21:J22,J39,J48:J49,J54) -> 231.06476 | K20: =SUM(K21:K22,K39,K48:K49,K54) -> 81.696255
A21: =A20 -> STEM | B21: =B20 -> SPS3 | C21: =C20 -> CH | D21: Imports|Coal | E21: PJ/yr. | F21: {=SUMPRODUCT(("COA"=[1]OUT_PrimaryEnergyCons!$C$4:$C$10000)*1,[1]OUT_PrimaryEnergyCons!D$4:D$10000)} -> 3.6600826 | G21: {=SUMPRODUCT(("COA"=[1]OUT_PrimaryEnergyCons!$C$4:$C$10000)*1,[1]OUT_PrimaryEnergyCons!E$4:E$10000)} -> 3.56474 | H21: {=SUMPRODUCT(("COA"=[1]OUT_PrimaryEnergyCons!$C$4:$C$10000)*1,[1]OUT_PrimaryEnergyCons!F$4:F$10000)} -> 1.3942393 | I21: {=SUMPRODUCT(("COA"=[1]OUT_PrimaryEnergyCons!$C$4:$C$10000)*1,[1]OUT_PrimaryEnergyCons!G$4:G$10000)} -> 9.6632043e-05 | J21: {=SUMPRODUCT(("COA"=[1]OUT_PrimaryEnergyCons!$C$4:$C$10000)*1,[1]OUT_PrimaryEnergyCons!H$4:H$10000)} -> 0.00011673945 | K21: {=SUMPRODUCT(("COA"=[1]OUT_PrimaryEnergyCons!$C$4:$C$10000)*1,[1]OUT_PrimaryEnergyCons!I$4:I$10000)} -> 8.4194731e-06
A22: =A21 -> STEM | B22: =B21 -> SPS3 | C22: =C21 -> CH | D22: Imports|Oil | E22: PJ/yr. | F22: =F23+F29 -> 311.53316 | G22: =G23+G29 -> 291.56945 | H22: =H23+H29 -> 262.189 | I22: =I23+I29 -> 188.65268 | J22: =J23+J29 -> 72.242434 | K22: =K23+K29 -> 58.214098
A23: =A22 -> STEM | B23: =B22 -> SPS3 | C23: =C22 -> CH | D23: Imports|Oil|Fossil liquids | E23: PJ/yr. | F23: =SUM(F24:F28) -> 304.86705 | G23: =SUM(G24:G28) -> 284.79282 | H23: =SUM(H24:H28) -> 254.89624 | I23: =SUM(I24:I28) -> 177.18049 | J23: =SUM(J24:J28) -> 40.734645 | K23: =SUM(K24:K28) -> 0
A24: =A22 -> STEM | B24: =B23 -> SPS3 | C24: =C22 -> CH | D24: Imports|Oil|Fossil liquids|Light fuel oil | E24: PJ/yr. | F24: {=SUMPRODUCT(("LFO"=[1]OUT_PrimaryEnergyCons!$C$4:$C$10000)*1,[1]OUT_PrimaryEnergyCons!D$4:D$10000)} -> 101.78019 | G24: {=SUMPRODUCT(("LFO"=[1]OUT_PrimaryEnergyCons!$C$4:$C$10000)*1,[1]OUT_PrimaryEnergyCons!E$4:E$10000)} -> 88.215373 | H24: {=SUMPRODUCT(("LFO"=[1]OUT_PrimaryEnergyCons!$C$4:$C$10000)*1,[1]OUT_PrimaryEnergyCons!F$4:F$10000)} -> 83.615009 | I24: {=SUMPRODUCT(("LFO"=[1]OUT_PrimaryEnergyCons!$C$4:$C$10000)*1,[1]OUT_PrimaryEnergyCons!G$4:G$10000)} -> 40.922146 | J24: {=SUMPRODUCT(("LFO"=[1]OUT_PrimaryEnergyCons!$C$4:$C$10000)*1,[1]OUT_PrimaryEnergyCons!H$4:H$10000)} -> 8.1877928 | K24: {=SUMPRODUCT(("LFO"=[1]OUT_PrimaryEnergyCons!$C$4:$C$10000)*1,[1]OUT_PrimaryEnergyCons!I$4:I$10000)} -> 0
A25: =A24 -> STEM | B25: =B24 -> SPS3 | C25: =C24 -> CH | D25: Imports|Oil|Fossil liquids|Heavy fuel oil | E25: PJ/yr. | F25: {=SUMPRODUCT(("HFO"=[1]OUT_PrimaryEnergyCons!$C$4:$C$10000)*1,[1]OUT_PrimaryEnergyCons!D$4:D$10000)} -> 2.7764033 | G25: {=SUMPRODUCT(("HFO"=[1]OUT_PrimaryEnergyCons!$C$4:$C$10000)*1,[1]OUT_PrimaryEnergyCons!E$4:E$10000)} -> 2.7644347 | H25: {=SUMPRODUCT(("HFO"=[1]OUT_PrimaryEnergyCons!$C$4:$C$10000)*1,[1]OUT_PrimaryEnergyCons!F$4:F$10000)} -> 0.0073640543 | I25: {=SUMPRODUCT(("HFO"=[1]OUT_PrimaryEnergyCons!$C$4:$C$10000)*1,[1]OUT_PrimaryEnergyCons!G$4:G$10000)} -> 0.00015550723 | J25: {=SUMPRODUCT(("HFO"=[1]OUT_PrimaryEnergyCons!$C$4:$C$10000)*1,[1]OUT_PrimaryEnergyCons!H$4:H$10000)} -> 0.00015383759 | K25: {=SUMPRODUCT(("HFO"=[1]OUT_PrimaryEnergyCons!$C$4:$C$10000)*1,[1]OUT_PrimaryEnergyCons!I$4:I$10000)} -> 0
A26: =A25 -> STEM | B26: =B25 -> SPS3 | C26: =C25 -> CH | D26: Imports|Oil|Fossil liquids|Motor Diesel | E26: PJ/yr. | F26: {=SUMPRODUCT(("DSL"=[1]OUT_PrimaryEnergyCons!$C$4:$C$10000)*1,[1]OUT_PrimaryEnergyCons!D$4:D$10000)} -> 120.33096 | G26: {=SUMPRODUCT(("DSL"=[1]OUT_PrimaryEnergyCons!$C$4:$C$10000)*1,[1]OUT_PrimaryEnergyCons!E$4:E$10000)} -> 112.68605 | H26: {=SUMPRODUCT(("DSL"=[1]OUT_PrimaryEnergyCons!$C$4:$C$10000)*1,[1]OUT_PrimaryEnergyCons!F$4:F$10000)} -> 97.453933 | I26: {=SUMPRODUCT(("DSL"=[1]OUT_PrimaryEnergyCons!$C$4:$C$10000)*1,[1]OUT_PrimaryEnergyCons!G$4:G$10000)} -> 72.50557 | J26: {=SUMPRODUCT(("DSL"=[1]OUT_PrimaryEnergyCons!$C$4:$C$10000)*1,[1]OUT_PrimaryEnergyCons!H$4:H$10000)} -> 26.59496 | K26: {=SUMPRODUCT(("DSL"=[1]OUT_PrimaryEnergyCons!$C$4:$C$10000)*1,[1]OUT_PrimaryEnergyCons!I$4:I$10000)} -> 0
A27: =A26 -> STEM | B27: =B26 -> SPS3 | C27: =C26 -> CH | D27: Imports|Oil|Fossil liquids|Motor Gasoline | E27: PJ/yr. | F27: {=SUMPRODUCT(("GSL"=[1]OUT_PrimaryEnergyCons!$C$4:$C$10000)*1,[1]OUT_PrimaryEnergyCons!D$4:D$10000)} -> 78.873041 | G27: {=SUMPRODUCT(("GSL"=[1]OUT_PrimaryEnergyCons!$C$4:$C$10000)*1,[1]OUT_PrimaryEnergyCons!E$4:E$10000)} -> 79.721754 | H27: {=SUMPRODUCT(("GSL"=[1]OUT_PrimaryEnergyCons!$C$4:$C$10000)*1,[1]OUT_PrimaryEnergyCons!F$4:F$10000)} -> 71.971097 | I27: {=SUMPRODUCT(("GSL"=[1]OUT_PrimaryEnergyCons!$C$4:$C$10000)*1,[1]OUT_PrimaryEnergyCons!G$4:G$10000)} -> 61.790685 | J27: {=SUMPRODUCT(("GSL"=[1]OUT_PrimaryEnergyCons!$C$4:$C$10000)*1,[1]OUT_PrimaryEnergyCons!H$4:H$10000)} -> 5.6038265 | K27: {=SUMPRODUCT(("GSL"=[1]OUT_PrimaryEnergyCons!$C$4:$C$10000)*1,[1]OUT_PrimaryEnergyCons!I$4:I$10000)} -> 0
A28: =A27 -> STEM | B28: =B27 -> SPS3 | C28: =C27 -> CH | D28: Imports|Oil|Fossil liquids|Kerosene (excl. international aviation) | E28: PJ/yr. | F28: {=SUMPRODUCT(("KER"=[1]OUT_PrimaryEnergyCons!$C$4:$C$10000)*1,[1]OUT_PrimaryEnergyCons!D$4:D$10000)} -> 1.1064527 | G28: {=SUMPRODUCT(("KER"=[1]OUT_PrimaryEnergyCons!$C$4:$C$10000)*1,[1]OUT_PrimaryEnergyCons!E$4:E$10000)} -> 1.4052077 | H28: {=SUMPRODUCT(("KER"=[1]OUT_PrimaryEnergyCons!$C$4:$C$10000)*1,[1]OUT_PrimaryEnergyCons!F$4:F$10000)} -> 1.8488332 | I28: {=SUMPRODUCT(("KER"=[1]OUT_PrimaryEnergyCons!$C$4:$C$10000)*1,[1]OUT_PrimaryEnergyCons!G$4:G$10000)} -> 1.9619319 | J28: {=SUMPRODUCT(("KER"=[1]OUT_PrimaryEnergyCons!$C$4:$C$10000)*1,[1]OUT_PrimaryEnergyCons!H$4:H$10000)} -> 0.34791178 | K28: {=SUMPRODUCT(("KER"=[1]OUT_PrimaryEnergyCons!$C$4:$C$10000)*1,[1]OUT_PrimaryEnergyCons!I$4:I$10000)} -> 0
A29: =A48 -> STEM | B29: =B28 -> SPS3 | C29: =C48 -> CH | D29: Imports|Oil|Synthetic liquids | E29: PJ/yr. | F29: =SUM(F30:F31) -> 6.6661111 | G29: =SUM(G30:G31) -> 6.7766338 | H29: =SUM(H30:H31) -> 7.2927684 | I29: =SUM(I30:I31) -> 11.472189 | J29: =SUM(J30:J31) -> 31.50779 | K29: =SUM(K30:K31) -> 58.214098
A30: =A35 -> STEM | B30: =B29 -> SPS3 | C30: =C35 -> CH | D30: Imports|Oil|Synthetic liquids|Total|Motor diesel | E30: PJ/yr. | F30: {=SUMPRODUCT(ISNUMBER(SEARCH("IMPBDS",[1]OUT_SyntheticFuels!$C$4:$C$1000))*1,("Var_Fout"=[1]OUT_SyntheticFuels!$B$4:$B$1000)*1,[1]OUT_SyntheticFuels!E$4:E$1000)} -> 2.2319555 | G30: {=SUMPRODUCT(ISNUMBER(SEARCH("IMPBDS",[1]OUT_SyntheticFuels!$C$4:$C$1000))*1,("Var_Fout"=[1]OUT_SyntheticFuels!$B$4:$B$1000)*1,[1]OUT_SyntheticFuels!F$4:F$1000)} -> 2.3780157 | H30: {=SUMPRODUCT(ISNUMBER(SEARCH("IMPBDS",[1]OUT_SyntheticFuels!$C$4:$C$1000))*1,("Var_Fout"=[1]OUT_SyntheticFuels!$B$4:$B$1000)*1,[1]OUT_SyntheticFuels!G$4:G$1000)} -> 3.3303176 | I30: {=SUMPRODUCT(ISNUMBER(SEARCH("IMPBDS",[1]OUT_SyntheticFuels!$C$4:$C$1000))*1,("Var_Fout"=[1]OUT_SyntheticFuels!$B$4:$B$1000)*1,[1]OUT_SyntheticFuels!H$4:H$1000)} -> 7.1269317 | J30: {=SUMPRODUCT(ISNUMBER(SEARCH("IMPBDS",[1]OUT_SyntheticFuels!$C$4:$C$1000))*1,("Var_Fout"=[1]OUT_SyntheticFuels!$B$4:$B$1000)*1,[1]OUT_SyntheticFuels!I$4:I$1000)} -> 26.936675 | K30: {=SUMPRODUCT(ISNUMBER(SEARCH("IMPBDS",[1]OUT_SyntheticFuels!$C$4:$C$1000))*1,("Var_Fout"=[1]OUT_SyntheticFuels!$B$4:$B$1000)*1,[1]OUT_SyntheticFuels!J$4:J$1000)} -> 58.187276
A31: =A30 -> STEM | B31: =B30 -> SPS3 | C31: =C30 -> CH | D31: Imports|Oil|Synthetic liquids|Total|Motor Gasoline | E31: PJ/yr. | F31: {=SUMPRODUCT(ISNUMBER(SEARCH("IMPeth",[1]OUT_SyntheticFuels!$C$4:$C$1000))*1,("Var_Fout"=[1]OUT_SyntheticFuels!$B$4:$B$1000)*1,[1]OUT_SyntheticFuels!E$4:E$1000)} -> 4.4341557 | G31: {=SUMPRODUCT(ISNUMBER(SEARCH("IMPeth",[1]OUT_SyntheticFuels!$C$4:$C$1000))*1,("Var_Fout"=[1]OUT_SyntheticFuels!$B$4:$B$1000)*1,[1]OUT_SyntheticFuels!F$4:F$1000)} -> 4.3986181 | H31: {=SUMPRODUCT(ISNUMBER(SEARCH("IMPeth",[1]OUT_SyntheticFuels!$C$4:$C$1000))*1,("Var_Fout"=[1]OUT_SyntheticFuels!$B$4:$B$1000)*1,[1]OUT_SyntheticFuels!G$4:G$1000)} -> 3.9624508 | I31: {=SUMPRODUCT(ISNUMBER(SEARCH("IMPeth",[1]OUT_SyntheticFuels!$C$4:$C$1000))*1,("Var_Fout"=[1]OUT_SyntheticFuels!$B$4:$B$1000)*1,[1]OUT_SyntheticFuels!H$4:H$1000)} -> 4.3452578 | J31: {=SUMPRODUCT(ISNUMBER(SEARCH("IMPeth",[1]OUT_SyntheticFuels!$C$4:$C$1000))*1,("Var_Fout"=[1]OUT_SyntheticFuels!$B$4:$B$1000)*1,[1]OUT_SyntheticFuels!I$4:I$1000)} -> 4.5711146 | K31: {=SUMPRODUCT(ISNUMBER(SEARCH("IMPeth",[1]OUT_SyntheticFuels!$C$4:$C$1000))*1,("Var_Fout"=[1]OUT_SyntheticFuels!$B$4:$B$1000)*1,[1]OUT_SyntheticFuels!J$4:J$1000)} -> 0.026821999
A32: =A29 -> STEM | B32: =B31 -> SPS3 | C32: =C29 -> CH | D32: Imports|Oil|Synthetic liquids|Bioliquids|Total | E32: PJ/yr. | F32: =SUM(F33:F34) -> 6.6661111 | G32: =SUM(G33:G34) -> 6.7766338 | H32: =SUM(H33:H34) -> 7.2927684 | I32: =SUM(I33:I34) -> 11.472189 | J32: =SUM(J33:J34) -> 11.561087 | K32: =SUM(K33:K34) -> 26.963497
A33: =A31 -> STEM | B33: =B32 -> SPS3 | C33: =C31 -> CH | D33: Imports|Oil|Synthetic liquids|Bioliquids|Biodiesel | E33: PJ/yr. | F33: =F30 -> 2.2319555 | G33: =G30 -> 2.3780157 | H33: =H30 -> 3.3303176 | I33: =I30 -> 7.1269317 | J33: =IF(J30-MAX(F30:I30)<0,J30,MAX(F30:I30)) -> 7.1269317 | K33: =IF(K30-MAX(F30:J30)<0,K30,MAX(F30:J30)) -> 26.936675
A34: =A33 -> STEM | B34: =B33 -> SPS3 | C34: =C33 -> CH | D34: Imports|Oil|Synthetic liquids|Bioliquids|Ethanol | E34: PJ/yr. | F34: =F31 -> 4.4341557 | G34: =G31 -> 4.3986181 | H34: =H31 -> 3.9624508 | I34: =I31 -> 4.3452578 | J34: =IF(J31-MAX(F31:I31)<0,J31,MAX(F31:I31)) -> 4.4341557 | K34: =IF(K31-MAX(F31:J31)<0,K31,MAX(F31:J31)) -> 0.026821999
A35: =A32 -> STEM | B35: =B34 -> SPS3 | C35: =C32 -> CH | D35: Imports|Oil|Synthetic liquids|PtL | E35: PJ/yr. | F35: =SUM(F36:F37) -> 0 | G35: =SUM(G36:G37) -> 0 | H35: =SUM(H36:H37) -> 0 | I35: =SUM(I36:I37) -> 0 | J35: =SUM(J36:J37) -> 19.946702 | K35: =SUM(K36:K37) -> 31.250601
A36: =A34 -> STEM | B36: =B35 -> SPS3 | C36: =C34 -> CH | D36: Imports|Oil|Synthetic liquids|PtL|PtL Diesel | E36: PJ/yr. | F36: 0 | G36: 0 | H36: 0 | I36: 0 | J36: =J30-J33 -> 19.809743 | K36: =K30-K33 -> 31.250601
A37: =A36 -> STEM | B37: =B36 -> SPS3 | C37: =C36 -> CH | D37: Imports|Oil|Synthetic liquids|PtL|PtL Gasoline | E37: PJ/yr. | F37: 0 | G37: 0 | H37: 0 | I37: 0 | J37: =J31-J34 -> 0.13695892 | K37: =K31-K34 -> 0
B38: =B37 -> SPS3 | C38: =C37 -> CH | D38: Imports|Oil|Synthetic liquids|PtL|PtL Kerosene | E38: PJ/yr. | F38: 0 | G38: 0 | H38: 0 | I38: 0 | J38: 0 | K38: 0
A39: =A28 -> STEM | B39: =B38 -> SPS3 | C39: =C28 -> CH | D39: Imports|Gas | E39: PJ/yr. | F39: =F40+F43 -> 117.12552 | G39: =G40+G43 -> 107.23653 | H39: =H40+H43 -> 106.38969 | I39: =I40+I43 -> 81.579394 | J39: =J40+J43 -> 22.417945 | K39: =K40+K43 -> 0.00011297262
A40: =A29 -> STEM | B40: =B39 -> SPS3 | C40: =C29 -> CH | D40: Imports|Gas|Fossil gases|Total | E40: PJ/yr. | F40: =F41+F42 -> 117.12552 | G40: =G41+G42 -> 106.72002 | H40: =H41+H42 -> 106.38931 | I40: =I41+I42 -> 81.060549 | J40: =J41+J42 -> 22.417684 | K40: =K41+K42 -> 7.0771735e-05
...

Sheet check
C2: 2020 | D2: 2022 | E2: 2025 | F2: 2030 | G2: 2040 | H2: 2050
B3: Final energy consumption | C3: =SUM(C4:C7) -> 716.98681 | D3: =SUM(D4:D7) -> 703.77611 | E3: =SUM(E4:E7) -> 684.46585 | F3: =SUM(F4:F7) -> 609.7254 | G3: =SUM(G4:G7) -> 483.33703 | H3: =SUM(H4:H7) -> 414.44373
B4: Industry | C4: ='SPS3'!F761 -> 142.21813 | D4: ='SPS3'!G761 -> 141.20304 | E4: ='SPS3'!H761 -> 142.25372 | F4: ='SPS3'!I761 -> 132.10751 | G4: ='SPS3'!J761 -> 113.99443 | H4: ='SPS3'!K761 -> 101.52819
B5: Services | C5: ='SPS3'!F880 -> 140.10135 | D5: ='SPS3'!G880 -> 137.10244 | E5: ='SPS3'!H880 -> 132.25033 | F5: ='SPS3'!I880 -> 118.32714 | G5: ='SPS3'!J880 -> 98.757697 | H5: ='SPS3'!K880 -> 81.989098
B6: Residential | C6: ='SPS3'!F970 -> 219.8674 | D6: ='SPS3'!G970 -> 216.38752 | E6: ='SPS3'!H970 -> 219.31663 | F6: ='SPS3'!I970 -> 196.25134 | G6: ='SPS3'!J970 -> 167.87963 | H6: ='SPS3'!K970 -> 143.04505
B7: Transport | C7: ='SPS3'!F1134+'SPS3'!F1313+'SPS3'!F1397+'SPS3'!F1481+'SPS3'!F1488+'SPS3'!F1495+'SPS3'!F1544+'SPS3'!F1591+'SPS3'!F1638 -> 214.79993 | D7: ='SPS3'!G1134+'SPS3'!G1313+'SPS3'!G1397+'SPS3'!G1481+'SPS3'!G1488+'SPS3'!G1495+'SPS3'!G1544+'SPS3'!G1591+'SPS3'!G1638 -> 209.08311 | E7: ='SPS3'!H1134+'SPS3'!H1313+'SPS3'!H1397+'SPS3'!H1481+'SPS3'!H1488+'SPS3'!H1495+'SPS3'!H1544+'SPS3'!H1591+'SPS3'!H1638 -> 190.64518 | F7: ='SPS3'!I1134+'SPS3'!I1313+'SPS3'!I1397+'SPS3'!I1481+'SPS3'!I1488+'SPS3'!I1495+'SPS3'!I1544+'SPS3'!I1591+'SPS3'!I1638 -> 163.03941 | G7: ='SPS3'!J1134+'SPS3'!J1313+'SPS3'!J1397+'SPS3'!J1481+'SPS3'!J1488+'SPS3'!J1495+'SPS3'!J1544+'SPS3'!J1591+'SPS3'!J1638 -> 102.70528 | H7: ='SPS3'!K1134+'SPS3'!K1313+'SPS3'!K1397+'SPS3'!K1481+'SPS3'!K1488+'SPS3'!K1495+'SPS3'!K1544+'SPS3'!K1591+'SPS3'!K1638 -> 87.881405
B8: Fuel input to energy conversion and DAC | C8: =SUM(C9:C12) -> 509.70286 | D8: =SUM(D9:D12) -> 504.97417 | E8: =SUM(E9:E12) -> 462.06553 | F8: =SUM(F9:F12) -> 535.79391 | G8: =SUM(G9:G12) -> 460.45032 | H8: =SUM(H9:H12) -> 438.79517
B9: Electricity and heat | C9: ='SPS3'!F289+'SPS3'!F407 -> 493.41871 | D9: ='SPS3'!G289+'SPS3'!G407 -> 479.02651 | E9: ='SPS3'!H289+'SPS3'!H407 -> 436.27274 | F9: ='SPS3'!I289+'SPS3'!I407 -> 509.56454 | G9: ='SPS3'!J289+'SPS3'!J407 -> 410.25098 | H9: ='SPS3'!K289+'SPS3'!K407 -> 361.16283
B10: Biofuel production | C10: ='SPS3'!F588+'SPS3'!F602+'SPS3'!F642 -> 16.278736 | D10: ='SPS3'!G588+'SPS3'!G602+'SPS3'!G642 -> 25.940344 | E10: ='SPS3'!H588+'SPS3'!H602+'SPS3'!H642 -> 25.785393 | F10: ='SPS3'!I588+'SPS3'!I602+'SPS3'!I642 -> 26.218987 | G10: ='SPS3'!J588+'SPS3'!J602+'SPS3'!J642 -> 41.873618 | H10: ='SPS3'!K588+'SPS3'!K602+'SPS3'!K642 -> 53.54151
B11: Hydrogen production | C11: ='SPS3'!F677 -> 0.0054157057 | D11: ='SPS3'!G677 -> 0.0073120542 | E11: ='SPS3'!H677 -> 0.0073961389 | F11: ='SPS3'!I677 -> 0.010375269 | G11: ='SPS3'!J677 -> 8.3257091 | H11: ='SPS3'!K677 -> 24.090401
B12: DAC | C12: ='SPS3'!F1702 -> 0 | D12: ='SPS3'!G1702 -> 0 | E12: ='SPS3'!H1702 -> 0 | F12: ='SPS3'!I1702 -> 0 | G12: ='SPS3'!J1702 -> 1.5437019e-05 | H12: ='SPS3'!K1702 -> 0.00043282772
B13: Total Primary energy consumption | C13: ='SPS3'!F2+'SPS3'!F20-'SPS3'!F55 -> 963.44382 | D13: ='SPS3'!G2+'SPS3'!G20-'SPS3'!G55 -> 966.20085 | E13: ='SPS3'!H2+'SPS3'!H20-'SPS3'!H55 -> 881.37338 | F13: ='SPS3'!I2+'SPS3'!I20-'SPS3'!I55 -> 874.65538 | G13: ='SPS3'!J2+'SPS3'!J20-'SPS3'!J55 -> 663.44447 | H13: ='SPS3'!K2+'SPS3'!K20-'SPS3'!K55 -> 563.19673
B14: Domestic production | C14: ='SPS3'!F2 -> 300.18678 | D14: ='SPS3'!G2 -> 295.40443 | E14: ='SPS3'!H2 -> 336.83425 | F14: ='SPS3'!I2 -> 417.25182 | G14: ='SPS3'!J2 -> 453.7564 | H14: ='SPS3'!K2 -> 501.77096
B15: Imports | C15: ='SPS3'!F20 -> 780.4271 | D15: ='SPS3'!G20 -> 705.94703 | E15: ='SPS3'!H20 -> 599.3344 | F15: ='SPS3'!I20 -> 508.1469 | G15: ='SPS3'!J20 -> 231.06476 | H15: ='SPS3'!K20 -> 81.696255
B16: Exports | C16: ='SPS3'!F55 -> 117.17006 | D16: ='SPS3'!G55 -> 35.150611 | E16: ='SPS3'!H55 -> 54.795268 | F16: ='SPS3'!I55 -> 50.743345 | G16: ='SPS3'!J55 -> 21.376692 | H16: ='SPS3'!K55 -> 20.270477
