Workbook

Sheet Variable_List
B2: Variable | C2: Description | D2: Unit | E2: Comment
B3: Primary Production | C3: Domestic primary production of resources | D3: PJ/yr.
B4: Imports | C4: Imports of energy carriers | D4: PJ/yr.
B5: Exports | C5: Exports of energy carriers | D5: PJ/yr.
B6: Electricity generation | C6: Domestic electricity generation | D6: PJ/yr.
B7: Heat generation from CHPs and heat plants | C7: Domestic heat production from CHPs (District heating CHPs or onsite CHPs) and heat plants | D7: PJ/yr.
B8: Fuel input for electricity generation | C8: Fuel input allocated to domestic electricity generation only | D8: PJ/yr.
B9: Fuel input for heat generation from CHPs and heat plants | C9: Fuel input allocated to domestic heat production from CHPs and heat plants only | D9: PJ/yr.
B10: Efficiency of power plants (electric) | C10: Average annual efficiency of power plants and CHPs for electricity production only | D10: % | E10: The thermal efficiency of CHPs can be inferred from the Heat to Electricity production ratio, but it can also be provided; the average efficiency differs from the technical efficiency as it includes efficiency losses due to part load operation
B11: Efficiency of heat plants (thermal) | C11: Average annual efficiency of heat plants | D11: % | E11: It is the annual marketed efficiency including part load efficiency losses and differs from the full load nominal technical efficiency; for heat pumps refers to COP
B12: Domestic biodiesel production | C12: Domestic production of biodiesel | D12: PJ/yr.
B13: Heat from domestic biodiesel production | C13: Heat produced as byproduct from biodiesel production and fed into the district heating network | D13: PJ/yr.
B14: Fuel input for domestic biodiesel production | C14: Fuel input for the domestic production of biodiesel | D14: PJ/yr.
B15: Efficiency for domestic biodiesel production | C15: Average annual efficiency for biodiesel and heat production | D15: %
B16: Domestic ethanol production | C16: Domestic production of ethanol | D16: PJ/yr.
B17: Fuel input for domestic ethanol production | C17: Fuel input for the domestic production of ethanol | D17: PJ/yr.
B18: Efficiency for domestic ethanol production | C18: Average annual efficiency for domestic production of ethanol | D18: %
B19: Domestic biogas production | C19: Domestic production of biogas and biogenic syngas | D19: PJ/yr.
B20: Electricity from domestic biogas production | C20: Electriicty produced as byproduct from biogas production and fed into the grid | D20: PJ/yr.
B21: Heat from domestic biogas production | C21: Heat produced as byproduct from biogas production and fed into the district heating network | D21: PJ/yr.
B22: Fuel input for domestic biogas production | C22: Fuel input for domestic biogas production | D22: PJ/yr.
B23: Efficiency for domestic biogas production | C23: Average annual efficiency for biogas production (accounting for byproduct production) | D23: %
... B25: Fuel input for hydrogen production | C25: Fuel input for deomstic hydrogen production | D25: PJ/yr.
B26: Efficiency for hydrogen production | C26: Average annual efficiency for hydrogen production | D26: % | E26: Including losses due to part load operation
B27: Biomethane production from biogas upgrade | C27: Production of domestic biomethane from biogas | D27: PJ/yr. | E27: One technology only fuel output is biomethane
B28: Fuel input for biogas upgrade to biomethane | C28: Use of biogas for upgrade to biomethane | D28: PJ/yr. | E28: One technology only fuel input is biogas
B29: Efficiency for biomethane production from biogas upgrade | C29: Average annual efficiency of biogas to biomethane upgrade | D29: PJ/yr. | E29: One technology only fuel input is biogas, fuel output is biomethane
B30: Domestic PtG and PtL production | C30: Domestic production of power-to-gas and power-to-liquids | D30: PJ/yr.
B31: Fuel input for domestic PtG and PtL production | C31: Fuel used for domestic PtG and PtL production (excl. CO2) | D31: PJ/yr.
B32: Efficiency for domestic PtG and PtL production | C32: Average annual efficiency for PtG and PtL processes (excl. CO2 consumption) | D32: %
B33: CO2 input for domestic PtG and PtL production | C33: CO2 input for domestic PtG and PtL production | D33: Mt/yr. | E33: The distinction of the source of CO2 (biogenic or fossil) is also provided and can be proportionally allocated to the technologies for PtG and PtL
B34: Domestic wood to pellet production | C34: Wood conversion to pellet domestic production output | D34: PJ/yr. | E34: One technology only , input is wood output is pellet
B35: Fuel input for wood to pellet production | C35: Wood conversion to pellet domestic production - input wood required | D35: PJ/yr. | E35: One technology only , input is wood output is pellet
B36: Efficiency for wood to pellet production | C36: Average annual efficiency of wood to pellet conversion | D36: %
B37: Fuel consumption in industry sectors | C37: Fuel consumption in industry by fuel and technology | D37: PJ/yr. | E37: This unfortunately it will change when the new industrial sectors will be integrated into STEM
B38: Process and space heating production in industry sectors | C38: Energy service demand provided in the form of process and space heating in industry | D38: PJ/yr. | E38: This unfortunately it will change when the new industrial sectors will be integrated into STEM
B39: Efficiency in industry sectors | C39: Boilers efficiency and COP of heat pumps in the industrial sectors | D39: % | E39: This unfortunately it will change when the new industrial sectors will be integrated into STEM
B40: Fuel consumption in Services sectors | C40: Fuel consumption in services sectors by fuel and technology | D40: PJ/yr.
B41: Space water and process heat production in Services sectors | C41: Production of energy service demand for space, water and process heat in Services sectors | D41: PJ/yr.
B42: Efficiency in Services sectors | C42: Boilers efficiency and COP of heat pumps in the Services sectors | D42: %
...

Sheet SPS4_FIN_Low
A1: Model | B1: Scenario | C1: Region | D1: Variable | E1: Unit | F1: 2020 | G1: 2022 | H1: 2025 | I1: 2030 | J1: 2035 | K1: 2040 | L1: 2050
A2: STEM | B2: SPS1 | C2: CH | D2: Primary Production | E2: PJ/yr. | F2: =F3+F8+F11+F12+F16+F17+F18+F19 -> 300.18603 | G2: =G3+G8+G11+G12+G16+G17+G18+G19 -> 295.45269 | H2: =H3+H8+H11+H12+H16+H17+H18+H19 -> 329.78473 | I2: =I3+I8+I11+I12+I16+I17+I18+I19 -> 369.92536 | J2: =J3+J8+J11+J12+J16+J17+J18+J19 -> 383.51029 | K2: =K3+K8+K11+K12+K16+K17+K18+K19 -> 402.42419 | L2: =L3+L8+L11+L12+L16+L17+L18+L19 -> 447.40324
A3: =A2 -> STEM | B3: =B2 -> SPS1 | C3: =C2 -> CH | D3: Primary Production|Wood | E3: PJ/yr. | F3: =SUM(F4:F7) -> 44.972435 | G3: =SUM(G4:G7) -> 48.190471 | H3: =SUM(H4:H7) -> 48.190518 | I3: =SUM(I4:I7) -> 48.19052 | J3: =SUM(J4:J7) -> 51.205952 | K3: =SUM(K4:K7) -> 52.136708 | L3: =SUM(L4:L7) -> 52.136713
A4: =A3 -> STEM | B4: =B3 -> SPS1 | C4: =C3 -> CH | D4: Primary Production|Wood|Waste wood | E4: PJ/yr. | F4: {=SUMPRODUCT(("RNWWOD1"=[1]OUT_PrimaryEnergyCons!$A$1:$A$1000)*1,[1]OUT_PrimaryEnergyCons!D$1:D$1000)} -> 11.111878 | G4: {=SUMPRODUCT(("RNWWOD1"=[1]OUT_PrimaryEnergyCons!$A$1:$A$1000)*1,[1]OUT_PrimaryEnergyCons!E$1:E$1000)} -> 11.952884 | H4: {=SUMPRODUCT(("RNWWOD1"=[1]OUT_PrimaryEnergyCons!$A$1:$A$1000)*1,[1]OUT_PrimaryEnergyCons!F$1:F$1000)} -> 13.214394 | I4: {=SUMPRODUCT(("RNWWOD1"=[1]OUT_PrimaryEnergyCons!$A$1:$A$1000)*1,[1]OUT_PrimaryEnergyCons!G$1:G$1000)} -> 15.31691 | J4: {=SUMPRODUCT(("RNWWOD1"=[2]OUT_PrimaryEnergyCons!$A$1:$A$1000)*1,[2]OUT_PrimaryEnergyCons!H$1:H$1000)} -> 15.849139 | K4: {=SUMPRODUCT(("RNWWOD1"=[2]OUT_PrimaryEnergyCons!$A$1:$A$1000)*1,[2]OUT_PrimaryEnergyCons!I$1:I$1000)} -> 16.266396 | L4: {=SUMPRODUCT(("RNWWOD1"=[2]OUT_PrimaryEnergyCons!$A$1:$A$1000)*1,[2]OUT_PrimaryEnergyCons!J$1:J$1000)} -> 16.956994
A5: =A4 -> STEM | B5: =B4 -> SPS1 | C5: =C4 -> CH | D5: Primary Production|Wood|Wood residues | E5: PJ/yr. | F5: {=SUMPRODUCT(("RNWWOD2"=[1]OUT_PrimaryEnergyCons!$A$1:$A$1000)*1,[1]OUT_PrimaryEnergyCons!D$1:D$1000)} -> 7.5116713 | G5: {=SUMPRODUCT(("RNWWOD2"=[1]OUT_PrimaryEnergyCons!$A$1:$A$1000)*1,[1]OUT_PrimaryEnergyCons!E$1:E$1000)} -> 7.5431417 | H5: {=SUMPRODUCT(("RNWWOD2"=[1]OUT_PrimaryEnergyCons!$A$1:$A$1000)*1,[1]OUT_PrimaryEnergyCons!F$1:F$1000)} -> 7.5903487 | I5: {=SUMPRODUCT(("RNWWOD2"=[1]OUT_PrimaryEnergyCons!$A$1:$A$1000)*1,[1]OUT_PrimaryEnergyCons!G$1:G$1000)} -> 7.6690272 | J5: {=SUMPRODUCT(("RNWWOD2"=[2]OUT_PrimaryEnergyCons!$A$1:$A$1000)*1,[2]OUT_PrimaryEnergyCons!H$1:H$1000)} -> 7.6690262 | K5: {=SUMPRODUCT(("RNWWOD2"=[2]OUT_PrimaryEnergyCons!$A$1:$A$1000)*1,[2]OUT_PrimaryEnergyCons!I$1:I$1000)} -> 7.6690265 | L5: {=SUMPRODUCT(("RNWWOD2"=[2]OUT_PrimaryEnergyCons!$A$1:$A$1000)*1,[2]OUT_PrimaryEnergyCons!J$1:J$1000)} -> 7.6690269
A6: =A5 -> STEM | B6: =B5 -> SPS1 | C6: =C5 -> CH | D6: Primary Production|Wood|Wood from landscape maintenance | E6: PJ/yr. | F6: {=SUMPRODUCT(("RNWWOD3"=[1]OUT_PrimaryEnergyCons!$A$1:$A$1000)*1,[1]OUT_PrimaryEnergyCons!D$1:D$1000)} -> 3.1682452 | G6: {=SUMPRODUCT(("RNWWOD3"=[1]OUT_PrimaryEnergyCons!$A$1:$A$1000)*1,[1]OUT_PrimaryEnergyCons!E$1:E$1000)} -> 3.4956727 | H6: {=SUMPRODUCT(("RNWWOD3"=[1]OUT_PrimaryEnergyCons!$A$1:$A$1000)*1,[1]OUT_PrimaryEnergyCons!F$1:F$1000)} -> 3.9868152 | I6: {=SUMPRODUCT(("RNWWOD3"=[1]OUT_PrimaryEnergyCons!$A$1:$A$1000)*1,[1]OUT_PrimaryEnergyCons!G$1:G$1000)} -> 4.8053865 | J6: {=SUMPRODUCT(("RNWWOD3"=[2]OUT_PrimaryEnergyCons!$A$1:$A$1000)*1,[2]OUT_PrimaryEnergyCons!H$1:H$1000)} -> 4.8053854 | K6: {=SUMPRODUCT(("RNWWOD3"=[2]OUT_PrimaryEnergyCons!$A$1:$A$1000)*1,[2]OUT_PrimaryEnergyCons!I$1:I$1000)} -> 4.8053857 | L6: {=SUMPRODUCT(("RNWWOD3"=[2]OUT_PrimaryEnergyCons!$A$1:$A$1000)*1,[2]OUT_PrimaryEnergyCons!J$1:J$1000)} -> 4.8053858
A7: =A6 -> STEM | B7: =B6 -> SPS1 | C7: =C6 -> CH | D7: Primary Production|Wood|Wood from Forest (hard wood) | E7: PJ/yr. | F7: {=SUMPRODUCT(("RNWWOD4"=[1]OUT_PrimaryEnergyCons!$A$1:$A$1000)*1+("RNWWOD5"=[1]OUT_PrimaryEnergyCons!$A$1:$A$1000)*1,[1]OUT_PrimaryEnergyCons!D$1:D$1000)} -> 23.180641 | G7: {=SUMPRODUCT(("RNWWOD4"=[1]OUT_PrimaryEnergyCons!$A$1:$A$1000)*1+("RNWWOD5"=[1]OUT_PrimaryEnergyCons!$A$1:$A$1000)*1,[1]OUT_PrimaryEnergyCons!E$1:E$1000)} -> 25.198773 | H7: {=SUMPRODUCT(("RNWWOD4"=[1]OUT_PrimaryEnergyCons!$A$1:$A$1000)*1+("RNWWOD5"=[1]OUT_PrimaryEnergyCons!$A$1:$A$1000)*1,[1]OUT_PrimaryEnergyCons!F$1:F$1000)} -> 23.39896 | I7: {=SUMPRODUCT(("RNWWOD4"=[1]OUT_PrimaryEnergyCons!$A$1:$A$1000)*1+("RNWWOD5"=[1]OUT_PrimaryEnergyCons!$A$1:$A$1000)*1,[1]OUT_PrimaryEnergyCons!G$1:G$1000)} -> 20.399196 | J7: {=SUMPRODUCT(("RNWWOD4"=[2]OUT_PrimaryEnergyCons!$A$1:$A$1000)*1+("RNWWOD5"=[2]OUT_PrimaryEnergyCons!$A$1:$A$1000)*1,[2]OUT_PrimaryEnergyCons!H$1:H$1000)} -> 22.882402 | K7: {=SUMPRODUCT(("RNWWOD4"=[2]OUT_PrimaryEnergyCons!$A$1:$A$1000)*1+("RNWWOD5"=[2]OUT_PrimaryEnergyCons!$A$1:$A$1000)*1,[2]OUT_PrimaryEnergyCons!I$1:I$1000)} -> 23.3959 | L7: {=SUMPRODUCT(("RNWWOD4"=[2]OUT_PrimaryEnergyCons!$A$1:$A$1000)*1+("RNWWOD5"=[2]OUT_PrimaryEnergyCons!$A$1:$A$1000)*1,[2]OUT_PrimaryEnergyCons!J$1:J$1000)} -> 22.705307
A8: =A7 -> STEM | B8: =B7 -> SPS1 | C8: =C7 -> CH | D8: Primary Production|Waste | E8: PJ/yr. | F8: =SUM(F9:F10) -> 70.031508 | G8: =SUM(G9:G10) -> 70.696979 | H8: =SUM(H9:H10) -> 70.30407 | I8: =SUM(I9:I10) -> 69.85456 | J8: =SUM(J9:J10) -> 69.752072 | K8: =SUM(K9:K10) -> 69.973946 | L8: =SUM(L9:L10) -> 70.417687
A9: =A8 -> STEM | B9: =B8 -> SPS1 | C9: =C8 -> CH | D9: Primary Production|Waste|Non renewable waste | E9: PJ/yr. | F9: {=SUMPRODUCT(("RNNWWST1"=[1]OUT_PrimaryEnergyCons!$A$1:$A$1000)*1,[1]OUT_PrimaryEnergyCons!D$1:D$1000)} -> 35.931071 | G9: {=SUMPRODUCT(("RNNWWST1"=[1]OUT_PrimaryEnergyCons!$A$1:$A$1000)*1,[1]OUT_PrimaryEnergyCons!E$1:E$1000)} -> 35.882384 | H9: {=SUMPRODUCT(("RNNWWST1"=[1]OUT_PrimaryEnergyCons!$A$1:$A$1000)*1,[1]OUT_PrimaryEnergyCons!F$1:F$1000)} -> 35.489473 | I9: {=SUMPRODUCT(("RNNWWST1"=[1]OUT_PrimaryEnergyCons!$A$1:$A$1000)*1,[1]OUT_PrimaryEnergyCons!G$1:G$1000)} -> 35.039965 | J9: {=SUMPRODUCT(("RNNWWST1"=[2]OUT_PrimaryEnergyCons!$A$1:$A$1000)*1,[2]OUT_PrimaryEnergyCons!H$1:H$1000)} -> 34.937586 | K9: {=SUMPRODUCT(("RNNWWST1"=[2]OUT_PrimaryEnergyCons!$A$1:$A$1000)*1,[2]OUT_PrimaryEnergyCons!I$1:I$1000)} -> 35.15945 | L9: {=SUMPRODUCT(("RNNWWST1"=[2]OUT_PrimaryEnergyCons!$A$1:$A$1000)*1,[2]OUT_PrimaryEnergyCons!J$1:J$1000)} -> 35.603176
A10: =A9 -> STEM | B10: =B9 -> SPS1 | C10: =C9 -> CH | D10: Primary Production|Waste|Renewable waste | E10: PJ/yr. | F10: {=SUMPRODUCT(("RNWWST1"=[1]OUT_PrimaryEnergyCons!$A$1:$A$1000)*1,[1]OUT_PrimaryEnergyCons!D$1:D$1000)} -> 34.100436 | G10: {=SUMPRODUCT(("RNWWST1"=[1]OUT_PrimaryEnergyCons!$A$1:$A$1000)*1,[1]OUT_PrimaryEnergyCons!E$1:E$1000)} -> 34.814595 | H10: {=SUMPRODUCT(("RNWWST1"=[1]OUT_PrimaryEnergyCons!$A$1:$A$1000)*1,[1]OUT_PrimaryEnergyCons!F$1:F$1000)} -> 34.814597 | I10: {=SUMPRODUCT(("RNWWST1"=[1]OUT_PrimaryEnergyCons!$A$1:$A$1000)*1,[1]OUT_PrimaryEnergyCons!G$1:G$1000)} -> 34.814595 | J10: {=SUMPRODUCT(("RNWWST1"=[2]OUT_PrimaryEnergyCons!$A$1:$A$1000)*1,[2]OUT_PrimaryEnergyCons!H$1:H$1000)} -> 34.814486 | K10: {=SUMPRODUCT(("RNWWST1"=[2]OUT_PrimaryEnergyCons!$A$1:$A$1000)*1,[2]OUT_PrimaryEnergyCons!I$1:I$1000)} -> 34.814496 | L10: {=SUMPRODUCT(("RNWWST1"=[2]OUT_PrimaryEnergyCons!$A$1:$A$1000)*1,[2]OUT_PrimaryEnergyCons!J$1:J$1000)} -> 34.814511
A11: =A10 -> STEM | B11: =B10 -> SPS1 | C11: =C10 -> CH | D11: Primary Production|Manure | E11: PJ/yr. | F11: {=SUMPRODUCT(("mnr"=[1]OUT_PrimaryEnergyCons!$C$1:$C$1000)*1,[1]OUT_PrimaryEnergyCons!D$1:D$1000)} -> 3.7980856 | G11: {=SUMPRODUCT(("mnr"=[1]OUT_PrimaryEnergyCons!$C$1:$C$1000)*1,[1]OUT_PrimaryEnergyCons!E$1:E$1000)} -> 12.115548 | H11: {=SUMPRODUCT(("mnr"=[1]OUT_PrimaryEnergyCons!$C$1:$C$1000)*1,[1]OUT_PrimaryEnergyCons!F$1:F$1000)} -> 12.540331 | I11: {=SUMPRODUCT(("mnr"=[1]OUT_PrimaryEnergyCons!$C$1:$C$1000)*1,[1]OUT_PrimaryEnergyCons!G$1:G$1000)} -> 12.540426 | J11: {=SUMPRODUCT(("mnr"=[2]OUT_PrimaryEnergyCons!$C$1:$C$1000)*1,[2]OUT_PrimaryEnergyCons!H$1:H$1000)} -> 12.540427 | K11: {=SUMPRODUCT(("mnr"=[2]OUT_PrimaryEnergyCons!$C$1:$C$1000)*1,[2]OUT_PrimaryEnergyCons!I$1:I$1000)} -> 12.64167 | L11: {=SUMPRODUCT(("mnr"=[2]OUT_PrimaryEnergyCons!$C$1:$C$1000)*1,[2]OUT_PrimaryEnergyCons!J$1:J$1000)} -> 17.636691
A12: =A11 -> STEM | B12: =B11 -> SPS1 | C12: =C11 -> CH | D12: Primary Production|Hydro | E12: PJ/yr. | F12: =SUM(F13:F15) -> 149.43048 | G12: =SUM(G13:G15) -> 125.60471 | H12: =SUM(H13:H15) -> 137.62371 | I12: =SUM(I13:I15) -> 150.62455 | J12: =SUM(J13:J15) -> 150.69272 | K12: =SUM(K13:K15) -> 150.82547 | L12: =SUM(L13:L15) -> 151.06688
A13: =A12 -> STEM | B13: =B12 -> SPS1 | C13: =C12 -> CH | D13: Primary Production|Hydro|Large hydro | E13: PJ/yr. | F13: {=SUMPRODUCT(ISNUMBER(SEARCH("EHYD-DAM",[1]OUT_Electricity_CHP!$B$1:$B$10000))*1,([1]OUT_Electricity_CHP!$C$1:$C$10000="Var_Fout")*1,ISNUMBER(SEARCH("ELC",[1]OUT_Electricity_CHP!$D$1:$D$10000))*1,[1]OUT_Electricity_CHP!E$1:E$10000)} -> 66.74568 | G13: {=SUMPRODUCT(ISNUMBER(SEARCH("EHYD-DAM",[1]OUT_Electricity_CHP!$B$1:$B$10000))*1,([1]OUT_Electricity_CHP!$C$1:$C$10000="Var_Fout")*1,ISNUMBER(SEARCH("ELC",[1]OUT_Electricity_CHP!$D$1:$D$10000))*1,[1]OUT_Electricity_CHP!F$1:F$10000)} -> 49.7988 | H13: {=SUMPRODUCT(ISNUMBER(SEARCH("EHYD-DAM",[1]OUT_Electricity_CHP!$B$1:$B$10000))*1,([1]OUT_Electricity_CHP!$C$1:$C$10000="Var_Fout")*1,ISNUMBER(SEARCH("ELC",[1]OUT_Electricity_CHP!$D$1:$D$10000))*1,[1]OUT_Electricity_CHP!G$1:G$10000)} -> 69.098092 | I13: {=SUMPRODUCT(ISNUMBER(SEARCH("EHYD-DAM",[1]OUT_Electricity_CHP!$B$1:$B$10000))*1,([1]OUT_Electricity_CHP!$C$1:$C$10000="Var_Fout")*1,ISNUMBER(SEARCH("ELC",[1]OUT_Electricity_CHP!$D$1:$D$10000))*1,[1]OUT_Electricity_CHP!H$1:H$10000)} -> 70.384658 | J13: {=SUMPRODUCT(ISNUMBER(SEARCH("EHYD-DAM",[2]OUT_Electricity_CHP!$B$1:$B$10000))*1,([2]OUT_Electricity_CHP!$C$1:$C$10000="Var_Fout")*1,ISNUMBER(SEARCH("ELC",[2]OUT_Electricity_CHP!$D$1:$D$10000))*1,[2]OUT_Electricity_CHP!I$1:I$10000)} -> 71.523278 | K13: {=SUMPRODUCT(ISNUMBER(SEARCH("EHYD-DAM",[2]OUT_Electricity_CHP!$B$1:$B$10000))*1,([2]OUT_Electricity_CHP!$C$1:$C$10000="Var_Fout")*1,ISNUMBER(SEARCH("ELC",[2]OUT_Electricity_CHP!$D$1:$D$10000))*1,[2]OUT_Electricity_CHP!J$1:J$10000)} -> 72.607216 | L13: {=SUMPRODUCT(ISNUMBER(SEARCH("EHYD-DAM",[2]OUT_Electricity_CHP!$B$1:$B$10000))*1,([2]OUT_Electricity_CHP!$C$1:$C$10000="Var_Fout")*1,ISNUMBER(SEARCH("ELC",[2]OUT_Electricity_CHP!$D$1:$D$10000))*1,[2]OUT_Electricity_CHP!K$1:K$10000)} -> 74.776919
A14: =A13 -> STEM | B14: =B13 -> SPS1 | C14: =C13 -> CH | D14: Primary Production|Hydro|Run-of-river hydro | E14: PJ/yr. | F14: {=SUMPRODUCT(ISNUMBER(SEARCH("EHYD-RUN",[1]OUT_Electricity_CHP!$B$1:$B$10000))*1,([1]OUT_Electricity_CHP!$C$1:$C$10000="Var_Fout")*1,ISNUMBER(SEARCH("ELC",[1]OUT_Electricity_CHP!$D$1:$D$10000))*1,[1]OUT_Electricity_CHP!E$1:E$10000)} -> 66.6324 | G14: {=SUMPRODUCT(ISNUMBER(SEARCH("EHYD-RUN",[1]OUT_Electricity_CHP!$B$1:$B$10000))*1,([1]OUT_Electricity_CHP!$C$1:$C$10000="Var_Fout")*1,ISNUMBER(SEARCH("ELC",[1]OUT_Electricity_CHP!$D$1:$D$10000))*1,[1]OUT_Electricity_CHP!F$1:F$10000)} -> 55.764 | H14: {=SUMPRODUCT(ISNUMBER(SEARCH("EHYD-RUN",[1]OUT_Electricity_CHP!$B$1:$B$10000))*1,([1]OUT_Electricity_CHP!$C$1:$C$10000="Var_Fout")*1,ISNUMBER(SEARCH("ELC",[1]OUT_Electricity_CHP!$D$1:$D$10000))*1,[1]OUT_Electricity_CHP!G$1:G$10000)} -> 65.549521 | I14: {=SUMPRODUCT(ISNUMBER(SEARCH("EHYD-RUN",[1]OUT_Electricity_CHP!$B$1:$B$10000))*1,([1]OUT_Electricity_CHP!$C$1:$C$10000="Var_Fout")*1,ISNUMBER(SEARCH("ELC",[1]OUT_Electricity_CHP!$D$1:$D$10000))*1,[1]OUT_Electricity_CHP!H$1:H$10000)} -> 64.465726 | J14: {=SUMPRODUCT(ISNUMBER(SEARCH("EHYD-RUN",[2]OUT_Electricity_CHP!$B$1:$B$10000))*1,([2]OUT_Electricity_CHP!$C$1:$C$10000="Var_Fout")*1,ISNUMBER(SEARCH("ELC",[2]OUT_Electricity_CHP!$D$1:$D$10000))*1,[2]OUT_Electricity_CHP!I$1:I$10000)} -> 63.38598 | K14: {=SUMPRODUCT(ISNUMBER(SEARCH("EHYD-RUN",[2]OUT_Electricity_CHP!$B$1:$B$10000))*1,([2]OUT_Electricity_CHP!$C$1:$C$10000="Var_Fout")*1,ISNUMBER(SEARCH("ELC",[2]OUT_Electricity_CHP!$D$1:$D$10000))*1,[2]OUT_Electricity_CHP!J$1:J$10000)} -> 62.302043 | L14: {=SUMPRODUCT(ISNUMBER(SEARCH("EHYD-RUN",[2]OUT_Electricity_CHP!$B$1:$B$10000))*1,([2]OUT_Electricity_CHP!$C$1:$C$10000="Var_Fout")*1,ISNUMBER(SEARCH("ELC",[2]OUT_Electricity_CHP!$D$1:$D$10000))*1,[2]OUT_Electricity_CHP!K$1:K$10000)} -> 60.132341
A15: =A14 -> STEM | B15: =B14 -> SPS1 | C15: =C14 -> CH | D15: Primary Production|Hydro|Pump storage | E15: PJ/yr. | F15: {=SUMPRODUCT(ISNUMBER(SEARCH("EHYD-PUM",[1]OUT_Electricity_CHP!$B$1:$B$10000))*1,([1]OUT_Electricity_CHP!$C$1:$C$10000="Var_Fin")*1,ISNUMBER(SEARCH("elc",[1]OUT_Electricity_CHP!$D$1:$D$10000))*1,[1]OUT_Electricity_CHP!E$1:E$10000)} -> 16.052401 | G15: {=SUMPRODUCT(ISNUMBER(SEARCH("EHYD-PUM",[1]OUT_Electricity_CHP!$B$1:$B$10000))*1,([1]OUT_Electricity_CHP!$C$1:$C$10000="Var_Fin")*1,ISNUMBER(SEARCH("elc",[1]OUT_Electricity_CHP!$D$1:$D$10000))*1,[1]OUT_Electricity_CHP!F$1:F$10000)} -> 20.041905 | H15: {=SUMPRODUCT(ISNUMBER(SEARCH("EHYD-PUM",[1]OUT_Electricity_CHP!$B$1:$B$10000))*1,([1]OUT_Electricity_CHP!$C$1:$C$10000="Var_Fin")*1,ISNUMBER(SEARCH("elc",[1]OUT_Electricity_CHP!$D$1:$D$10000))*1,[1]OUT_Electricity_CHP!G$1:G$10000)} -> 2.9761012 | I15: {=SUMPRODUCT(ISNUMBER(SEARCH("EHYD-PUM",[1]OUT_Electricity_CHP!$B$1:$B$10000))*1,([1]OUT_Electricity_CHP!$C$1:$C$10000="Var_Fin")*1,ISNUMBER(SEARCH("elc",[1]OUT_Electricity_CHP!$D$1:$D$10000))*1,[1]OUT_Electricity_CHP!H$1:H$10000)} -> 15.774166 | J15: {=SUMPRODUCT(ISNUMBER(SEARCH("EHYD-PUM",[2]OUT_Electricity_CHP!$B$1:$B$10000))*1,([2]OUT_Electricity_CHP!$C$1:$C$10000="Var_Fin")*1,ISNUMBER(SEARCH("elc",[2]OUT_Electricity_CHP!$D$1:$D$10000))*1,[2]OUT_Electricity_CHP!I$1:I$10000)} -> 15.783462 | K15: {=SUMPRODUCT(ISNUMBER(SEARCH("EHYD-PUM",[2]OUT_Electricity_CHP!$B$1:$B$10000))*1,([2]OUT_Electricity_CHP!$C$1:$C$10000="Var_Fin")*1,ISNUMBER(SEARCH("elc",[2]OUT_Electricity_CHP!$D$1:$D$10000))*1,[2]OUT_Electricity_CHP!J$1:J$10000)} -> 15.916208 | L15: {=SUMPRODUCT(ISNUMBER(SEARCH("EHYD-PUM",[2]OUT_Electricity_CHP!$B$1:$B$10000))*1,([2]OUT_Electricity_CHP!$C$1:$C$10000="Var_Fin")*1,ISNUMBER(SEARCH("elc",[2]OUT_Electricity_CHP!$D$1:$D$10000))*1,[2]OUT_Electricity_CHP!K$1:K$10000)} -> 16.157624
A16: =A15 -> STEM | B16: =B15 -> SPS1 | C16: =C15 -> CH | D16: Primary Production|Solar | E16: PJ/yr. | F16: {=SUMPRODUCT(ISNUMBER(SEARCH("SOL",[1]OUT_PrimaryEnergyCons!$C$1:$C$1000))*1,[1]OUT_PrimaryEnergyCons!D$1:D$1000)} -> 12.556465 | G16: {=SUMPRODUCT(ISNUMBER(SEARCH("SOL",[1]OUT_PrimaryEnergyCons!$C$1:$C$1000))*1,[1]OUT_PrimaryEnergyCons!E$1:E$1000)} -> 16.522193 | H16: {=SUMPRODUCT(ISNUMBER(SEARCH("SOL",[1]OUT_PrimaryEnergyCons!$C$1:$C$1000))*1,[1]OUT_PrimaryEnergyCons!F$1:F$1000)} -> 30.343315 | I16: {=SUMPRODUCT(ISNUMBER(SEARCH("SOL",[1]OUT_PrimaryEnergyCons!$C$1:$C$1000))*1,[1]OUT_PrimaryEnergyCons!G$1:G$1000)} -> 40.766964 | J16: {=SUMPRODUCT(ISNUMBER(SEARCH("SOL",[2]OUT_PrimaryEnergyCons!$C$1:$C$1000))*1,[2]OUT_PrimaryEnergyCons!H$1:H$1000)} -> 42.651103 | K16: {=SUMPRODUCT(ISNUMBER(SEARCH("SOL",[2]OUT_PrimaryEnergyCons!$C$1:$C$1000))*1,[2]OUT_PrimaryEnergyCons!I$1:I$1000)} -> 52.374004 | L16: {=SUMPRODUCT(ISNUMBER(SEARCH("SOL",[2]OUT_PrimaryEnergyCons!$C$1:$C$1000))*1,[2]OUT_PrimaryEnergyCons!J$1:J$1000)} -> 70.013707
A17: =A16 -> STEM | B17: =B16 -> SPS1 | C17: =C16 -> CH | D17: Primary Production|Wind | E17: PJ/yr. | F17: {=SUMPRODUCT(ISNUMBER(SEARCH("wnd",[1]OUT_PrimaryEnergyCons!$C$1:$C$1000))*1,[1]OUT_PrimaryEnergyCons!D$1:D$1000)} -> 0.52400642 | G17: {=SUMPRODUCT(ISNUMBER(SEARCH("wnd",[1]OUT_PrimaryEnergyCons!$C$1:$C$1000))*1,[1]OUT_PrimaryEnergyCons!E$1:E$1000)} -> 0.54529297 | H17: {=SUMPRODUCT(ISNUMBER(SEARCH("wnd",[1]OUT_PrimaryEnergyCons!$C$1:$C$1000))*1,[1]OUT_PrimaryEnergyCons!F$1:F$1000)} -> 0.50316557 | I17: {=SUMPRODUCT(ISNUMBER(SEARCH("wnd",[1]OUT_PrimaryEnergyCons!$C$1:$C$1000))*1,[1]OUT_PrimaryEnergyCons!G$1:G$1000)} -> 2.050267 | J17: {=SUMPRODUCT(ISNUMBER(SEARCH("wnd",[2]OUT_PrimaryEnergyCons!$C$1:$C$1000))*1,[2]OUT_PrimaryEnergyCons!H$1:H$1000)} -> 0.93821047 | K17: {=SUMPRODUCT(ISNUMBER(SEARCH("wnd",[2]OUT_PrimaryEnergyCons!$C$1:$C$1000))*1,[2]OUT_PrimaryEnergyCons!I$1:I$1000)} -> 0.93822669 | L17: {=SUMPRODUCT(ISNUMBER(SEARCH("wnd",[2]OUT_PrimaryEnergyCons!$C$1:$C$1000))*1,[2]OUT_PrimaryEnergyCons!J$1:J$1000)} -> 0.93859981
A18: =A17 -> STEM | B18: =B17 -> SPS1 | C18: =C17 -> CH | D18: Primary Production|Ambient heat | E18: PJ/yr. | F18: =[1]Overview!B$9-F19 -> 18.873044 | G18: =[1]Overview!C$9-G19 -> 21.777499 | H18: =[1]Overview!D$9-H19 -> 30.279619 | I18: =[1]Overview!E$9-I19 -> 45.898069 | J18: =[2]Overview!F$9-J19 -> 55.729804 | K18: =[2]Overview!G$9-K19 -> 63.517402 | L18: =[2]Overview!H$9-L19 -> 85.086385
A19: =A18 -> STEM | B19: =B18 -> SPS1 | C19: =C18 -> CH | D19: Primary Production|Geothermal | E19: PJ/yr. | F19: =+[1]Overview!B$28 -> 0 | G19: =+[1]Overview!C$28 -> 0 | H19: =+[1]Overview!D$28 -> 0 | I19: =+[1]Overview!E$28 -> 0 | J19: =+[2]Overview!F$28 -> 0 | K19: =+[2]Overview!G$28 -> 0.016764987 | L19: =+[2]Overview!H$28 -> 0.10657571
A20: =A19 -> STEM | B20: =B19 -> SPS1 | C20: =C19 -> CH | D20: Imports | E20: PJ/yr. | F20: =SUM(F21:F22,F41,F50:F51,F56) -> 779.2967 | G20: =SUM(G21:G22,G41,G50:G51,G56) -> 700.84944 | H20: =SUM(H21:H22,H41,H50:H51,H56) -> 657.91151 | I20: =SUM(I21:I22,I41,I50:I51,I56) -> 553.03123 | J20: =SUM(J21:J22,J41,J50:J51,J56) -> 467.07405 | K20: =SUM(K21:K22,K41,K50:K51,K56) -> 370.78838 | L20: =SUM(L21:L22,L41,L50:L51,L56) -> 227.83896
A21: =A20 -> STEM | B21: =B20 -> SPS1 | C21: =C20 -> CH | D21: Imports|Coal | E21: PJ/yr. | F21: {=SUMPRODUCT(("COA"=[1]OUT_PrimaryEnergyCons!$C$4:$C$10000)*1,[1]OUT_PrimaryEnergyCons!D$4:D$10000)} -> 3.6600053 | G21: {=SUMPRODUCT(("COA"=[1]OUT_PrimaryEnergyCons!$C$4:$C$10000)*1,[1]OUT_PrimaryEnergyCons!E$4:E$10000)} -> 3.5647181 | H21: {=SUMPRODUCT(("COA"=[1]OUT_PrimaryEnergyCons!$C$4:$C$10000)*1,[1]OUT_PrimaryEnergyCons!F$4:F$10000)} -> 3.36728 | I21: {=SUMPRODUCT(("COA"=[1]OUT_PrimaryEnergyCons!$C$4:$C$10000)*1,[1]OUT_PrimaryEnergyCons!G$4:G$10000)} -> 0.0062984431 | J21: {=SUMPRODUCT(("COA"=[2]OUT_PrimaryEnergyCons!$C$4:$C$10000)*1,[2]OUT_PrimaryEnergyCons!H$4:H$10000)} -> 0.0023452262 | K21: {=SUMPRODUCT(("COA"=[2]OUT_PrimaryEnergyCons!$C$4:$C$10000)*1,[2]OUT_PrimaryEnergyCons!I$4:I$10000)} -> 0.00069834284 | L21: {=SUMPRODUCT(("COA"=[2]OUT_PrimaryEnergyCons!$C$4:$C$10000)*1,[2]OUT_PrimaryEnergyCons!J$4:J$10000)} -> 0.00036979546
A22: =A21 -> STEM | B22: =B21 -> SPS1 | C22: =C21 -> CH | D22: Imports|Oil | E22: PJ/yr. | F22: =F23+F29 -> 310.48072 | G22: =G23+G29 -> 286.47395 | H22: =H23+H29 -> 263.66721 | I22: =I23+I29 -> 186.63073 | J22: =J23+J29 -> 131.57429 | K22: =K23+K29 -> 116.12757 | L22: =L23+L29 -> 87.915198
A23: =A22 -> STEM | B23: =B22 -> SPS1 | C23: =C22 -> CH | D23: Imports|Oil|Fossil liquids | E23: PJ/yr. | F23: =SUM(F24:F28) -> 303.6756 | G23: =SUM(G24:G28) -> 279.76996 | H23: =SUM(H24:H28) -> 256.48635 | I23: =SUM(I24:I28) -> 174.92568 | J23: =SUM(J24:J28) -> 120.7062 | K23: =SUM(K24:K28) -> 105.30664 | L23: =SUM(L24:L28) -> 77.379969
A24: =A22 -> STEM | B24: =B22 -> SPS1 | C24: =C22 -> CH | D24: Imports|Oil|Fossil liquids|Light fuel oil | E24: PJ/yr. | F24: {=SUMPRODUCT(("LFO"=[1]OUT_PrimaryEnergyCons!$C$4:$C$10000)*1,[1]OUT_PrimaryEnergyCons!D$4:D$10000)} -> 101.72708 | G24: {=SUMPRODUCT(("LFO"=[1]OUT_PrimaryEnergyCons!$C$4:$C$10000)*1,[1]OUT_PrimaryEnergyCons!E$4:E$10000)} -> 88.213219 | H24: {=SUMPRODUCT(("LFO"=[1]OUT_PrimaryEnergyCons!$C$4:$C$10000)*1,[1]OUT_PrimaryEnergyCons!F$4:F$10000)} -> 87.829416 | I24: {=SUMPRODUCT(("LFO"=[1]OUT_PrimaryEnergyCons!$C$4:$C$10000)*1,[1]OUT_PrimaryEnergyCons!G$4:G$10000)} -> 60.373687 | J24: {=SUMPRODUCT(("LFO"=[2]OUT_PrimaryEnergyCons!$C$4:$C$10000)*1,[2]OUT_PrimaryEnergyCons!H$4:H$10000)} -> 44.765996 | K24: {=SUMPRODUCT(("LFO"=[2]OUT_PrimaryEnergyCons!$C$4:$C$10000)*1,[2]OUT_PrimaryEnergyCons!I$4:I$10000)} -> 33.357017 | L24: {=SUMPRODUCT(("LFO"=[2]OUT_PrimaryEnergyCons!$C$4:$C$10000)*1,[2]OUT_PrimaryEnergyCons!J$4:J$10000)} -> 12.984924
A25: =A24 -> STEM | B25: =B24 -> SPS1 | C25: =C24 -> CH | D25: Imports|Oil|Fossil liquids|Heavy fuel oil | E25: PJ/yr. | F25: {=SUMPRODUCT(("HFO"=[1]OUT_PrimaryEnergyCons!$C$4:$C$10000)*1,[1]OUT_PrimaryEnergyCons!D$4:D$10000)} -> 2.776373 | G25: {=SUMPRODUCT(("HFO"=[1]OUT_PrimaryEnergyCons!$C$4:$C$10000)*1,[1]OUT_PrimaryEnergyCons!E$4:E$10000)} -> 2.7644096 | H25: {=SUMPRODUCT(("HFO"=[1]OUT_PrimaryEnergyCons!$C$4:$C$10000)*1,[1]OUT_PrimaryEnergyCons!F$4:F$10000)} -> 0.0011874232 | I25: {=SUMPRODUCT(("HFO"=[1]OUT_PrimaryEnergyCons!$C$4:$C$10000)*1,[1]OUT_PrimaryEnergyCons!G$4:G$10000)} -> 0.00021723863 | J25: {=SUMPRODUCT(("HFO"=[2]OUT_PrimaryEnergyCons!$C$4:$C$10000)*1,[2]OUT_PrimaryEnergyCons!H$4:H$10000)} -> 0.0010803013 | K25: {=SUMPRODUCT(("HFO"=[2]OUT_PrimaryEnergyCons!$C$4:$C$10000)*1,[2]OUT_PrimaryEnergyCons!I$4:I$10000)} -> 0.00075511098 | L25: {=SUMPRODUCT(("HFO"=[2]OUT_PrimaryEnergyCons!$C$4:$C$10000)*1,[2]OUT_PrimaryEnergyCons!J$4:J$10000)} -> 0
A26: =A25 -> STEM | B26: =B25 -> SPS1 | C26: =C25 -> CH | D26: Imports|Oil|Fossil liquids|Motor Diesel | E26: PJ/yr. | F26: {=SUMPRODUCT(("DSL"=[1]OUT_PrimaryEnergyCons!$C$4:$C$10000)*1,[1]OUT_PrimaryEnergyCons!D$4:D$10000)} -> 117.52489 | G26: {=SUMPRODUCT(("DSL"=[1]OUT_PrimaryEnergyCons!$C$4:$C$10000)*1,[1]OUT_PrimaryEnergyCons!E$4:E$10000)} -> 112.68584 | H26: {=SUMPRODUCT(("DSL"=[1]OUT_PrimaryEnergyCons!$C$4:$C$10000)*1,[1]OUT_PrimaryEnergyCons!F$4:F$10000)} -> 95.748446 | I26: {=SUMPRODUCT(("DSL"=[1]OUT_PrimaryEnergyCons!$C$4:$C$10000)*1,[1]OUT_PrimaryEnergyCons!G$4:G$10000)} -> 69.136065 | J26: {=SUMPRODUCT(("DSL"=[2]OUT_PrimaryEnergyCons!$C$4:$C$10000)*1,[2]OUT_PrimaryEnergyCons!H$4:H$10000)} -> 47.814421 | K26: {=SUMPRODUCT(("DSL"=[2]OUT_PrimaryEnergyCons!$C$4:$C$10000)*1,[2]OUT_PrimaryEnergyCons!I$4:I$10000)} -> 45.182592 | L26: {=SUMPRODUCT(("DSL"=[2]OUT_PrimaryEnergyCons!$C$4:$C$10000)*1,[2]OUT_PrimaryEnergyCons!J$4:J$10000)} -> 43.053153
A27: =A26 -> STEM | B27: =B26 -> SPS1 | C27: =C26 -> CH | D27: Imports|Oil|Fossil liquids|Motor Gasoline | E27: PJ/yr. | F27: {=SUMPRODUCT(("GSL"=[1]OUT_PrimaryEnergyCons!$C$4:$C$10000)*1,[1]OUT_PrimaryEnergyCons!D$4:D$10000)} -> 80.538262 | G27: {=SUMPRODUCT(("GSL"=[1]OUT_PrimaryEnergyCons!$C$4:$C$10000)*1,[1]OUT_PrimaryEnergyCons!E$4:E$10000)} -> 74.701289 | H27: {=SUMPRODUCT(("GSL"=[1]OUT_PrimaryEnergyCons!$C$4:$C$10000)*1,[1]OUT_PrimaryEnergyCons!F$4:F$10000)} -> 71.058842 | I27: {=SUMPRODUCT(("GSL"=[1]OUT_PrimaryEnergyCons!$C$4:$C$10000)*1,[1]OUT_PrimaryEnergyCons!G$4:G$10000)} -> 42.843897 | J27: {=SUMPRODUCT(("GSL"=[2]OUT_PrimaryEnergyCons!$C$4:$C$10000)*1,[2]OUT_PrimaryEnergyCons!H$4:H$10000)} -> 26.493193 | K27: {=SUMPRODUCT(("GSL"=[2]OUT_PrimaryEnergyCons!$C$4:$C$10000)*1,[2]OUT_PrimaryEnergyCons!I$4:I$10000)} -> 25.689378 | L27: {=SUMPRODUCT(("GSL"=[2]OUT_PrimaryEnergyCons!$C$4:$C$10000)*1,[2]OUT_PrimaryEnergyCons!J$4:J$10000)} -> 20.761591
A28: =A27 -> STEM | B28: =B27 -> SPS1 | C28: =C27 -> CH | D28: Imports|Oil|Fossil liquids|Kerosene (excl. international aviation) | E28: PJ/yr. | F28: {=SUMPRODUCT(("KER"=[1]OUT_PrimaryEnergyCons!$C$4:$C$10000)*1,[1]OUT_PrimaryEnergyCons!D$4:D$10000)} -> 1.1089892 | G28: {=SUMPRODUCT(("KER"=[1]OUT_PrimaryEnergyCons!$C$4:$C$10000)*1,[1]OUT_PrimaryEnergyCons!E$4:E$10000)} -> 1.4052036 | H28: {=SUMPRODUCT(("KER"=[1]OUT_PrimaryEnergyCons!$C$4:$C$10000)*1,[1]OUT_PrimaryEnergyCons!F$4:F$10000)} -> 1.8484572 | I28: {=SUMPRODUCT(("KER"=[1]OUT_PrimaryEnergyCons!$C$4:$C$10000)*1,[1]OUT_PrimaryEnergyCons!G$4:G$10000)} -> 2.5718156 | J28: {=SUMPRODUCT(("KER"=[2]OUT_PrimaryEnergyCons!$C$4:$C$10000)*1,[2]OUT_PrimaryEnergyCons!H$4:H$10000)} -> 1.6315113 | K28: {=SUMPRODUCT(("KER"=[2]OUT_PrimaryEnergyCons!$C$4:$C$10000)*1,[2]OUT_PrimaryEnergyCons!I$4:I$10000)} -> 1.0768995 | L28: {=SUMPRODUCT(("KER"=[2]OUT_PrimaryEnergyCons!$C$4:$C$10000)*1,[2]OUT_PrimaryEnergyCons!J$4:J$10000)} -> 0.58030082
A29: =A50 -> STEM | B29: =B50 -> SPS1 | C29: =C50 -> CH | D29: Imports|Oil|Synthetic liquids | E29: PJ/yr. | F29: =SUM(F30:F32) -> 6.8051209 | G29: =SUM(G30:G32) -> 6.7039972 | H29: =SUM(H30:H32) -> 7.1808633 | I29: =SUM(I30:I32) -> 11.705047 | J29: =SUM(J30:J32) -> 10.868087 | K29: =SUM(K30:K32) -> 10.820928 | L29: =SUM(L30:L32) -> 10.535229
A30: =A37 -> STEM | B30: =B37 -> SPS1 | C30: =C37 -> CH | D30: Imports|Oil|Synthetic liquids|Total|Motor diesel | E30: PJ/yr. | F30: {=SUMPRODUCT(ISNUMBER(SEARCH("IMPBDS",[1]OUT_SyntheticFuels!$C$4:$C$1000))*1,("Var_Fout"=[1]OUT_SyntheticFuels!$B$4:$B$1000)*1,[1]OUT_SyntheticFuels!E$4:E$1000)-F32} -> 2.3705794 | G30: {=SUMPRODUCT(ISNUMBER(SEARCH("IMPBDS",[1]OUT_SyntheticFuels!$C$4:$C$1000))*1,("Var_Fout"=[1]OUT_SyntheticFuels!$B$4:$B$1000)*1,[1]OUT_SyntheticFuels!F$4:F$1000)-G32} -> 2.3780006 | H30: {=SUMPRODUCT(ISNUMBER(SEARCH("IMPBDS",[1]OUT_SyntheticFuels!$C$4:$C$1000))*1,("Var_Fout"=[1]OUT_SyntheticFuels!$B$4:$B$1000)*1,[1]OUT_SyntheticFuels!G$4:G$1000)-H32} -> 3.2951817 | I30: {=SUMPRODUCT(ISNUMBER(SEARCH("IMPBDS",[1]OUT_SyntheticFuels!$C$4:$C$1000))*1,("Var_Fout"=[1]OUT_SyntheticFuels!$B$4:$B$1000)*1,[1]OUT_SyntheticFuels!H$4:H$1000)-I32} -> 4.1472494 | J30: {=SUMPRODUCT(ISNUMBER(SEARCH("IMPBDS",[2]OUT_SyntheticFuels!$C$4:$C$1000))*1,("Var_Fout"=[2]OUT_SyntheticFuels!$B$4:$B$1000)*1,[2]OUT_SyntheticFuels!I$4:I$1000)-J32} -> 3.3630015 | K30: {=SUMPRODUCT(ISNUMBER(SEARCH("IMPBDS",[2]OUT_SyntheticFuels!$C$4:$C$1000))*1,("Var_Fout"=[2]OUT_SyntheticFuels!$B$4:$B$1000)*1,[2]OUT_SyntheticFuels!J$4:J$1000)-K32} -> 3.2462452 | L30: {=SUMPRODUCT(ISNUMBER(SEARCH("IMPBDS",[2]OUT_SyntheticFuels!$C$4:$C$1000))*1,("Var_Fout"=[2]OUT_SyntheticFuels!$B$4:$B$1000)*1,[2]OUT_SyntheticFuels!K$4:K$1000)-L32} -> 3.1864925
A31: =A30 -> STEM | B31: =B30 -> SPS1 | C31: =C30 -> CH | D31: Imports|Oil|Synthetic liquids|Total|Motor Gasoline | E31: PJ/yr. | F31: {=SUMPRODUCT(ISNUMBER(SEARCH("IMPeth",[1]OUT_SyntheticFuels!$C$4:$C$1000))*1,("Var_Fout"=[1]OUT_SyntheticFuels!$B$4:$B$1000)*1,[1]OUT_SyntheticFuels!E$4:E$1000)} -> 4.4341506 | G31: {=SUMPRODUCT(ISNUMBER(SEARCH("IMPeth",[1]OUT_SyntheticFuels!$C$4:$C$1000))*1,("Var_Fout"=[1]OUT_SyntheticFuels!$B$4:$B$1000)*1,[1]OUT_SyntheticFuels!F$4:F$1000)} -> 4.3259844 | H31: {=SUMPRODUCT(ISNUMBER(SEARCH("IMPeth",[1]OUT_SyntheticFuels!$C$4:$C$1000))*1,("Var_Fout"=[1]OUT_SyntheticFuels!$B$4:$B$1000)*1,[1]OUT_SyntheticFuels!G$4:G$1000)} -> 3.8851869 | I31: {=SUMPRODUCT(ISNUMBER(SEARCH("IMPeth",[1]OUT_SyntheticFuels!$C$4:$C$1000))*1,("Var_Fout"=[1]OUT_SyntheticFuels!$B$4:$B$1000)*1,[1]OUT_SyntheticFuels!H$4:H$1000)} -> 2.4820304 | J31: {=SUMPRODUCT(ISNUMBER(SEARCH("IMPeth",[2]OUT_SyntheticFuels!$C$4:$C$1000))*1,("Var_Fout"=[2]OUT_SyntheticFuels!$B$4:$B$1000)*1,[2]OUT_SyntheticFuels!I$4:I$1000)} -> 1.5351869 | K31: {=SUMPRODUCT(ISNUMBER(SEARCH("IMPeth",[2]OUT_SyntheticFuels!$C$4:$C$1000))*1,("Var_Fout"=[2]OUT_SyntheticFuels!$B$4:$B$1000)*1,[2]OUT_SyntheticFuels!J$4:J$1000)} -> 1.4881818 | L31: {=SUMPRODUCT(ISNUMBER(SEARCH("IMPeth",[2]OUT_SyntheticFuels!$C$4:$C$1000))*1,("Var_Fout"=[2]OUT_SyntheticFuels!$B$4:$B$1000)*1,[2]OUT_SyntheticFuels!K$4:K$1000)} -> 1.2027939
B32: =B31 -> SPS1 | C32: =C31 -> CH | D32: Imports|Oil|Synthetic liquids|Total|Kerosene | E32: PJ/yr. | F32: =SUM([1]Transport_Aviation_Intl!B$12,[1]Transport!B$28) -> 0.00039081036 | G32: =SUM([1]Transport_Aviation_Intl!C$12,[1]Transport!C$28) -> 1.2177234e-05 | H32: =SUM([1]Transport_Aviation_Intl!D$12,[1]Transport!D$28) -> 0.00049472061 | I32: =SUM([1]Transport_Aviation_Intl!E$12,[1]Transport!E$28) -> 5.0757674 | J32: =SUM([2]Transport_Aviation_Intl!F$12,[2]Transport!F$28) -> 5.9698984 | K32: =SUM([2]Transport_Aviation_Intl!G$12,[2]Transport!G$28) -> 6.0865013 | L32: =SUM([2]Transport_Aviation_Intl!H$12,[2]Transport!H$28) -> 6.1459427
A33: =A29 -> STEM | B33: =B29 -> SPS1 | C33: =C29 -> CH | D33: Imports|Oil|Synthetic liquids|Bioliquids|Total | E33: PJ/yr. | F33: =SUM(F34:F36) -> 6.8051209 | G33: =SUM(G34:G36) -> 6.7039972 | H33: =SUM(H34:H36) -> 7.1808633 | I33: =SUM(I34:I36) -> 11.705047 | J33: =SUM(J34:J36) -> 9.9739558 | K33: =SUM(K34:K36) -> 10.704325 | L33: =SUM(L34:L36) -> 10.475788
A34: =A31 -> STEM | B34: =B31 -> SPS1 | C34: =C31 -> CH | D34: Imports|Oil|Synthetic liquids|Bioliquids|Biodiesel | E34: PJ/yr. | F34: =F30 -> 2.3705794 | G34: =G30 -> 2.3780006 | H34: =H30 -> 3.2951817 | I34: =I30 -> 4.1472494 | J34: =IF(J30-MAX(F30:I30)<0,J30,MAX(F30:I30)) -> 3.3630015 | K34: =IF(K30-MAX(F30:J30)<0,K30,MAX(F30:J30)) -> 3.2462452 | L34: =IF(L30-MAX(G30:K30)<0,L30,MAX(G30:K30)) -> 3.1864925
A35: =A34 -> STEM | B35: =B34 -> SPS1 | C35: =C34 -> CH | D35: Imports|Oil|Synthetic liquids|Bioliquids|Ethanol | E35: PJ/yr. | F35: =F31 -> 4.4341506 | G35: =G31 -> 4.3259844 | H35: =H31 -> 3.8851869 | I35: =I31 -> 2.4820304 | J35: =IF(J31-MAX(F31:I31)<0,J31,MAX(F31:I31)) -> 1.5351869 | K35: =IF(K31-MAX(F31:J31)<0,K31,MAX(F31:J31)) -> 1.4881818 | L35: =IF(L31-MAX(G31:K31)<0,L31,MAX(G31:K31)) -> 1.2027939
B36: =B35 -> SPS1 | C36: =C35 -> CH | D36: Imports|Oil|Synthetic liquids|Bioliquids|Biokerosene | E36: PJ/yr. | F36: =SUM([1]Transport!B$28,[1]Transport_Aviation_Intl!B$12) -> 0.00039081036 | G36: =SUM([1]Transport!C$28,[1]Transport_Aviation_Intl!C$12) -> 1.2177234e-05 | H36: =SUM([1]Transport!D$28,[1]Transport_Aviation_Intl!D$12) -> 0.00049472061 | I36: =SUM([1]Transport!E$28,[1]Transport_Aviation_Intl!E$12) -> 5.0757674 | J36: =IF(J32-MAX(F32:I32)<0,J32,MAX(F32:I32)) -> 5.0757674 | K36: =IF(K32-MAX(G32:J32)<0,K32,MAX(G32:J32)) -> 5.9698984 | L36: =IF(L32-MAX(H32:K32)<0,L32,MAX(H32:K32)) -> 6.0865013
A37: =A33 -> STEM | B37: =B33 -> SPS1 | C37: =C33 -> CH | D37: Imports|Oil|Synthetic liquids|PtL|Total | E37: PJ/yr. | F37: =SUM(F38:F40) -> 0 | G37: =SUM(G38:G40) -> 0 | H37: =SUM(H38:H40) -> 0 | I37: =SUM(I38:I40) -> 0 | J37: =SUM(J38:J40) -> 0.89413093 | K37: =SUM(K38:K40) -> 0.11660291 | L37: =SUM(L38:L40) -> 0.059441406
A38: =A35 -> STEM | B38: =B35 -> SPS1 | C38: =C35 -> CH | D38: Imports|Oil|Synthetic liquids|PtL|PtL Diesel | E38: PJ/yr. | F38: 0 | G38: 0 | H38: 0 | I38: 0 | J38: =J30-J34 -> 0 | K38: =K30-K34 -> 0 | L38: =L30-L34 -> 0
A39: =A38 -> STEM | B39: =B38 -> SPS1 | C39: =C38 -> CH | D39: Imports|Oil|Synthetic liquids|PtL|PtL Gasoline | E39: PJ/yr. | F39: 0 | G39: 0 | H39: 0 | I39: 0 | J39: =J31-J35 -> 0 | K39: =K31-K35 -> 0 | L39: =L31-L35 -> 0
B40: =B39 -> SPS1 | C40: =C39 -> CH | D40: Imports|Oil|Synthetic liquids|PtL|PtL Kerosene | E40: PJ/yr. | F40: 0 | G40: 0 | H40: 0 | I40: 0 | J40: =J32-J36 -> 0.89413093 | K40: =K32-K36 -> 0.11660291 | L40: =L32-L36 -> 0.059441406
...

Sheet check
C2: 2020 | D2: 2022 | E2: 2025 | F2: 2030 | G2: 2040 | H2: 2050
B3: Final energy consumption | C3: =SUM(C4:C7) -> 715.97461 | D3: =SUM(D4:D7) -> 703.8406 | E3: =SUM(E4:E7) -> 691.24611 | F3: =SUM(F4:F7) -> 637.80902 | G3: =SUM(G4:G7) -> 602.69524 | H3: =SUM(H4:H7) -> 590.19652
B4: Industry | C4: =SPS4_FIN_Low!F763 -> 142.21742 | D4: =SPS4_FIN_Low!G763 -> 142.7224 | E4: =SPS4_FIN_Low!H763 -> 148.56509 | F4: =SPS4_FIN_Low!I763 -> 149.71092 | G4: =SPS4_FIN_Low!J763 -> 150.27297 | H4: =SPS4_FIN_Low!K763 -> 147.8005
B5: Services | C5: =SPS4_FIN_Low!F882 -> 140.10109 | D5: =SPS4_FIN_Low!G882 -> 139.66588 | E5: =SPS4_FIN_Low!H882 -> 133.51313 | F5: =SPS4_FIN_Low!I882 -> 128.68312 | G5: =SPS4_FIN_Low!J882 -> 125.46328 | H5: =SPS4_FIN_Low!K882 -> 121.64193
B6: Residential | C6: =SPS4_FIN_Low!F972 -> 219.91228 | D6: =SPS4_FIN_Low!G972 -> 216.99271 | E6: =SPS4_FIN_Low!H972 -> 220.35317 | F6: =SPS4_FIN_Low!I972 -> 211.18259 | G6: =SPS4_FIN_Low!J972 -> 205.25164 | H6: =SPS4_FIN_Low!K972 -> 200.14574
B7: Transport | C7: =SPS4_FIN_Low!F1136+SPS4_FIN_Low!F1315+SPS4_FIN_Low!F1399+SPS4_FIN_Low!F1483+SPS4_FIN_Low!F1490+SPS4_FIN_Low!F1497+SPS4_FIN_Low!F1546+SPS4_FIN_Low!F1593+SPS4_FIN_Low!F1640 -> 213.74382 | D7: =SPS4_FIN_Low!G1136+SPS4_FIN_Low!G1315+SPS4_FIN_Low!G1399+SPS4_FIN_Low!G1483+SPS4_FIN_Low!G1490+SPS4_FIN_Low!G1497+SPS4_FIN_Low!G1546+SPS4_FIN_Low!G1593+SPS4_FIN_Low!G1640 -> 204.45961 | E7: =SPS4_FIN_Low!H1136+SPS4_FIN_Low!H1315+SPS4_FIN_Low!H1399+SPS4_FIN_Low!H1483+SPS4_FIN_Low!H1490+SPS4_FIN_Low!H1497+SPS4_FIN_Low!H1546+SPS4_FIN_Low!H1593+SPS4_FIN_Low!H1640 -> 188.81471 | F7: =SPS4_FIN_Low!I1136+SPS4_FIN_Low!I1315+SPS4_FIN_Low!I1399+SPS4_FIN_Low!I1483+SPS4_FIN_Low!I1490+SPS4_FIN_Low!I1497+SPS4_FIN_Low!I1546+SPS4_FIN_Low!I1593+SPS4_FIN_Low!I1640 -> 148.23239 | G7: =SPS4_FIN_Low!J1136+SPS4_FIN_Low!J1315+SPS4_FIN_Low!J1399+SPS4_FIN_Low!J1483+SPS4_FIN_Low!J1490+SPS4_FIN_Low!J1497+SPS4_FIN_Low!J1546+SPS4_FIN_Low!J1593+SPS4_FIN_Low!J1640 -> 121.70735 | H7: =SPS4_FIN_Low!K1136+SPS4_FIN_Low!K1315+SPS4_FIN_Low!K1399+SPS4_FIN_Low!K1483+SPS4_FIN_Low!K1490+SPS4_FIN_Low!K1497+SPS4_FIN_Low!K1546+SPS4_FIN_Low!K1593+SPS4_FIN_Low!K1640 -> 120.60835
B8: Fuel input to energy conversion and DAC | C8: =SUM(C9:C12) -> 509.61966 | D8: =SUM(D9:D12) -> 499.19819 | E8: =SUM(E9:E12) -> 508.42264 | F8: =SUM(F9:F12) -> 512.31182 | G8: =SUM(G9:G12) -> 487.05318 | H8: =SUM(H9:H12) -> 439.33026
B9: Electricity and heat | C9: =SPS4_FIN_Low!F291+SPS4_FIN_Low!F409 -> 493.39818 | D9: =SPS4_FIN_Low!G291+SPS4_FIN_Low!G409 -> 474.49247 | E9: =SPS4_FIN_Low!H291+SPS4_FIN_Low!H409 -> 481.1407 | F9: =SPS4_FIN_Low!I291+SPS4_FIN_Low!I409 -> 489.07484 | G9: =SPS4_FIN_Low!J291+SPS4_FIN_Low!J409 -> 463.82525 | H9: =SPS4_FIN_Low!K291+SPS4_FIN_Low!K409 -> 416.27729
B10: Biofuel production | C10: =SPS4_FIN_Low!F590+SPS4_FIN_Low!F604+SPS4_FIN_Low!F644 -> 16.217753 | D10: =SPS4_FIN_Low!G590+SPS4_FIN_Low!G604+SPS4_FIN_Low!G644 -> 24.701967 | E10: =SPS4_FIN_Low!H590+SPS4_FIN_Low!H604+SPS4_FIN_Low!H644 -> 27.278265 | F10: =SPS4_FIN_Low!I590+SPS4_FIN_Low!I604+SPS4_FIN_Low!I644 -> 23.233424 | G10: =SPS4_FIN_Low!J590+SPS4_FIN_Low!J604+SPS4_FIN_Low!J644 -> 23.213027 | H10: =SPS4_FIN_Low!K590+SPS4_FIN_Low!K604+SPS4_FIN_Low!K644 -> 23.037732
B11: Hydrogen production | C11: =SPS4_FIN_Low!F679 -> 0.0037283021 | D11: =SPS4_FIN_Low!G679 -> 0.0037478591 | E11: =SPS4_FIN_Low!H679 -> 0.0036757241 | F11: =SPS4_FIN_Low!I679 -> 0.0035620016 | G11: =SPS4_FIN_Low!J679 -> 0.014910033 | H11: =SPS4_FIN_Low!K679 -> 0.015237459
B12: DAC | C12: =SPS4_FIN_Low!F1707 -> 0 | D12: =SPS4_FIN_Low!G1707 -> 0 | E12: =SPS4_FIN_Low!H1707 -> 0 | F12: =SPS4_FIN_Low!I1707 -> 0 | G12: =SPS4_FIN_Low!J1707 -> 0 | H12: =SPS4_FIN_Low!K1707 -> 0
B13: Total Primary energy consumption | C13: =SPS4_FIN_Low!F2+SPS4_FIN_Low!F20-SPS4_FIN_Low!F57 -> 962.31272 | D13: =SPS4_FIN_Low!G2+SPS4_FIN_Low!G20-SPS4_FIN_Low!G57 -> 960.67929 | E13: =SPS4_FIN_Low!H2+SPS4_FIN_Low!H20-SPS4_FIN_Low!H57 -> 913.07082 | F13: =SPS4_FIN_Low!I2+SPS4_FIN_Low!I20-SPS4_FIN_Low!I57 -> 864.17176 | G13: =SPS4_FIN_Low!J2+SPS4_FIN_Low!J20-SPS4_FIN_Low!J57 -> 806.50848 | H13: =SPS4_FIN_Low!K2+SPS4_FIN_Low!K20-SPS4_FIN_Low!K57 -> 753.4916
B14: Domestic production | C14: =SPS4_FIN_Low!F2 -> 300.18603 | D14: =SPS4_FIN_Low!G2 -> 295.45269 | E14: =SPS4_FIN_Low!H2 -> 329.78473 | F14: =SPS4_FIN_Low!I2 -> 369.92536 | G14: =SPS4_FIN_Low!J2 -> 383.51029 | H14: =SPS4_FIN_Low!K2 -> 402.42419
B15: Imports | C15: =SPS4_FIN_Low!F20 -> 779.2967 | D15: =SPS4_FIN_Low!G20 -> 700.84944 | E15: =SPS4_FIN_Low!H20 -> 657.91151 | F15: =SPS4_FIN_Low!I20 -> 553.03123 | G15: =SPS4_FIN_Low!J20 -> 467.07405 | H15: =SPS4_FIN_Low!K20 -> 370.78838
B16: Exports | C16: =SPS4_FIN_Low!F57 -> 117.17001 | D16: =SPS4_FIN_Low!G57 -> 35.622834 | E16: =SPS4_FIN_Low!H57 -> 74.625428 | F16: =SPS4_FIN_Low!I57 -> 58.784829 | G16: =SPS4_FIN_Low!J57 -> 44.075852 | H16: =SPS4_FIN_Low!K57 -> 19.720964
