Workbook

Sheet Variable_List
B2: Variable | C2: Description | D2: Unit | E2: Comment
B3: Primary Production | C3: Domestic primary production of resources | D3: PJ/yr.
B4: Imports | C4: Imports of energy carriers | D4: PJ/yr.
B5: Exports | C5: Exports of energy carriers | D5: PJ/yr.
B6: Electricity generation | C6: Domestic electricity generation | D6: PJ/yr.
B7: Heat generation from CHPs and heat plants | C7: Domestic heat production from CHPs (District heating CHPs or onsite CHPs) and heat plants | D7: PJ/yr.
B8: Fuel input for electricity generation | C8: Fuel input allocated to domestic electricity generation only | D8: PJ/yr.
B9: Fuel input for heat generation from CHPs and heat plants | C9: Fuel input allocated to domestic heat production from CHPs and heat plants only | D9: PJ/yr.
B10: Efficiency of power plants (electric) | C10: Average annual efficiency of power plants and CHPs for electricity production only | D10: % | E10: The thermal efficiency of CHPs can be inferred from the Heat to Electricity production ratio, but it can also be provided; the average efficiency differs from the technical efficiency as it includes efficiency losses due to part load operation
B11: Efficiency of heat plants (thermal) | C11: Average annual efficiency of heat plants | D11: % | E11: It is the annual marketed efficiency including part load efficiency losses and differs from the full load nominal technical efficiency; for heat pumps refers to COP
B12: Domestic biodiesel production | C12: Domestic production of biodiesel | D12: PJ/yr.
B13: Heat from domestic biodiesel production | C13: Heat produced as byproduct from biodiesel production and fed into the district heating network | D13: PJ/yr.
B14: Fuel input for domestic biodiesel production | C14: Fuel input for the domestic production of biodiesel | D14: PJ/yr.
B15: Efficiency for domestic biodiesel production | C15: Average annual efficiency for biodiesel and heat production | D15: %
B16: Domestic ethanol production | C16: Domestic production of ethanol | D16: PJ/yr.
B17: Fuel input for domestic ethanol production | C17: Fuel input for the domestic production of ethanol | D17: PJ/yr.
B18: Efficiency for domestic ethanol production | C18: Average annual efficiency for domestic production of ethanol | D18: %
B19: Domestic biogas production | C19: Domestic production of biogas and biogenic syngas | D19: PJ/yr.
B20: Electricity from domestic biogas production | C20: Electriicty produced as byproduct from biogas production and fed into the grid | D20: PJ/yr.
B21: Heat from domestic biogas production | C21: Heat produced as byproduct from biogas production and fed into the district heating network | D21: PJ/yr.
B22: Fuel input for domestic biogas production | C22: Fuel input for domestic biogas production | D22: PJ/yr.
B23: Efficiency for domestic biogas production | C23: Average annual efficiency for biogas production (accounting for byproduct production) | D23: %
... B25: Fuel input for hydrogen production | C25: Fuel input for deomstic hydrogen production | D25: PJ/yr.
B26: Efficiency for hydrogen production | C26: Average annual efficiency for hydrogen production | D26: % | E26: Including losses due to part load operation
B27: Biomethane production from biogas upgrade | C27: Production of domestic biomethane from biogas | D27: PJ/yr. | E27: One technology only fuel output is biomethane
B28: Fuel input for biogas upgrade to biomethane | C28: Use of biogas for upgrade to biomethane | D28: PJ/yr. | E28: One technology only fuel input is biogas
B29: Efficiency for biomethane production from biogas upgrade | C29: Average annual efficiency of biogas to biomethane upgrade | D29: PJ/yr. | E29: One technology only fuel input is biogas, fuel output is biomethane
B30: Domestic PtG and PtL production | C30: Domestic production of power-to-gas and power-to-liquids | D30: PJ/yr.
B31: Fuel input for domestic PtG and PtL production | C31: Fuel used for domestic PtG and PtL production (excl. CO2) | D31: PJ/yr.
B32: Efficiency for domestic PtG and PtL production | C32: Average annual efficiency for PtG and PtL processes (excl. CO2 consumption) | D32: %
B33: CO2 input for domestic PtG and PtL production | C33: CO2 input for domestic PtG and PtL production | D33: Mt/yr. | E33: The distinction of the source of CO2 (biogenic or fossil) is also provided and can be proportionally allocated to the technologies for PtG and PtL
B34: Domestic wood to pellet production | C34: Wood conversion to pellet domestic production output | D34: PJ/yr. | E34: One technology only , input is wood output is pellet
B35: Fuel input for wood to pellet production | C35: Wood conversion to pellet domestic production - input wood required | D35: PJ/yr. | E35: One technology only , input is wood output is pellet
B36: Efficiency for wood to pellet production | C36: Average annual efficiency of wood to pellet conversion | D36: %
B37: Fuel consumption in industry sectors | C37: Fuel consumption in industry by fuel and technology | D37: PJ/yr. | E37: This unfortunately it will change when the new industrial sectors will be integrated into STEM
B38: Process and space heating production in industry sectors | C38: Energy service demand provided in the form of process and space heating in industry | D38: PJ/yr. | E38: This unfortunately it will change when the new industrial sectors will be integrated into STEM
B39: Efficiency in industry sectors | C39: Boilers efficiency and COP of heat pumps in the industrial sectors | D39: % | E39: This unfortunately it will change when the new industrial sectors will be integrated into STEM
B40: Fuel consumption in Services sectors | C40: Fuel consumption in services sectors by fuel and technology | D40: PJ/yr.
B41: Space water and process heat production in Services sectors | C41: Production of energy service demand for space, water and process heat in Services sectors | D41: PJ/yr.
B42: Efficiency in Services sectors | C42: Boilers efficiency and COP of heat pumps in the Services sectors | D42: %
...

Sheet SPS2_NUC_Mid
A1: Model | B1: Scenario | C1: Region | D1: Variable | E1: Unit | F1: 2020 | G1: 2022 | H1: 2025 | I1: 2030 | J1: 2035 | K1: 2040 | L1: 2050
A2: STEM | B2: SPS1 | C2: CH | D2: Primary Production | E2: PJ/yr. | F2: =F3+F8+F11+F12+F16+F17+F18+F19 -> 301.55157 | G2: =G3+G8+G11+G12+G16+G17+G18+G19 -> 298.76898 | H2: =H3+H8+H11+H12+H16+H17+H18+H19 -> 338.20473 | I2: =I3+I8+I11+I12+I16+I17+I18+I19 -> 444.85986 | J2: =J3+J8+J11+J12+J16+J17+J18+J19 -> 418.94116 | K2: =K3+K8+K11+K12+K16+K17+K18+K19 -> 512.14577 | L2: =L3+L8+L11+L12+L16+L17+L18+L19 -> 550.1052
A3: =A2 -> STEM | B3: =B2 -> SPS1 | C3: =C2 -> CH | D3: Primary Production|Wood | E3: PJ/yr. | F3: =SUM(F4:F7) -> 46.334115 | G3: =SUM(G4:G7) -> 50.490588 | H3: =SUM(H4:H7) -> 53.544917 | I3: =SUM(I4:I7) -> 53.546452 | J3: =SUM(J4:J7) -> 53.589483 | K3: =SUM(K4:K7) -> 53.589502 | L3: =SUM(L4:L7) -> 53.589509
A4: =A3 -> STEM | B4: =B3 -> SPS1 | C4: =C3 -> CH | D4: Primary Production|Wood|Waste wood | E4: PJ/yr. | F4: {=SUMPRODUCT(("RNWWOD1"=[1]OUT_PrimaryEnergyCons!$A$1:$A$1000)*1,[1]OUT_PrimaryEnergyCons!D$1:D$1000)} -> 11.111976 | G4: {=SUMPRODUCT(("RNWWOD1"=[1]OUT_PrimaryEnergyCons!$A$1:$A$1000)*1,[1]OUT_PrimaryEnergyCons!E$1:E$1000)} -> 11.952924 | H4: {=SUMPRODUCT(("RNWWOD1"=[1]OUT_PrimaryEnergyCons!$A$1:$A$1000)*1,[1]OUT_PrimaryEnergyCons!F$1:F$1000)} -> 13.357213 | I4: {=SUMPRODUCT(("RNWWOD1"=[1]OUT_PrimaryEnergyCons!$A$1:$A$1000)*1,[1]OUT_PrimaryEnergyCons!G$1:G$1000)} -> 15.656187 | J4: {=SUMPRODUCT(("RNWWOD1"=[2]OUT_PrimaryEnergyCons!$A$1:$A$1000)*1,[2]OUT_PrimaryEnergyCons!H$1:H$1000)} -> 16.42457 | K4: {=SUMPRODUCT(("RNWWOD1"=[2]OUT_PrimaryEnergyCons!$A$1:$A$1000)*1,[2]OUT_PrimaryEnergyCons!I$1:I$1000)} -> 17.113643 | L4: {=SUMPRODUCT(("RNWWOD1"=[2]OUT_PrimaryEnergyCons!$A$1:$A$1000)*1,[2]OUT_PrimaryEnergyCons!J$1:J$1000)} -> 18.429672
A5: =A4 -> STEM | B5: =B4 -> SPS1 | C5: =C4 -> CH | D5: Primary Production|Wood|Wood residues | E5: PJ/yr. | F5: {=SUMPRODUCT(("RNWWOD2"=[1]OUT_PrimaryEnergyCons!$A$1:$A$1000)*1,[1]OUT_PrimaryEnergyCons!D$1:D$1000)} -> 7.5117708 | G5: {=SUMPRODUCT(("RNWWOD2"=[1]OUT_PrimaryEnergyCons!$A$1:$A$1000)*1,[1]OUT_PrimaryEnergyCons!E$1:E$1000)} -> 7.5431833 | H5: {=SUMPRODUCT(("RNWWOD2"=[1]OUT_PrimaryEnergyCons!$A$1:$A$1000)*1,[1]OUT_PrimaryEnergyCons!F$1:F$1000)} -> 7.5903685 | I5: {=SUMPRODUCT(("RNWWOD2"=[1]OUT_PrimaryEnergyCons!$A$1:$A$1000)*1,[1]OUT_PrimaryEnergyCons!G$1:G$1000)} -> 7.6690331 | J5: {=SUMPRODUCT(("RNWWOD2"=[2]OUT_PrimaryEnergyCons!$A$1:$A$1000)*1,[2]OUT_PrimaryEnergyCons!H$1:H$1000)} -> 7.6690269 | K5: {=SUMPRODUCT(("RNWWOD2"=[2]OUT_PrimaryEnergyCons!$A$1:$A$1000)*1,[2]OUT_PrimaryEnergyCons!I$1:I$1000)} -> 7.6690272 | L5: {=SUMPRODUCT(("RNWWOD2"=[2]OUT_PrimaryEnergyCons!$A$1:$A$1000)*1,[2]OUT_PrimaryEnergyCons!J$1:J$1000)} -> 7.6690281
A6: =A5 -> STEM | B6: =B5 -> SPS1 | C6: =C5 -> CH | D6: Primary Production|Wood|Wood from landscape maintenance | E6: PJ/yr. | F6: {=SUMPRODUCT(("RNWWOD3"=[1]OUT_PrimaryEnergyCons!$A$1:$A$1000)*1,[1]OUT_PrimaryEnergyCons!D$1:D$1000)} -> 3.1683464 | G6: {=SUMPRODUCT(("RNWWOD3"=[1]OUT_PrimaryEnergyCons!$A$1:$A$1000)*1,[1]OUT_PrimaryEnergyCons!E$1:E$1000)} -> 3.4957145 | H6: {=SUMPRODUCT(("RNWWOD3"=[1]OUT_PrimaryEnergyCons!$A$1:$A$1000)*1,[1]OUT_PrimaryEnergyCons!F$1:F$1000)} -> 3.9868298 | I6: {=SUMPRODUCT(("RNWWOD3"=[1]OUT_PrimaryEnergyCons!$A$1:$A$1000)*1,[1]OUT_PrimaryEnergyCons!G$1:G$1000)} -> 4.8053895 | J6: {=SUMPRODUCT(("RNWWOD3"=[2]OUT_PrimaryEnergyCons!$A$1:$A$1000)*1,[2]OUT_PrimaryEnergyCons!H$1:H$1000)} -> 4.8053858 | K6: {=SUMPRODUCT(("RNWWOD3"=[2]OUT_PrimaryEnergyCons!$A$1:$A$1000)*1,[2]OUT_PrimaryEnergyCons!I$1:I$1000)} -> 4.805386 | L6: {=SUMPRODUCT(("RNWWOD3"=[2]OUT_PrimaryEnergyCons!$A$1:$A$1000)*1,[2]OUT_PrimaryEnergyCons!J$1:J$1000)} -> 4.8053858
A7: =A6 -> STEM | B7: =B6 -> SPS1 | C7: =C6 -> CH | D7: Primary Production|Wood|Wood from Forest (hard wood) | E7: PJ/yr. | F7: {=SUMPRODUCT(("RNWWOD4"=[1]OUT_PrimaryEnergyCons!$A$1:$A$1000)*1+("RNWWOD5"=[1]OUT_PrimaryEnergyCons!$A$1:$A$1000)*1,[1]OUT_PrimaryEnergyCons!D$1:D$1000)} -> 24.542022 | G7: {=SUMPRODUCT(("RNWWOD4"=[1]OUT_PrimaryEnergyCons!$A$1:$A$1000)*1+("RNWWOD5"=[1]OUT_PrimaryEnergyCons!$A$1:$A$1000)*1,[1]OUT_PrimaryEnergyCons!E$1:E$1000)} -> 27.498767 | H7: {=SUMPRODUCT(("RNWWOD4"=[1]OUT_PrimaryEnergyCons!$A$1:$A$1000)*1+("RNWWOD5"=[1]OUT_PrimaryEnergyCons!$A$1:$A$1000)*1,[1]OUT_PrimaryEnergyCons!F$1:F$1000)} -> 28.610505 | I7: {=SUMPRODUCT(("RNWWOD4"=[1]OUT_PrimaryEnergyCons!$A$1:$A$1000)*1+("RNWWOD5"=[1]OUT_PrimaryEnergyCons!$A$1:$A$1000)*1,[1]OUT_PrimaryEnergyCons!G$1:G$1000)} -> 25.415842 | J7: {=SUMPRODUCT(("RNWWOD4"=[2]OUT_PrimaryEnergyCons!$A$1:$A$1000)*1+("RNWWOD5"=[2]OUT_PrimaryEnergyCons!$A$1:$A$1000)*1,[2]OUT_PrimaryEnergyCons!H$1:H$1000)} -> 24.690501 | K7: {=SUMPRODUCT(("RNWWOD4"=[2]OUT_PrimaryEnergyCons!$A$1:$A$1000)*1+("RNWWOD5"=[2]OUT_PrimaryEnergyCons!$A$1:$A$1000)*1,[2]OUT_PrimaryEnergyCons!I$1:I$1000)} -> 24.001446 | L7: {=SUMPRODUCT(("RNWWOD4"=[2]OUT_PrimaryEnergyCons!$A$1:$A$1000)*1+("RNWWOD5"=[2]OUT_PrimaryEnergyCons!$A$1:$A$1000)*1,[2]OUT_PrimaryEnergyCons!J$1:J$1000)} -> 22.685422
A8: =A7 -> STEM | B8: =B7 -> SPS1 | C8: =C7 -> CH | D8: Primary Production|Waste | E8: PJ/yr. | F8: =SUM(F9:F10) -> 70.032087 | G8: =SUM(G9:G10) -> 71.22429 | H8: =SUM(H9:H10) -> 71.06665 | I8: =SUM(I9:I10) -> 74.271073 | J8: =SUM(J9:J10) -> 72.227045 | K8: =SUM(K9:K10) -> 79.195697 | L8: =SUM(L9:L10) -> 83.827976
A9: =A8 -> STEM | B9: =B8 -> SPS1 | C9: =C8 -> CH | D9: Primary Production|Waste|Non renewable waste | E9: PJ/yr. | F9: {=SUMPRODUCT(("RNNWWST1"=[1]OUT_PrimaryEnergyCons!$A$1:$A$1000)*1,[1]OUT_PrimaryEnergyCons!D$1:D$1000)} -> 35.931416 | G9: {=SUMPRODUCT(("RNNWWST1"=[1]OUT_PrimaryEnergyCons!$A$1:$A$1000)*1,[1]OUT_PrimaryEnergyCons!E$1:E$1000)} -> 36.121601 | H9: {=SUMPRODUCT(("RNNWWST1"=[1]OUT_PrimaryEnergyCons!$A$1:$A$1000)*1,[1]OUT_PrimaryEnergyCons!F$1:F$1000)} -> 35.963639 | I9: {=SUMPRODUCT(("RNNWWST1"=[1]OUT_PrimaryEnergyCons!$A$1:$A$1000)*1,[1]OUT_PrimaryEnergyCons!G$1:G$1000)} -> 37.032766 | J9: {=SUMPRODUCT(("RNNWWST1"=[2]OUT_PrimaryEnergyCons!$A$1:$A$1000)*1,[2]OUT_PrimaryEnergyCons!H$1:H$1000)} -> 34.937591 | K9: {=SUMPRODUCT(("RNNWWST1"=[2]OUT_PrimaryEnergyCons!$A$1:$A$1000)*1,[2]OUT_PrimaryEnergyCons!I$1:I$1000)} -> 38.082489 | L9: {=SUMPRODUCT(("RNNWWST1"=[2]OUT_PrimaryEnergyCons!$A$1:$A$1000)*1,[2]OUT_PrimaryEnergyCons!J$1:J$1000)} -> 39.221629
A10: =A9 -> STEM | B10: =B9 -> SPS1 | C10: =C9 -> CH | D10: Primary Production|Waste|Renewable waste | E10: PJ/yr. | F10: {=SUMPRODUCT(("RNWWST1"=[1]OUT_PrimaryEnergyCons!$A$1:$A$1000)*1,[1]OUT_PrimaryEnergyCons!D$1:D$1000)} -> 34.100671 | G10: {=SUMPRODUCT(("RNWWST1"=[1]OUT_PrimaryEnergyCons!$A$1:$A$1000)*1,[1]OUT_PrimaryEnergyCons!E$1:E$1000)} -> 35.102689 | H10: {=SUMPRODUCT(("RNWWST1"=[1]OUT_PrimaryEnergyCons!$A$1:$A$1000)*1,[1]OUT_PrimaryEnergyCons!F$1:F$1000)} -> 35.103011 | I10: {=SUMPRODUCT(("RNWWST1"=[1]OUT_PrimaryEnergyCons!$A$1:$A$1000)*1,[1]OUT_PrimaryEnergyCons!G$1:G$1000)} -> 37.238307 | J10: {=SUMPRODUCT(("RNWWST1"=[2]OUT_PrimaryEnergyCons!$A$1:$A$1000)*1,[2]OUT_PrimaryEnergyCons!H$1:H$1000)} -> 37.289454 | K10: {=SUMPRODUCT(("RNWWST1"=[2]OUT_PrimaryEnergyCons!$A$1:$A$1000)*1,[2]OUT_PrimaryEnergyCons!I$1:I$1000)} -> 41.113208 | L10: {=SUMPRODUCT(("RNWWST1"=[2]OUT_PrimaryEnergyCons!$A$1:$A$1000)*1,[2]OUT_PrimaryEnergyCons!J$1:J$1000)} -> 44.606347
A11: =A10 -> STEM | B11: =B10 -> SPS1 | C11: =C10 -> CH | D11: Primary Production|Manure | E11: PJ/yr. | F11: {=SUMPRODUCT(("mnr"=[1]OUT_PrimaryEnergyCons!$C$1:$C$1000)*1,[1]OUT_PrimaryEnergyCons!D$1:D$1000)} -> 3.7982919 | G11: {=SUMPRODUCT(("mnr"=[1]OUT_PrimaryEnergyCons!$C$1:$C$1000)*1,[1]OUT_PrimaryEnergyCons!E$1:E$1000)} -> 12.540359 | H11: {=SUMPRODUCT(("mnr"=[1]OUT_PrimaryEnergyCons!$C$1:$C$1000)*1,[1]OUT_PrimaryEnergyCons!F$1:F$1000)} -> 12.540421 | I11: {=SUMPRODUCT(("mnr"=[1]OUT_PrimaryEnergyCons!$C$1:$C$1000)*1,[1]OUT_PrimaryEnergyCons!G$1:G$1000)} -> 12.540431 | J11: {=SUMPRODUCT(("mnr"=[2]OUT_PrimaryEnergyCons!$C$1:$C$1000)*1,[2]OUT_PrimaryEnergyCons!H$1:H$1000)} -> 12.540435 | K11: {=SUMPRODUCT(("mnr"=[2]OUT_PrimaryEnergyCons!$C$1:$C$1000)*1,[2]OUT_PrimaryEnergyCons!I$1:I$1000)} -> 14.634123 | L11: {=SUMPRODUCT(("mnr"=[2]OUT_PrimaryEnergyCons!$C$1:$C$1000)*1,[2]OUT_PrimaryEnergyCons!J$1:J$1000)} -> 14.634137
A12: =A11 -> STEM | B12: =B11 -> SPS1 | C12: =C11 -> CH | D12: Primary Production|Hydro | E12: PJ/yr. | F12: =SUM(F13:F15) -> 149.43061 | G12: =SUM(G13:G15) -> 125.65125 | H12: =SUM(H13:H15) -> 137.72924 | I12: =SUM(I13:I15) -> 191.68915 | J12: =SUM(J13:J15) -> 152.49166 | K12: =SUM(K13:K15) -> 154.88225 | L12: =SUM(L13:L15) -> 158.83687
A13: =A12 -> STEM | B13: =B12 -> SPS1 | C13: =C12 -> CH | D13: Primary Production|Hydro|Large hydro | E13: PJ/yr. | F13: {=SUMPRODUCT(ISNUMBER(SEARCH("EHYD-DAM",[1]OUT_Electricity_CHP!$B$1:$B$10000))*1,([1]OUT_Electricity_CHP!$C$1:$C$10000="Var_Fout")*1,ISNUMBER(SEARCH("ELC",[1]OUT_Electricity_CHP!$D$1:$D$10000))*1,[1]OUT_Electricity_CHP!E$1:E$10000)} -> 66.745682 | G13: {=SUMPRODUCT(ISNUMBER(SEARCH("EHYD-DAM",[1]OUT_Electricity_CHP!$B$1:$B$10000))*1,([1]OUT_Electricity_CHP!$C$1:$C$10000="Var_Fout")*1,ISNUMBER(SEARCH("ELC",[1]OUT_Electricity_CHP!$D$1:$D$10000))*1,[1]OUT_Electricity_CHP!F$1:F$10000)} -> 49.798778 | H13: {=SUMPRODUCT(ISNUMBER(SEARCH("EHYD-DAM",[1]OUT_Electricity_CHP!$B$1:$B$10000))*1,([1]OUT_Electricity_CHP!$C$1:$C$10000="Var_Fout")*1,ISNUMBER(SEARCH("ELC",[1]OUT_Electricity_CHP!$D$1:$D$10000))*1,[1]OUT_Electricity_CHP!G$1:G$10000)} -> 68.970401 | I13: {=SUMPRODUCT(ISNUMBER(SEARCH("EHYD-DAM",[1]OUT_Electricity_CHP!$B$1:$B$10000))*1,([1]OUT_Electricity_CHP!$C$1:$C$10000="Var_Fout")*1,ISNUMBER(SEARCH("ELC",[1]OUT_Electricity_CHP!$D$1:$D$10000))*1,[1]OUT_Electricity_CHP!H$1:H$10000)} -> 70.970232 | J13: {=SUMPRODUCT(ISNUMBER(SEARCH("EHYD-DAM",[2]OUT_Electricity_CHP!$B$1:$B$10000))*1,([2]OUT_Electricity_CHP!$C$1:$C$10000="Var_Fout")*1,ISNUMBER(SEARCH("ELC",[2]OUT_Electricity_CHP!$D$1:$D$10000))*1,[2]OUT_Electricity_CHP!I$1:I$10000)} -> 71.021496 | K13: {=SUMPRODUCT(ISNUMBER(SEARCH("EHYD-DAM",[2]OUT_Electricity_CHP!$B$1:$B$10000))*1,([2]OUT_Electricity_CHP!$C$1:$C$10000="Var_Fout")*1,ISNUMBER(SEARCH("ELC",[2]OUT_Electricity_CHP!$D$1:$D$10000))*1,[2]OUT_Electricity_CHP!J$1:J$10000)} -> 73.932877 | L13: {=SUMPRODUCT(ISNUMBER(SEARCH("EHYD-DAM",[2]OUT_Electricity_CHP!$B$1:$B$10000))*1,([2]OUT_Electricity_CHP!$C$1:$C$10000="Var_Fout")*1,ISNUMBER(SEARCH("ELC",[2]OUT_Electricity_CHP!$D$1:$D$10000))*1,[2]OUT_Electricity_CHP!K$1:K$10000)} -> 74.836059
A14: =A13 -> STEM | B14: =B13 -> SPS1 | C14: =C13 -> CH | D14: Primary Production|Hydro|Run-of-river hydro | E14: PJ/yr. | F14: {=SUMPRODUCT(ISNUMBER(SEARCH("EHYD-RUN",[1]OUT_Electricity_CHP!$B$1:$B$10000))*1,([1]OUT_Electricity_CHP!$C$1:$C$10000="Var_Fout")*1,ISNUMBER(SEARCH("ELC",[1]OUT_Electricity_CHP!$D$1:$D$10000))*1,[1]OUT_Electricity_CHP!E$1:E$10000)} -> 66.632431 | G14: {=SUMPRODUCT(ISNUMBER(SEARCH("EHYD-RUN",[1]OUT_Electricity_CHP!$B$1:$B$10000))*1,([1]OUT_Electricity_CHP!$C$1:$C$10000="Var_Fout")*1,ISNUMBER(SEARCH("ELC",[1]OUT_Electricity_CHP!$D$1:$D$10000))*1,[1]OUT_Electricity_CHP!F$1:F$10000)} -> 55.764056 | H14: {=SUMPRODUCT(ISNUMBER(SEARCH("EHYD-RUN",[1]OUT_Electricity_CHP!$B$1:$B$10000))*1,([1]OUT_Electricity_CHP!$C$1:$C$10000="Var_Fout")*1,ISNUMBER(SEARCH("ELC",[1]OUT_Electricity_CHP!$D$1:$D$10000))*1,[1]OUT_Electricity_CHP!G$1:G$10000)} -> 65.677218 | I14: {=SUMPRODUCT(ISNUMBER(SEARCH("EHYD-RUN",[1]OUT_Electricity_CHP!$B$1:$B$10000))*1,([1]OUT_Electricity_CHP!$C$1:$C$10000="Var_Fout")*1,ISNUMBER(SEARCH("ELC",[1]OUT_Electricity_CHP!$D$1:$D$10000))*1,[1]OUT_Electricity_CHP!H$1:H$10000)} -> 64.85374 | J14: {=SUMPRODUCT(ISNUMBER(SEARCH("EHYD-RUN",[2]OUT_Electricity_CHP!$B$1:$B$10000))*1,([2]OUT_Electricity_CHP!$C$1:$C$10000="Var_Fout")*1,ISNUMBER(SEARCH("ELC",[2]OUT_Electricity_CHP!$D$1:$D$10000))*1,[2]OUT_Electricity_CHP!I$1:I$10000)} -> 65.46491 | K14: {=SUMPRODUCT(ISNUMBER(SEARCH("EHYD-RUN",[2]OUT_Electricity_CHP!$B$1:$B$10000))*1,([2]OUT_Electricity_CHP!$C$1:$C$10000="Var_Fout")*1,ISNUMBER(SEARCH("ELC",[2]OUT_Electricity_CHP!$D$1:$D$10000))*1,[2]OUT_Electricity_CHP!J$1:J$10000)} -> 64.381743 | L14: {=SUMPRODUCT(ISNUMBER(SEARCH("EHYD-RUN",[2]OUT_Electricity_CHP!$B$1:$B$10000))*1,([2]OUT_Electricity_CHP!$C$1:$C$10000="Var_Fout")*1,ISNUMBER(SEARCH("ELC",[2]OUT_Electricity_CHP!$D$1:$D$10000))*1,[2]OUT_Electricity_CHP!K$1:K$10000)} -> 67.134923
A15: =A14 -> STEM | B15: =B14 -> SPS1 | C15: =C14 -> CH | D15: Primary Production|Hydro|Pump storage | E15: PJ/yr. | F15: {=SUMPRODUCT(ISNUMBER(SEARCH("EHYD-PUM",[1]OUT_Electricity_CHP!$B$1:$B$10000))*1,([1]OUT_Electricity_CHP!$C$1:$C$10000="Var_Fin")*1,ISNUMBER(SEARCH("elc",[1]OUT_Electricity_CHP!$D$1:$D$10000))*1,[1]OUT_Electricity_CHP!E$1:E$10000)} -> 16.052497 | G15: {=SUMPRODUCT(ISNUMBER(SEARCH("EHYD-PUM",[1]OUT_Electricity_CHP!$B$1:$B$10000))*1,([1]OUT_Electricity_CHP!$C$1:$C$10000="Var_Fin")*1,ISNUMBER(SEARCH("elc",[1]OUT_Electricity_CHP!$D$1:$D$10000))*1,[1]OUT_Electricity_CHP!F$1:F$10000)} -> 20.088412 | H15: {=SUMPRODUCT(ISNUMBER(SEARCH("EHYD-PUM",[1]OUT_Electricity_CHP!$B$1:$B$10000))*1,([1]OUT_Electricity_CHP!$C$1:$C$10000="Var_Fin")*1,ISNUMBER(SEARCH("elc",[1]OUT_Electricity_CHP!$D$1:$D$10000))*1,[1]OUT_Electricity_CHP!G$1:G$10000)} -> 3.0816247 | I15: {=SUMPRODUCT(ISNUMBER(SEARCH("EHYD-PUM",[1]OUT_Electricity_CHP!$B$1:$B$10000))*1,([1]OUT_Electricity_CHP!$C$1:$C$10000="Var_Fin")*1,ISNUMBER(SEARCH("elc",[1]OUT_Electricity_CHP!$D$1:$D$10000))*1,[1]OUT_Electricity_CHP!H$1:H$10000)} -> 55.865175 | J15: {=SUMPRODUCT(ISNUMBER(SEARCH("EHYD-PUM",[2]OUT_Electricity_CHP!$B$1:$B$10000))*1,([2]OUT_Electricity_CHP!$C$1:$C$10000="Var_Fin")*1,ISNUMBER(SEARCH("elc",[2]OUT_Electricity_CHP!$D$1:$D$10000))*1,[2]OUT_Electricity_CHP!I$1:I$10000)} -> 16.005249 | K15: {=SUMPRODUCT(ISNUMBER(SEARCH("EHYD-PUM",[2]OUT_Electricity_CHP!$B$1:$B$10000))*1,([2]OUT_Electricity_CHP!$C$1:$C$10000="Var_Fin")*1,ISNUMBER(SEARCH("elc",[2]OUT_Electricity_CHP!$D$1:$D$10000))*1,[2]OUT_Electricity_CHP!J$1:J$10000)} -> 16.567629 | L15: {=SUMPRODUCT(ISNUMBER(SEARCH("EHYD-PUM",[2]OUT_Electricity_CHP!$B$1:$B$10000))*1,([2]OUT_Electricity_CHP!$C$1:$C$10000="Var_Fin")*1,ISNUMBER(SEARCH("elc",[2]OUT_Electricity_CHP!$D$1:$D$10000))*1,[2]OUT_Electricity_CHP!K$1:K$10000)} -> 16.865889
A16: =A15 -> STEM | B16: =B15 -> SPS1 | C16: =C15 -> CH | D16: Primary Production|Solar | E16: PJ/yr. | F16: {=SUMPRODUCT(ISNUMBER(SEARCH("SOL",[1]OUT_PrimaryEnergyCons!$C$1:$C$1000))*1,[1]OUT_PrimaryEnergyCons!D$1:D$1000)} -> 12.557136 | G16: {=SUMPRODUCT(ISNUMBER(SEARCH("SOL",[1]OUT_PrimaryEnergyCons!$C$1:$C$1000))*1,[1]OUT_PrimaryEnergyCons!E$1:E$1000)} -> 16.525178 | H16: {=SUMPRODUCT(ISNUMBER(SEARCH("SOL",[1]OUT_PrimaryEnergyCons!$C$1:$C$1000))*1,[1]OUT_PrimaryEnergyCons!F$1:F$1000)} -> 30.421479 | I16: {=SUMPRODUCT(ISNUMBER(SEARCH("SOL",[1]OUT_PrimaryEnergyCons!$C$1:$C$1000))*1,[1]OUT_PrimaryEnergyCons!G$1:G$1000)} -> 56.344573 | J16: {=SUMPRODUCT(ISNUMBER(SEARCH("SOL",[2]OUT_PrimaryEnergyCons!$C$1:$C$1000))*1,[2]OUT_PrimaryEnergyCons!H$1:H$1000)} -> 59.990444 | K16: {=SUMPRODUCT(ISNUMBER(SEARCH("SOL",[2]OUT_PrimaryEnergyCons!$C$1:$C$1000))*1,[2]OUT_PrimaryEnergyCons!I$1:I$1000)} -> 123.39194 | L16: {=SUMPRODUCT(ISNUMBER(SEARCH("SOL",[2]OUT_PrimaryEnergyCons!$C$1:$C$1000))*1,[2]OUT_PrimaryEnergyCons!J$1:J$1000)} -> 145.05428
A17: =A16 -> STEM | B17: =B16 -> SPS1 | C17: =C16 -> CH | D17: Primary Production|Wind | E17: PJ/yr. | F17: {=SUMPRODUCT(ISNUMBER(SEARCH("wnd",[1]OUT_PrimaryEnergyCons!$C$1:$C$1000))*1,[1]OUT_PrimaryEnergyCons!D$1:D$1000)} -> 0.52448854 | G17: {=SUMPRODUCT(ISNUMBER(SEARCH("wnd",[1]OUT_PrimaryEnergyCons!$C$1:$C$1000))*1,[1]OUT_PrimaryEnergyCons!E$1:E$1000)} -> 0.54536872 | H17: {=SUMPRODUCT(ISNUMBER(SEARCH("wnd",[1]OUT_PrimaryEnergyCons!$C$1:$C$1000))*1,[1]OUT_PrimaryEnergyCons!F$1:F$1000)} -> 0.50324133 | I17: {=SUMPRODUCT(ISNUMBER(SEARCH("wnd",[1]OUT_PrimaryEnergyCons!$C$1:$C$1000))*1,[1]OUT_PrimaryEnergyCons!G$1:G$1000)} -> 2.0507563 | J17: {=SUMPRODUCT(ISNUMBER(SEARCH("wnd",[2]OUT_PrimaryEnergyCons!$C$1:$C$1000))*1,[2]OUT_PrimaryEnergyCons!H$1:H$1000)} -> 0.88477031 | K17: {=SUMPRODUCT(ISNUMBER(SEARCH("wnd",[2]OUT_PrimaryEnergyCons!$C$1:$C$1000))*1,[2]OUT_PrimaryEnergyCons!I$1:I$1000)} -> 0.88546719 | L17: {=SUMPRODUCT(ISNUMBER(SEARCH("wnd",[2]OUT_PrimaryEnergyCons!$C$1:$C$1000))*1,[2]OUT_PrimaryEnergyCons!J$1:J$1000)} -> 0.88547365
A18: =A17 -> STEM | B18: =B17 -> SPS1 | C18: =C17 -> CH | D18: Primary Production|Ambient heat | E18: PJ/yr. | F18: =[1]Overview!B$9-F19 -> 18.87484 | G18: =[1]Overview!C$9-G19 -> 21.791946 | H18: =[1]Overview!D$9-H19 -> 32.398774 | I18: =[1]Overview!E$9-I19 -> 54.417428 | J18: =[2]Overview!F$9-J19 -> 67.217328 | K18: =[2]Overview!G$9-K19 -> 85.553969 | L18: =[2]Overview!H$9-L19 -> 93.196759
A19: =A18 -> STEM | B19: =B18 -> SPS1 | C19: =C18 -> CH | D19: Primary Production|Geothermal | E19: PJ/yr. | F19: =+[1]Overview!B$28 -> 0 | G19: =+[1]Overview!C$28 -> 0 | H19: =+[1]Overview!D$28 -> 0 | I19: =+[1]Overview!E$28 -> 0 | J19: =+[2]Overview!F$28 -> 0 | K19: =+[2]Overview!G$28 -> 0.012818944 | L19: =+[2]Overview!H$28 -> 0.080190479
A20: =A19 -> STEM | B20: =B19 -> SPS1 | C20: =C19 -> CH | D20: Imports | E20: PJ/yr. | F20: =SUM(F21:F22,F41,F50:F51,F56) -> 781.7773 | G20: =SUM(G21:G22,G41,G50:G51,G56) -> 700.48164 | H20: =SUM(H21:H22,H41,H50:H51,H56) -> 650.19265 | I20: =SUM(I21:I22,I41,I50:I51,I56) -> 500.05517 | J20: =SUM(J21:J22,J41,J50:J51,J56) -> 405.00251 | K20: =SUM(K21:K22,K41,K50:K51,K56) -> 298.1296 | L20: =SUM(L21:L22,L41,L50:L51,L56) -> 225.04177
A21: =A20 -> STEM | B21: =B20 -> SPS1 | C21: =C20 -> CH | D21: Imports|Coal | E21: PJ/yr. | F21: {=SUMPRODUCT(("COA"=[1]OUT_PrimaryEnergyCons!$C$4:$C$10000)*1,[1]OUT_PrimaryEnergyCons!D$4:D$10000)} -> 3.6601882 | G21: {=SUMPRODUCT(("COA"=[1]OUT_PrimaryEnergyCons!$C$4:$C$10000)*1,[1]OUT_PrimaryEnergyCons!E$4:E$10000)} -> 3.564766 | H21: {=SUMPRODUCT(("COA"=[1]OUT_PrimaryEnergyCons!$C$4:$C$10000)*1,[1]OUT_PrimaryEnergyCons!F$4:F$10000)} -> 0.15596099 | I21: {=SUMPRODUCT(("COA"=[1]OUT_PrimaryEnergyCons!$C$4:$C$10000)*1,[1]OUT_PrimaryEnergyCons!G$4:G$10000)} -> 0.0046208377 | J21: {=SUMPRODUCT(("COA"=[2]OUT_PrimaryEnergyCons!$C$4:$C$10000)*1,[2]OUT_PrimaryEnergyCons!H$4:H$10000)} -> 0.0047033616 | K21: {=SUMPRODUCT(("COA"=[2]OUT_PrimaryEnergyCons!$C$4:$C$10000)*1,[2]OUT_PrimaryEnergyCons!I$4:I$10000)} -> 0.00048860444 | L21: {=SUMPRODUCT(("COA"=[2]OUT_PrimaryEnergyCons!$C$4:$C$10000)*1,[2]OUT_PrimaryEnergyCons!J$4:J$10000)} -> 0
A22: =A21 -> STEM | B22: =B21 -> SPS1 | C22: =C21 -> CH | D22: Imports|Oil | E22: PJ/yr. | F22: =F23+F29 -> 311.19204 | G22: =G23+G29 -> 286.59565 | H22: =H23+H29 -> 260.17312 | I22: =I23+I29 -> 158.41677 | J22: =J23+J29 -> 107.02121 | K22: =K23+K29 -> 66.616379 | L22: =L23+L29 -> 78.618845
A23: =A22 -> STEM | B23: =B22 -> SPS1 | C23: =C22 -> CH | D23: Imports|Oil|Fossil liquids | E23: PJ/yr. | F23: =SUM(F24:F28) -> 305.33109 | G23: =SUM(G24:G28) -> 280.7365 | H23: =SUM(H24:H28) -> 254.31385 | I23: =SUM(I24:I28) -> 148.06345 | J23: =SUM(J24:J28) -> 86.025692 | K23: =SUM(K24:K28) -> 34.113662 | L23: =SUM(L24:L28) -> 0
A24: =A22 -> STEM | B24: =B22 -> SPS1 | C24: =C22 -> CH | D24: Imports|Oil|Fossil liquids|Light fuel oil | E24: PJ/yr. | F24: {=SUMPRODUCT(("LFO"=[1]OUT_PrimaryEnergyCons!$C$4:$C$10000)*1,[1]OUT_PrimaryEnergyCons!D$4:D$10000)} -> 102.14686 | G24: {=SUMPRODUCT(("LFO"=[1]OUT_PrimaryEnergyCons!$C$4:$C$10000)*1,[1]OUT_PrimaryEnergyCons!E$4:E$10000)} -> 88.23263 | H24: {=SUMPRODUCT(("LFO"=[1]OUT_PrimaryEnergyCons!$C$4:$C$10000)*1,[1]OUT_PrimaryEnergyCons!F$4:F$10000)} -> 86.025824 | I24: {=SUMPRODUCT(("LFO"=[1]OUT_PrimaryEnergyCons!$C$4:$C$10000)*1,[1]OUT_PrimaryEnergyCons!G$4:G$10000)} -> 47.723315 | J24: {=SUMPRODUCT(("LFO"=[2]OUT_PrimaryEnergyCons!$C$4:$C$10000)*1,[2]OUT_PrimaryEnergyCons!H$4:H$10000)} -> 33.484946 | K24: {=SUMPRODUCT(("LFO"=[2]OUT_PrimaryEnergyCons!$C$4:$C$10000)*1,[2]OUT_PrimaryEnergyCons!I$4:I$10000)} -> 15.097296 | L24: {=SUMPRODUCT(("LFO"=[2]OUT_PrimaryEnergyCons!$C$4:$C$10000)*1,[2]OUT_PrimaryEnergyCons!J$4:J$10000)} -> 0
A25: =A24 -> STEM | B25: =B24 -> SPS1 | C25: =C24 -> CH | D25: Imports|Oil|Fossil liquids|Heavy fuel oil | E25: PJ/yr. | F25: {=SUMPRODUCT(("HFO"=[1]OUT_PrimaryEnergyCons!$C$4:$C$10000)*1,[1]OUT_PrimaryEnergyCons!D$4:D$10000)} -> 2.7765248 | G25: {=SUMPRODUCT(("HFO"=[1]OUT_PrimaryEnergyCons!$C$4:$C$10000)*1,[1]OUT_PrimaryEnergyCons!E$4:E$10000)} -> 2.7643674 | H25: {=SUMPRODUCT(("HFO"=[1]OUT_PrimaryEnergyCons!$C$4:$C$10000)*1,[1]OUT_PrimaryEnergyCons!F$4:F$10000)} -> 0.048276247 | I25: {=SUMPRODUCT(("HFO"=[1]OUT_PrimaryEnergyCons!$C$4:$C$10000)*1,[1]OUT_PrimaryEnergyCons!G$4:G$10000)} -> 0.004621587 | J25: {=SUMPRODUCT(("HFO"=[2]OUT_PrimaryEnergyCons!$C$4:$C$10000)*1,[2]OUT_PrimaryEnergyCons!H$4:H$10000)} -> 0.0066085858 | K25: {=SUMPRODUCT(("HFO"=[2]OUT_PrimaryEnergyCons!$C$4:$C$10000)*1,[2]OUT_PrimaryEnergyCons!I$4:I$10000)} -> 0.00049804572 | L25: {=SUMPRODUCT(("HFO"=[2]OUT_PrimaryEnergyCons!$C$4:$C$10000)*1,[2]OUT_PrimaryEnergyCons!J$4:J$10000)} -> 0
A26: =A25 -> STEM | B26: =B25 -> SPS1 | C26: =C25 -> CH | D26: Imports|Oil|Fossil liquids|Motor Diesel | E26: PJ/yr. | F26: {=SUMPRODUCT(("DSL"=[1]OUT_PrimaryEnergyCons!$C$4:$C$10000)*1,[1]OUT_PrimaryEnergyCons!D$4:D$10000)} -> 121.89425 | G26: {=SUMPRODUCT(("DSL"=[1]OUT_PrimaryEnergyCons!$C$4:$C$10000)*1,[1]OUT_PrimaryEnergyCons!E$4:E$10000)} -> 112.68575 | H26: {=SUMPRODUCT(("DSL"=[1]OUT_PrimaryEnergyCons!$C$4:$C$10000)*1,[1]OUT_PrimaryEnergyCons!F$4:F$10000)} -> 95.482327 | I26: {=SUMPRODUCT(("DSL"=[1]OUT_PrimaryEnergyCons!$C$4:$C$10000)*1,[1]OUT_PrimaryEnergyCons!G$4:G$10000)} -> 56.806865 | J26: {=SUMPRODUCT(("DSL"=[2]OUT_PrimaryEnergyCons!$C$4:$C$10000)*1,[2]OUT_PrimaryEnergyCons!H$4:H$10000)} -> 32.556474 | K26: {=SUMPRODUCT(("DSL"=[2]OUT_PrimaryEnergyCons!$C$4:$C$10000)*1,[2]OUT_PrimaryEnergyCons!I$4:I$10000)} -> 14.675985 | L26: {=SUMPRODUCT(("DSL"=[2]OUT_PrimaryEnergyCons!$C$4:$C$10000)*1,[2]OUT_PrimaryEnergyCons!J$4:J$10000)} -> 0
A27: =A26 -> STEM | B27: =B26 -> SPS1 | C27: =C26 -> CH | D27: Imports|Oil|Fossil liquids|Motor Gasoline | E27: PJ/yr. | F27: {=SUMPRODUCT(("GSL"=[1]OUT_PrimaryEnergyCons!$C$4:$C$10000)*1,[1]OUT_PrimaryEnergyCons!D$4:D$10000)} -> 77.404074 | G27: {=SUMPRODUCT(("GSL"=[1]OUT_PrimaryEnergyCons!$C$4:$C$10000)*1,[1]OUT_PrimaryEnergyCons!E$4:E$10000)} -> 75.649647 | H27: {=SUMPRODUCT(("GSL"=[1]OUT_PrimaryEnergyCons!$C$4:$C$10000)*1,[1]OUT_PrimaryEnergyCons!F$4:F$10000)} -> 70.929146 | I27: {=SUMPRODUCT(("GSL"=[1]OUT_PrimaryEnergyCons!$C$4:$C$10000)*1,[1]OUT_PrimaryEnergyCons!G$4:G$10000)} -> 41.082883 | J27: {=SUMPRODUCT(("GSL"=[2]OUT_PrimaryEnergyCons!$C$4:$C$10000)*1,[2]OUT_PrimaryEnergyCons!H$4:H$10000)} -> 17.391935 | K27: {=SUMPRODUCT(("GSL"=[2]OUT_PrimaryEnergyCons!$C$4:$C$10000)*1,[2]OUT_PrimaryEnergyCons!I$4:I$10000)} -> 2.1974827 | L27: {=SUMPRODUCT(("GSL"=[2]OUT_PrimaryEnergyCons!$C$4:$C$10000)*1,[2]OUT_PrimaryEnergyCons!J$4:J$10000)} -> 0
A28: =A27 -> STEM | B28: =B27 -> SPS1 | C28: =C27 -> CH | D28: Imports|Oil|Fossil liquids|Kerosene (excl. international aviation) | E28: PJ/yr. | F28: {=SUMPRODUCT(("KER"=[1]OUT_PrimaryEnergyCons!$C$4:$C$10000)*1,[1]OUT_PrimaryEnergyCons!D$4:D$10000)} -> 1.1093794 | G28: {=SUMPRODUCT(("KER"=[1]OUT_PrimaryEnergyCons!$C$4:$C$10000)*1,[1]OUT_PrimaryEnergyCons!E$4:E$10000)} -> 1.4041021 | H28: {=SUMPRODUCT(("KER"=[1]OUT_PrimaryEnergyCons!$C$4:$C$10000)*1,[1]OUT_PrimaryEnergyCons!F$4:F$10000)} -> 1.8282779 | I28: {=SUMPRODUCT(("KER"=[1]OUT_PrimaryEnergyCons!$C$4:$C$10000)*1,[1]OUT_PrimaryEnergyCons!G$4:G$10000)} -> 2.4457699 | J28: {=SUMPRODUCT(("KER"=[2]OUT_PrimaryEnergyCons!$C$4:$C$10000)*1,[2]OUT_PrimaryEnergyCons!H$4:H$10000)} -> 2.5857289 | K28: {=SUMPRODUCT(("KER"=[2]OUT_PrimaryEnergyCons!$C$4:$C$10000)*1,[2]OUT_PrimaryEnergyCons!I$4:I$10000)} -> 2.1424004 | L28: {=SUMPRODUCT(("KER"=[2]OUT_PrimaryEnergyCons!$C$4:$C$10000)*1,[2]OUT_PrimaryEnergyCons!J$4:J$10000)} -> 0
A29: =A50 -> STEM | B29: =B50 -> SPS1 | C29: =C50 -> CH | D29: Imports|Oil|Synthetic liquids | E29: PJ/yr. | F29: =SUM(F30:F32) -> 5.8609506 | G29: =SUM(G30:G32) -> 5.8591561 | H29: =SUM(H30:H32) -> 5.8592666 | I29: =SUM(I30:I32) -> 10.353313 | J29: =SUM(J30:J32) -> 20.995515 | K29: =SUM(K30:K32) -> 32.502717 | L29: =SUM(L30:L32) -> 78.618845
A30: =A37 -> STEM | B30: =B37 -> SPS1 | C30: =C37 -> CH | D30: Imports|Oil|Synthetic liquids|Total|Motor diesel | E30: PJ/yr. | F30: {=SUMPRODUCT(ISNUMBER(SEARCH("IMPBDS",[1]OUT_SyntheticFuels!$C$4:$C$1000))*1,("Var_Fout"=[1]OUT_SyntheticFuels!$B$4:$B$1000)*1,[1]OUT_SyntheticFuels!E$4:E$1000)-F32} -> 2.8760569 | G30: {=SUMPRODUCT(ISNUMBER(SEARCH("IMPBDS",[1]OUT_SyntheticFuels!$C$4:$C$1000))*1,("Var_Fout"=[1]OUT_SyntheticFuels!$B$4:$B$1000)*1,[1]OUT_SyntheticFuels!F$4:F$1000)-G32} -> 1.8135911 | H30: {=SUMPRODUCT(ISNUMBER(SEARCH("IMPBDS",[1]OUT_SyntheticFuels!$C$4:$C$1000))*1,("Var_Fout"=[1]OUT_SyntheticFuels!$B$4:$B$1000)*1,[1]OUT_SyntheticFuels!G$4:G$1000)-H32} -> 3.2681377 | I30: {=SUMPRODUCT(ISNUMBER(SEARCH("IMPBDS",[1]OUT_SyntheticFuels!$C$4:$C$1000))*1,("Var_Fout"=[1]OUT_SyntheticFuels!$B$4:$B$1000)*1,[1]OUT_SyntheticFuels!H$4:H$1000)-I32} -> 3.2465039 | J30: {=SUMPRODUCT(ISNUMBER(SEARCH("IMPBDS",[2]OUT_SyntheticFuels!$C$4:$C$1000))*1,("Var_Fout"=[2]OUT_SyntheticFuels!$B$4:$B$1000)*1,[2]OUT_SyntheticFuels!I$4:I$1000)-J32} -> 3.0618746 | K30: {=SUMPRODUCT(ISNUMBER(SEARCH("IMPBDS",[2]OUT_SyntheticFuels!$C$4:$C$1000))*1,("Var_Fout"=[2]OUT_SyntheticFuels!$B$4:$B$1000)*1,[2]OUT_SyntheticFuels!J$4:J$1000)-K32} -> 3.0616603 | L30: {=SUMPRODUCT(ISNUMBER(SEARCH("IMPBDS",[2]OUT_SyntheticFuels!$C$4:$C$1000))*1,("Var_Fout"=[2]OUT_SyntheticFuels!$B$4:$B$1000)*1,[2]OUT_SyntheticFuels!K$4:K$1000)-L32} -> 2.6504227
A31: =A30 -> STEM | B31: =B30 -> SPS1 | C31: =C30 -> CH | D31: Imports|Oil|Synthetic liquids|Total|Motor Gasoline | E31: PJ/yr. | F31: {=SUMPRODUCT(ISNUMBER(SEARCH("IMPeth",[1]OUT_SyntheticFuels!$C$4:$C$1000))*1,("Var_Fout"=[1]OUT_SyntheticFuels!$B$4:$B$1000)*1,[1]OUT_SyntheticFuels!E$4:E$1000)} -> 2.9848618 | G31: {=SUMPRODUCT(ISNUMBER(SEARCH("IMPeth",[1]OUT_SyntheticFuels!$C$4:$C$1000))*1,("Var_Fout"=[1]OUT_SyntheticFuels!$B$4:$B$1000)*1,[1]OUT_SyntheticFuels!F$4:F$1000)} -> 4.0443988 | H31: {=SUMPRODUCT(ISNUMBER(SEARCH("IMPeth",[1]OUT_SyntheticFuels!$C$4:$C$1000))*1,("Var_Fout"=[1]OUT_SyntheticFuels!$B$4:$B$1000)*1,[1]OUT_SyntheticFuels!G$4:G$1000)} -> 2.5707393 | I31: {=SUMPRODUCT(ISNUMBER(SEARCH("IMPeth",[1]OUT_SyntheticFuels!$C$4:$C$1000))*1,("Var_Fout"=[1]OUT_SyntheticFuels!$B$4:$B$1000)*1,[1]OUT_SyntheticFuels!H$4:H$1000)} -> 1.955005 | J31: {=SUMPRODUCT(ISNUMBER(SEARCH("IMPeth",[2]OUT_SyntheticFuels!$C$4:$C$1000))*1,("Var_Fout"=[2]OUT_SyntheticFuels!$B$4:$B$1000)*1,[2]OUT_SyntheticFuels!I$4:I$1000)} -> 1.4621749 | K31: {=SUMPRODUCT(ISNUMBER(SEARCH("IMPeth",[2]OUT_SyntheticFuels!$C$4:$C$1000))*1,("Var_Fout"=[2]OUT_SyntheticFuels!$B$4:$B$1000)*1,[2]OUT_SyntheticFuels!J$4:J$1000)} -> 2.3886011 | L31: {=SUMPRODUCT(ISNUMBER(SEARCH("IMPeth",[2]OUT_SyntheticFuels!$C$4:$C$1000))*1,("Var_Fout"=[2]OUT_SyntheticFuels!$B$4:$B$1000)*1,[2]OUT_SyntheticFuels!K$4:K$1000)} -> 0.19058886
B32: =B31 -> SPS1 | C32: =C31 -> CH | D32: Imports|Oil|Synthetic liquids|Total|Kerosene | E32: PJ/yr. | F32: =SUM([1]Transport_Aviation_Intl!B$12,[1]Transport!B$28) -> 3.183688e-05 | G32: =SUM([1]Transport_Aviation_Intl!C$12,[1]Transport!C$28) -> 0.0011661261 | H32: =SUM([1]Transport_Aviation_Intl!D$12,[1]Transport!D$28) -> 0.020389632 | I32: =SUM([1]Transport_Aviation_Intl!E$12,[1]Transport!E$28) -> 5.1518037 | J32: =SUM([2]Transport_Aviation_Intl!F$12,[2]Transport!F$28) -> 16.471465 | K32: =SUM([2]Transport_Aviation_Intl!G$12,[2]Transport!G$28) -> 27.052456 | L32: =SUM([2]Transport_Aviation_Intl!H$12,[2]Transport!H$28) -> 75.777834
A33: =A29 -> STEM | B33: =B29 -> SPS1 | C33: =C29 -> CH | D33: Imports|Oil|Synthetic liquids|Bioliquids|Total | E33: PJ/yr. | F33: =SUM(F34:F36) -> 5.8609506 | G33: =SUM(G34:G36) -> 5.8591561 | H33: =SUM(H34:H36) -> 5.8592666 | I33: =SUM(I34:I36) -> 10.353313 | J33: =SUM(J34:J36) -> 9.6758532 | K33: =SUM(K34:K36) -> 21.921727 | L33: =SUM(L34:L36) -> 29.893467
A34: =A31 -> STEM | B34: =B31 -> SPS1 | C34: =C31 -> CH | D34: Imports|Oil|Synthetic liquids|Bioliquids|Biodiesel | E34: PJ/yr. | F34: =F30 -> 2.8760569 | G34: =G30 -> 1.8135911 | H34: =H30 -> 3.2681377 | I34: =I30 -> 3.2465039 | J34: =IF(J30-MAX(F30:I30)<0,J30,MAX(F30:I30)) -> 3.0618746 | K34: =IF(K30-MAX(F30:J30)<0,K30,MAX(F30:J30)) -> 3.0616603 | L34: =IF(L30-MAX(G30:K30)<0,L30,MAX(G30:K30)) -> 2.6504227
A35: =A34 -> STEM | B35: =B34 -> SPS1 | C35: =C34 -> CH | D35: Imports|Oil|Synthetic liquids|Bioliquids|Ethanol | E35: PJ/yr. | F35: =F31 -> 2.9848618 | G35: =G31 -> 4.0443988 | H35: =H31 -> 2.5707393 | I35: =I31 -> 1.955005 | J35: =IF(J31-MAX(F31:I31)<0,J31,MAX(F31:I31)) -> 1.4621749 | K35: =IF(K31-MAX(F31:J31)<0,K31,MAX(F31:J31)) -> 2.3886011 | L35: =IF(L31-MAX(G31:K31)<0,L31,MAX(G31:K31)) -> 0.19058886
B36: =B35 -> SPS1 | C36: =C35 -> CH | D36: Imports|Oil|Synthetic liquids|Bioliquids|Biokerosene | E36: PJ/yr. | F36: =SUM([1]Transport!B$28,[1]Transport_Aviation_Intl!B$12) -> 3.183688e-05 | G36: =SUM([1]Transport!C$28,[1]Transport_Aviation_Intl!C$12) -> 0.0011661261 | H36: =SUM([1]Transport!D$28,[1]Transport_Aviation_Intl!D$12) -> 0.020389632 | I36: =SUM([1]Transport!E$28,[1]Transport_Aviation_Intl!E$12) -> 5.1518037 | J36: =IF(J32-MAX(F32:I32)<0,J32,MAX(F32:I32)) -> 5.1518037 | K36: =IF(K32-MAX(G32:J32)<0,K32,MAX(G32:J32)) -> 16.471465 | L36: =IF(L32-MAX(H32:K32)<0,L32,MAX(H32:K32)) -> 27.052456
A37: =A33 -> STEM | B37: =B33 -> SPS1 | C37: =C33 -> CH | D37: Imports|Oil|Synthetic liquids|PtL|Total | E37: PJ/yr. | F37: =SUM(F38:F40) -> 0 | G37: =SUM(G38:G40) -> 0 | H37: =SUM(H38:H40) -> 0 | I37: =SUM(I38:I40) -> 0 | J37: =SUM(J38:J40) -> 11.319661 | K37: =SUM(K38:K40) -> 10.58099 | L37: =SUM(L38:L40) -> 48.725378
A38: =A35 -> STEM | B38: =B35 -> SPS1 | C38: =C35 -> CH | D38: Imports|Oil|Synthetic liquids|PtL|PtL Diesel | E38: PJ/yr. | F38: 0 | G38: 0 | H38: 0 | I38: 0 | J38: =J30-J34 -> 0 | K38: =K30-K34 -> 0 | L38: =L30-L34 -> 0
A39: =A38 -> STEM | B39: =B38 -> SPS1 | C39: =C38 -> CH | D39: Imports|Oil|Synthetic liquids|PtL|PtL Gasoline | E39: PJ/yr. | F39: 0 | G39: 0 | H39: 0 | I39: 0 | J39: =J31-J35 -> 0 | K39: =K31-K35 -> 0 | L39: =L31-L35 -> 0
B40: =B39 -> SPS1 | C40: =C39 -> CH | D40: Imports|Oil|Synthetic liquids|PtL|PtL Kerosene | E40: PJ/yr. | F40: 0 | G40: 0 | H40: 0 | I40: 0 | J40: =J32-J36 -> 11.319661 | K40: =K32-K36 -> 10.58099 | L40: =L32-L36 -> 48.725378
...

Sheet check
C2: 2020 | D2: 2022 | E2: 2025 | F2: 2030 | G2: 2040 | H2: 2050
B3: Final energy consumption | C3: =SUM(C4:C7) -> 717.26759 | D3: =SUM(D4:D7) -> 704.05238 | E3: =SUM(E4:E7) -> 688.6843 | F3: =SUM(F4:F7) -> 612.75458 | G3: =SUM(G4:G7) -> 564.86807 | H3: =SUM(H4:H7) -> 531.55569
B4: Industry | C4: =SPS2_NUC_Mid!F763 -> 142.22068 | D4: =SPS2_NUC_Mid!G763 -> 142.43487 | E4: =SPS2_NUC_Mid!H763 -> 147.51305 | F4: =SPS2_NUC_Mid!I763 -> 148.41977 | G4: =SPS2_NUC_Mid!J763 -> 149.76776 | H4: =SPS2_NUC_Mid!K763 -> 147.70041
B5: Services | C5: =SPS2_NUC_Mid!F882 -> 140.1026 | D5: =SPS2_NUC_Mid!G882 -> 136.76647 | E5: =SPS2_NUC_Mid!H882 -> 132.76306 | F5: =SPS2_NUC_Mid!I882 -> 121.47085 | G5: =SPS2_NUC_Mid!J882 -> 115.16728 | H5: =SPS2_NUC_Mid!K882 -> 108.55457
B6: Residential | C6: =SPS2_NUC_Mid!F972 -> 219.63039 | D6: =SPS2_NUC_Mid!G972 -> 218.95225 | E6: =SPS2_NUC_Mid!H972 -> 219.68116 | F6: =SPS2_NUC_Mid!I972 -> 200.42838 | G6: =SPS2_NUC_Mid!J972 -> 190.67232 | H6: =SPS2_NUC_Mid!K972 -> 181.89085
B7: Transport | C7: =SPS2_NUC_Mid!F1136+SPS2_NUC_Mid!F1315+SPS2_NUC_Mid!F1399+SPS2_NUC_Mid!F1483+SPS2_NUC_Mid!F1490+SPS2_NUC_Mid!F1497+SPS2_NUC_Mid!F1546+SPS2_NUC_Mid!F1593+SPS2_NUC_Mid!F1640 -> 215.31392 | D7: =SPS2_NUC_Mid!G1136+SPS2_NUC_Mid!G1315+SPS2_NUC_Mid!G1399+SPS2_NUC_Mid!G1483+SPS2_NUC_Mid!G1490+SPS2_NUC_Mid!G1497+SPS2_NUC_Mid!G1546+SPS2_NUC_Mid!G1593+SPS2_NUC_Mid!G1640 -> 205.89879 | E7: =SPS2_NUC_Mid!H1136+SPS2_NUC_Mid!H1315+SPS2_NUC_Mid!H1399+SPS2_NUC_Mid!H1483+SPS2_NUC_Mid!H1490+SPS2_NUC_Mid!H1497+SPS2_NUC_Mid!H1546+SPS2_NUC_Mid!H1593+SPS2_NUC_Mid!H1640 -> 188.72702 | F7: =SPS2_NUC_Mid!I1136+SPS2_NUC_Mid!I1315+SPS2_NUC_Mid!I1399+SPS2_NUC_Mid!I1483+SPS2_NUC_Mid!I1490+SPS2_NUC_Mid!I1497+SPS2_NUC_Mid!I1546+SPS2_NUC_Mid!I1593+SPS2_NUC_Mid!I1640 -> 142.43558 | G7: =SPS2_NUC_Mid!J1136+SPS2_NUC_Mid!J1315+SPS2_NUC_Mid!J1399+SPS2_NUC_Mid!J1483+SPS2_NUC_Mid!J1490+SPS2_NUC_Mid!J1497+SPS2_NUC_Mid!J1546+SPS2_NUC_Mid!J1593+SPS2_NUC_Mid!J1640 -> 109.26072 | H7: =SPS2_NUC_Mid!K1136+SPS2_NUC_Mid!K1315+SPS2_NUC_Mid!K1399+SPS2_NUC_Mid!K1483+SPS2_NUC_Mid!K1490+SPS2_NUC_Mid!K1497+SPS2_NUC_Mid!K1546+SPS2_NUC_Mid!K1593+SPS2_NUC_Mid!K1640 -> 93.409869
B8: Fuel input to energy conversion and DAC | C8: =SUM(C9:C12) -> 515.11897 | D8: =SUM(D9:D12) -> 504.61287 | E8: =SUM(E9:E12) -> 515.96568 | F8: =SUM(F9:F12) -> 576.50633 | G8: =SUM(G9:G12) -> 531.34165 | H8: =SUM(H9:H12) -> 645.55475
B9: Electricity and heat | C9: =SPS2_NUC_Mid!F291+SPS2_NUC_Mid!F409 -> 495.64128 | D9: =SPS2_NUC_Mid!G291+SPS2_NUC_Mid!G409 -> 476.27631 | E9: =SPS2_NUC_Mid!H291+SPS2_NUC_Mid!H409 -> 483.96899 | F9: =SPS2_NUC_Mid!I291+SPS2_NUC_Mid!I409 -> 544.45137 | G9: =SPS2_NUC_Mid!J291+SPS2_NUC_Mid!J409 -> 492.04817 | H9: =SPS2_NUC_Mid!K291+SPS2_NUC_Mid!K409 -> 567.94943
B10: Biofuel production | C10: =SPS2_NUC_Mid!F590+SPS2_NUC_Mid!F604+SPS2_NUC_Mid!F644 -> 19.470357 | D10: =SPS2_NUC_Mid!G590+SPS2_NUC_Mid!G604+SPS2_NUC_Mid!G644 -> 28.307016 | E10: =SPS2_NUC_Mid!H590+SPS2_NUC_Mid!H604+SPS2_NUC_Mid!H644 -> 31.96659 | F10: =SPS2_NUC_Mid!I590+SPS2_NUC_Mid!I604+SPS2_NUC_Mid!I644 -> 31.91628 | G10: =SPS2_NUC_Mid!J590+SPS2_NUC_Mid!J604+SPS2_NUC_Mid!J644 -> 25.696405 | H10: =SPS2_NUC_Mid!K590+SPS2_NUC_Mid!K604+SPS2_NUC_Mid!K644 -> 29.245808
B11: Hydrogen production | C11: =SPS2_NUC_Mid!F679 -> 0.007334972 | D11: =SPS2_NUC_Mid!G679 -> 0.029548522 | E11: =SPS2_NUC_Mid!H679 -> 0.030094104 | F11: =SPS2_NUC_Mid!I679 -> 0.13868003 | G11: =SPS2_NUC_Mid!J679 -> 13.597075 | H11: =SPS2_NUC_Mid!K679 -> 48.359461
B12: DAC | C12: =SPS2_NUC_Mid!F1707 -> 0 | D12: =SPS2_NUC_Mid!G1707 -> 0 | E12: =SPS2_NUC_Mid!H1707 -> 0 | F12: =SPS2_NUC_Mid!I1707 -> 0 | G12: =SPS2_NUC_Mid!J1707 -> 0 | H12: =SPS2_NUC_Mid!K1707 -> 5.1769418e-05
B13: Total Primary energy consumption | C13: =SPS2_NUC_Mid!F2+SPS2_NUC_Mid!F20-SPS2_NUC_Mid!F57 -> 966.15861 | D13: =SPS2_NUC_Mid!G2+SPS2_NUC_Mid!G20-SPS2_NUC_Mid!G57 -> 964.3481 | E13: =SPS2_NUC_Mid!H2+SPS2_NUC_Mid!H20-SPS2_NUC_Mid!H57 -> 916.44483 | F13: =SPS2_NUC_Mid!I2+SPS2_NUC_Mid!I20-SPS2_NUC_Mid!I57 -> 892.21411 | G13: =SPS2_NUC_Mid!J2+SPS2_NUC_Mid!J20-SPS2_NUC_Mid!J57 -> 787.26344 | H13: =SPS2_NUC_Mid!K2+SPS2_NUC_Mid!K20-SPS2_NUC_Mid!K57 -> 783.07841
B14: Domestic production | C14: =SPS2_NUC_Mid!F2 -> 301.55157 | D14: =SPS2_NUC_Mid!G2 -> 298.76898 | E14: =SPS2_NUC_Mid!H2 -> 338.20473 | F14: =SPS2_NUC_Mid!I2 -> 444.85986 | G14: =SPS2_NUC_Mid!J2 -> 418.94116 | H14: =SPS2_NUC_Mid!K2 -> 512.14577
B15: Imports | C15: =SPS2_NUC_Mid!F20 -> 781.7773 | D15: =SPS2_NUC_Mid!G20 -> 700.48164 | E15: =SPS2_NUC_Mid!H20 -> 650.19265 | F15: =SPS2_NUC_Mid!I20 -> 500.05517 | G15: =SPS2_NUC_Mid!J20 -> 405.00251 | H15: =SPS2_NUC_Mid!K20 -> 298.1296
B16: Exports | C16: =SPS2_NUC_Mid!F57 -> 117.17026 | D16: =SPS2_NUC_Mid!G57 -> 34.902519 | E16: =SPS2_NUC_Mid!H57 -> 71.952546 | F16: =SPS2_NUC_Mid!I57 -> 52.700914 | G16: =SPS2_NUC_Mid!J57 -> 36.68023 | H16: =SPS2_NUC_Mid!K57 -> 27.196955
