Workbook

Sheet Variable_List
B2: Variable | C2: Description | D2: Unit | E2: Comment
B3: Primary Production | C3: Domestic primary production of resources | D3: PJ/yr.
B4: Imports | C4: Imports of energy carriers | D4: PJ/yr.
B5: Exports | C5: Exports of energy carriers | D5: PJ/yr.
B6: Electricity generation | C6: Domestic electricity generation | D6: PJ/yr.
B7: Heat generation from CHPs and heat plants | C7: Domestic heat production from CHPs (District heating CHPs or onsite CHPs) and heat plants | D7: PJ/yr.
B8: Fuel input for electricity generation | C8: Fuel input allocated to domestic electricity generation only | D8: PJ/yr.
B9: Fuel input for heat generation from CHPs and heat plants | C9: Fuel input allocated to domestic heat production from CHPs and heat plants only | D9: PJ/yr.
B10: Efficiency of power plants (electric) | C10: Average annual efficiency of power plants and CHPs for electricity production only | D10: % | E10: The thermal efficiency of CHPs can be inferred from the Heat to Electricity production ratio, but it can also be provided; the average efficiency differs from the technical efficiency as it includes efficiency losses due to part load operation
B11: Efficiency of heat plants (thermal) | C11: Average annual efficiency of heat plants | D11: % | E11: It is the annual marketed efficiency including part load efficiency losses and differs from the full load nominal technical efficiency; for heat pumps refers to COP
B12: Domestic biodiesel production | C12: Domestic production of biodiesel | D12: PJ/yr.
B13: Heat from domestic biodiesel production | C13: Heat produced as byproduct from biodiesel production and fed into the district heating network | D13: PJ/yr.
B14: Fuel input for domestic biodiesel production | C14: Fuel input for the domestic production of biodiesel | D14: PJ/yr.
B15: Efficiency for domestic biodiesel production | C15: Average annual efficiency for biodiesel and heat production | D15: %
B16: Domestic ethanol production | C16: Domestic production of ethanol | D16: PJ/yr.
B17: Fuel input for domestic ethanol production | C17: Fuel input for the domestic production of ethanol | D17: PJ/yr.
B18: Efficiency for domestic ethanol production | C18: Average annual efficiency for domestic production of ethanol | D18: %
B19: Domestic biogas production | C19: Domestic production of biogas and biogenic syngas | D19: PJ/yr.
B20: Electricity from domestic biogas production | C20: Electriicty produced as byproduct from biogas production and fed into the grid | D20: PJ/yr.
B21: Heat from domestic biogas production | C21: Heat produced as byproduct from biogas production and fed into the district heating network | D21: PJ/yr.
B22: Fuel input for domestic biogas production | C22: Fuel input for domestic biogas production | D22: PJ/yr.
B23: Efficiency for domestic biogas production | C23: Average annual efficiency for biogas production (accounting for byproduct production) | D23: %
... B25: Fuel input for hydrogen production | C25: Fuel input for deomstic hydrogen production | D25: PJ/yr.
B26: Efficiency for hydrogen production | C26: Average annual efficiency for hydrogen production | D26: % | E26: Including losses due to part load operation
B27: Biomethane production from biogas upgrade | C27: Production of domestic biomethane from biogas | D27: PJ/yr. | E27: One technology only fuel output is biomethane
B28: Fuel input for biogas upgrade to biomethane | C28: Use of biogas for upgrade to biomethane | D28: PJ/yr. | E28: One technology only fuel input is biogas
B29: Efficiency for biomethane production from biogas upgrade | C29: Average annual efficiency of biogas to biomethane upgrade | D29: PJ/yr. | E29: One technology only fuel input is biogas, fuel output is biomethane
B30: Domestic PtG and PtL production | C30: Domestic production of power-to-gas and power-to-liquids | D30: PJ/yr.
B31: Fuel input for domestic PtG and PtL production | C31: Fuel used for domestic PtG and PtL production (excl. CO2) | D31: PJ/yr.
B32: Efficiency for domestic PtG and PtL production | C32: Average annual efficiency for PtG and PtL processes (excl. CO2 consumption) | D32: %
B33: CO2 input for domestic PtG and PtL production | C33: CO2 input for domestic PtG and PtL production | D33: Mt/yr. | E33: The distinction of the source of CO2 (biogenic or fossil) is also provided and can be proportionally allocated to the technologies for PtG and PtL
B34: Domestic wood to pellet production | C34: Wood conversion to pellet domestic production output | D34: PJ/yr. | E34: One technology only , input is wood output is pellet
B35: Fuel input for wood to pellet production | C35: Wood conversion to pellet domestic production - input wood required | D35: PJ/yr. | E35: One technology only , input is wood output is pellet
B36: Efficiency for wood to pellet production | C36: Average annual efficiency of wood to pellet conversion | D36: %
B37: Fuel consumption in industry sectors | C37: Fuel consumption in industry by fuel and technology | D37: PJ/yr. | E37: This unfortunately it will change when the new industrial sectors will be integrated into STEM
B38: Process and space heating production in industry sectors | C38: Energy service demand provided in the form of process and space heating in industry | D38: PJ/yr. | E38: This unfortunately it will change when the new industrial sectors will be integrated into STEM
B39: Efficiency in industry sectors | C39: Boilers efficiency and COP of heat pumps in the industrial sectors | D39: % | E39: This unfortunately it will change when the new industrial sectors will be integrated into STEM
B40: Fuel consumption in Services sectors | C40: Fuel consumption in services sectors by fuel and technology | D40: PJ/yr.
B41: Space water and process heat production in Services sectors | C41: Production of energy service demand for space, water and process heat in Services sectors | D41: PJ/yr.
B42: Efficiency in Services sectors | C42: Boilers efficiency and COP of heat pumps in the Services sectors | D42: %
...

Sheet SPS1_NUC_Low
A1: Model | B1: Scenario | C1: Region | D1: Variable | E1: Unit | F1: 2020 | G1: 2022 | H1: 2025 | I1: 2030 | J1: 2035 | K1: 2040 | L1: 2050
A2: STEM | B2: SPS1 | C2: CH | D2: Primary Production | E2: PJ/yr. | F2: =F3+F8+F11+F12+F16+F17+F18+F19 -> 300.18609 | G2: =G3+G8+G11+G12+G16+G17+G18+G19 -> 292.84408 | H2: =H3+H8+H11+H12+H16+H17+H18+H19 -> 331.72196 | I2: =I3+I8+I11+I12+I16+I17+I18+I19 -> 399.67808 | J2: =J3+J8+J11+J12+J16+J17+J18+J19 -> 423.00398 | K2: =K3+K8+K11+K12+K16+K17+K18+K19 -> 452.22188 | L2: =L3+L8+L11+L12+L16+L17+L18+L19 -> 503.75761
A3: =A2 -> STEM | B3: =B2 -> SPS1 | C3: =C2 -> CH | D3: Primary Production|Wood | E3: PJ/yr. | F3: =SUM(F4:F7) -> 44.972435 | G3: =SUM(G4:G7) -> 48.190475 | H3: =SUM(H4:H7) -> 49.768348 | I3: =SUM(I4:I7) -> 49.76848 | J3: =SUM(J4:J7) -> 51.331849 | K3: =SUM(K4:K7) -> 51.33208 | L3: =SUM(L4:L7) -> 51.332341
A4: =A3 -> STEM | B4: =B3 -> SPS1 | C4: =C3 -> CH | D4: Primary Production|Wood|Waste wood | E4: PJ/yr. | F4: {=SUMPRODUCT(("RNWWOD1"=[1]OUT_PrimaryEnergyCons!$A$1:$A$1000)*1,[1]OUT_PrimaryEnergyCons!D$1:D$1000)} -> 11.111879 | G4: {=SUMPRODUCT(("RNWWOD1"=[1]OUT_PrimaryEnergyCons!$A$1:$A$1000)*1,[1]OUT_PrimaryEnergyCons!E$1:E$1000)} -> 11.952886 | H4: {=SUMPRODUCT(("RNWWOD1"=[1]OUT_PrimaryEnergyCons!$A$1:$A$1000)*1,[1]OUT_PrimaryEnergyCons!F$1:F$1000)} -> 13.214393 | I4: {=SUMPRODUCT(("RNWWOD1"=[1]OUT_PrimaryEnergyCons!$A$1:$A$1000)*1,[1]OUT_PrimaryEnergyCons!G$1:G$1000)} -> 15.316911 | J4: {=SUMPRODUCT(("RNWWOD1"=[2]OUT_PrimaryEnergyCons!$A$1:$A$1000)*1,[2]OUT_PrimaryEnergyCons!H$1:H$1000)} -> 15.849116 | K4: {=SUMPRODUCT(("RNWWOD1"=[2]OUT_PrimaryEnergyCons!$A$1:$A$1000)*1,[2]OUT_PrimaryEnergyCons!I$1:I$1000)} -> 16.266425 | L4: {=SUMPRODUCT(("RNWWOD1"=[2]OUT_PrimaryEnergyCons!$A$1:$A$1000)*1,[2]OUT_PrimaryEnergyCons!J$1:J$1000)} -> 16.957033
A5: =A4 -> STEM | B5: =B4 -> SPS1 | C5: =C4 -> CH | D5: Primary Production|Wood|Wood residues | E5: PJ/yr. | F5: {=SUMPRODUCT(("RNWWOD2"=[1]OUT_PrimaryEnergyCons!$A$1:$A$1000)*1,[1]OUT_PrimaryEnergyCons!D$1:D$1000)} -> 7.5116716 | G5: {=SUMPRODUCT(("RNWWOD2"=[1]OUT_PrimaryEnergyCons!$A$1:$A$1000)*1,[1]OUT_PrimaryEnergyCons!E$1:E$1000)} -> 7.5431441 | H5: {=SUMPRODUCT(("RNWWOD2"=[1]OUT_PrimaryEnergyCons!$A$1:$A$1000)*1,[1]OUT_PrimaryEnergyCons!F$1:F$1000)} -> 7.5903482 | I5: {=SUMPRODUCT(("RNWWOD2"=[1]OUT_PrimaryEnergyCons!$A$1:$A$1000)*1,[1]OUT_PrimaryEnergyCons!G$1:G$1000)} -> 7.669027 | J5: {=SUMPRODUCT(("RNWWOD2"=[2]OUT_PrimaryEnergyCons!$A$1:$A$1000)*1,[2]OUT_PrimaryEnergyCons!H$1:H$1000)} -> 7.6690141 | K5: {=SUMPRODUCT(("RNWWOD2"=[2]OUT_PrimaryEnergyCons!$A$1:$A$1000)*1,[2]OUT_PrimaryEnergyCons!I$1:I$1000)} -> 7.6690648 | L5: {=SUMPRODUCT(("RNWWOD2"=[2]OUT_PrimaryEnergyCons!$A$1:$A$1000)*1,[2]OUT_PrimaryEnergyCons!J$1:J$1000)} -> 7.6690761
A6: =A5 -> STEM | B6: =B5 -> SPS1 | C6: =C5 -> CH | D6: Primary Production|Wood|Wood from landscape maintenance | E6: PJ/yr. | F6: {=SUMPRODUCT(("RNWWOD3"=[1]OUT_PrimaryEnergyCons!$A$1:$A$1000)*1,[1]OUT_PrimaryEnergyCons!D$1:D$1000)} -> 3.1682454 | G6: {=SUMPRODUCT(("RNWWOD3"=[1]OUT_PrimaryEnergyCons!$A$1:$A$1000)*1,[1]OUT_PrimaryEnergyCons!E$1:E$1000)} -> 3.4956729 | H6: {=SUMPRODUCT(("RNWWOD3"=[1]OUT_PrimaryEnergyCons!$A$1:$A$1000)*1,[1]OUT_PrimaryEnergyCons!F$1:F$1000)} -> 3.9868144 | I6: {=SUMPRODUCT(("RNWWOD3"=[1]OUT_PrimaryEnergyCons!$A$1:$A$1000)*1,[1]OUT_PrimaryEnergyCons!G$1:G$1000)} -> 4.8053861 | J6: {=SUMPRODUCT(("RNWWOD3"=[2]OUT_PrimaryEnergyCons!$A$1:$A$1000)*1,[2]OUT_PrimaryEnergyCons!H$1:H$1000)} -> 4.8053539 | K6: {=SUMPRODUCT(("RNWWOD3"=[2]OUT_PrimaryEnergyCons!$A$1:$A$1000)*1,[2]OUT_PrimaryEnergyCons!I$1:I$1000)} -> 4.80542 | L6: {=SUMPRODUCT(("RNWWOD3"=[2]OUT_PrimaryEnergyCons!$A$1:$A$1000)*1,[2]OUT_PrimaryEnergyCons!J$1:J$1000)} -> 4.8053895
A7: =A6 -> STEM | B7: =B6 -> SPS1 | C7: =C6 -> CH | D7: Primary Production|Wood|Wood from Forest (hard wood) | E7: PJ/yr. | F7: {=SUMPRODUCT(("RNWWOD4"=[1]OUT_PrimaryEnergyCons!$A$1:$A$1000)*1+("RNWWOD5"=[1]OUT_PrimaryEnergyCons!$A$1:$A$1000)*1,[1]OUT_PrimaryEnergyCons!D$1:D$1000)} -> 23.180639 | G7: {=SUMPRODUCT(("RNWWOD4"=[1]OUT_PrimaryEnergyCons!$A$1:$A$1000)*1+("RNWWOD5"=[1]OUT_PrimaryEnergyCons!$A$1:$A$1000)*1,[1]OUT_PrimaryEnergyCons!E$1:E$1000)} -> 25.198772 | H7: {=SUMPRODUCT(("RNWWOD4"=[1]OUT_PrimaryEnergyCons!$A$1:$A$1000)*1+("RNWWOD5"=[1]OUT_PrimaryEnergyCons!$A$1:$A$1000)*1,[1]OUT_PrimaryEnergyCons!F$1:F$1000)} -> 24.976792 | I7: {=SUMPRODUCT(("RNWWOD4"=[1]OUT_PrimaryEnergyCons!$A$1:$A$1000)*1+("RNWWOD5"=[1]OUT_PrimaryEnergyCons!$A$1:$A$1000)*1,[1]OUT_PrimaryEnergyCons!G$1:G$1000)} -> 21.977155 | J7: {=SUMPRODUCT(("RNWWOD4"=[2]OUT_PrimaryEnergyCons!$A$1:$A$1000)*1+("RNWWOD5"=[2]OUT_PrimaryEnergyCons!$A$1:$A$1000)*1,[2]OUT_PrimaryEnergyCons!H$1:H$1000)} -> 23.008365 | K7: {=SUMPRODUCT(("RNWWOD4"=[2]OUT_PrimaryEnergyCons!$A$1:$A$1000)*1+("RNWWOD5"=[2]OUT_PrimaryEnergyCons!$A$1:$A$1000)*1,[2]OUT_PrimaryEnergyCons!I$1:I$1000)} -> 22.59117 | L7: {=SUMPRODUCT(("RNWWOD4"=[2]OUT_PrimaryEnergyCons!$A$1:$A$1000)*1+("RNWWOD5"=[2]OUT_PrimaryEnergyCons!$A$1:$A$1000)*1,[2]OUT_PrimaryEnergyCons!J$1:J$1000)} -> 21.900842
A8: =A7 -> STEM | B8: =B7 -> SPS1 | C8: =C7 -> CH | D8: Primary Production|Waste | E8: PJ/yr. | F8: =SUM(F9:F10) -> 70.031517 | G8: =SUM(G9:G10) -> 70.097158 | H8: =SUM(H9:H10) -> 69.498225 | I8: =SUM(I9:I10) -> 71.102492 | J8: =SUM(J9:J10) -> 72.080301 | K8: =SUM(K9:K10) -> 72.321964 | L8: =SUM(L9:L10) -> 73.177897
A9: =A8 -> STEM | B9: =B8 -> SPS1 | C9: =C8 -> CH | D9: Primary Production|Waste|Non renewable waste | E9: PJ/yr. | F9: {=SUMPRODUCT(("RNNWWST1"=[1]OUT_PrimaryEnergyCons!$A$1:$A$1000)*1,[1]OUT_PrimaryEnergyCons!D$1:D$1000)} -> 35.931077 | G9: {=SUMPRODUCT(("RNNWWST1"=[1]OUT_PrimaryEnergyCons!$A$1:$A$1000)*1,[1]OUT_PrimaryEnergyCons!E$1:E$1000)} -> 35.882386 | H9: {=SUMPRODUCT(("RNNWWST1"=[1]OUT_PrimaryEnergyCons!$A$1:$A$1000)*1,[1]OUT_PrimaryEnergyCons!F$1:F$1000)} -> 35.283442 | I9: {=SUMPRODUCT(("RNNWWST1"=[1]OUT_PrimaryEnergyCons!$A$1:$A$1000)*1,[1]OUT_PrimaryEnergyCons!G$1:G$1000)} -> 35.060088 | J9: {=SUMPRODUCT(("RNNWWST1"=[2]OUT_PrimaryEnergyCons!$A$1:$A$1000)*1,[2]OUT_PrimaryEnergyCons!H$1:H$1000)} -> 34.937739 | K9: {=SUMPRODUCT(("RNNWWST1"=[2]OUT_PrimaryEnergyCons!$A$1:$A$1000)*1,[2]OUT_PrimaryEnergyCons!I$1:I$1000)} -> 35.176282 | L9: {=SUMPRODUCT(("RNNWWST1"=[2]OUT_PrimaryEnergyCons!$A$1:$A$1000)*1,[2]OUT_PrimaryEnergyCons!J$1:J$1000)} -> 35.853386
A10: =A9 -> STEM | B10: =B9 -> SPS1 | C10: =C9 -> CH | D10: Primary Production|Waste|Renewable waste | E10: PJ/yr. | F10: {=SUMPRODUCT(("RNWWST1"=[1]OUT_PrimaryEnergyCons!$A$1:$A$1000)*1,[1]OUT_PrimaryEnergyCons!D$1:D$1000)} -> 34.10044 | G10: {=SUMPRODUCT(("RNWWST1"=[1]OUT_PrimaryEnergyCons!$A$1:$A$1000)*1,[1]OUT_PrimaryEnergyCons!E$1:E$1000)} -> 34.214772 | H10: {=SUMPRODUCT(("RNWWST1"=[1]OUT_PrimaryEnergyCons!$A$1:$A$1000)*1,[1]OUT_PrimaryEnergyCons!F$1:F$1000)} -> 34.214783 | I10: {=SUMPRODUCT(("RNWWST1"=[1]OUT_PrimaryEnergyCons!$A$1:$A$1000)*1,[1]OUT_PrimaryEnergyCons!G$1:G$1000)} -> 36.042404 | J10: {=SUMPRODUCT(("RNWWST1"=[2]OUT_PrimaryEnergyCons!$A$1:$A$1000)*1,[2]OUT_PrimaryEnergyCons!H$1:H$1000)} -> 37.142562 | K10: {=SUMPRODUCT(("RNWWST1"=[2]OUT_PrimaryEnergyCons!$A$1:$A$1000)*1,[2]OUT_PrimaryEnergyCons!I$1:I$1000)} -> 37.145682 | L10: {=SUMPRODUCT(("RNWWST1"=[2]OUT_PrimaryEnergyCons!$A$1:$A$1000)*1,[2]OUT_PrimaryEnergyCons!J$1:J$1000)} -> 37.324512
A11: =A10 -> STEM | B11: =B10 -> SPS1 | C11: =C10 -> CH | D11: Primary Production|Manure | E11: PJ/yr. | F11: {=SUMPRODUCT(("mnr"=[1]OUT_PrimaryEnergyCons!$C$1:$C$1000)*1,[1]OUT_PrimaryEnergyCons!D$1:D$1000)} -> 3.7980919 | G11: {=SUMPRODUCT(("mnr"=[1]OUT_PrimaryEnergyCons!$C$1:$C$1000)*1,[1]OUT_PrimaryEnergyCons!E$1:E$1000)} -> 10.103738 | H11: {=SUMPRODUCT(("mnr"=[1]OUT_PrimaryEnergyCons!$C$1:$C$1000)*1,[1]OUT_PrimaryEnergyCons!F$1:F$1000)} -> 12.540178 | I11: {=SUMPRODUCT(("mnr"=[1]OUT_PrimaryEnergyCons!$C$1:$C$1000)*1,[1]OUT_PrimaryEnergyCons!G$1:G$1000)} -> 12.540422 | J11: {=SUMPRODUCT(("mnr"=[2]OUT_PrimaryEnergyCons!$C$1:$C$1000)*1,[2]OUT_PrimaryEnergyCons!H$1:H$1000)} -> 12.540697 | K11: {=SUMPRODUCT(("mnr"=[2]OUT_PrimaryEnergyCons!$C$1:$C$1000)*1,[2]OUT_PrimaryEnergyCons!I$1:I$1000)} -> 14.539891 | L11: {=SUMPRODUCT(("mnr"=[2]OUT_PrimaryEnergyCons!$C$1:$C$1000)*1,[2]OUT_PrimaryEnergyCons!J$1:J$1000)} -> 26.817677
A12: =A11 -> STEM | B12: =B11 -> SPS1 | C12: =C11 -> CH | D12: Primary Production|Hydro | E12: PJ/yr. | F12: =SUM(F13:F15) -> 149.43048 | G12: =SUM(G13:G15) -> 125.60698 | H12: =SUM(H13:H15) -> 137.1414 | I12: =SUM(I13:I15) -> 151.25679 | J12: =SUM(J13:J15) -> 151.34074 | K12: =SUM(K13:K15) -> 151.45728 | L12: =SUM(L13:L15) -> 151.77418
A13: =A12 -> STEM | B13: =B12 -> SPS1 | C13: =C12 -> CH | D13: Primary Production|Hydro|Large hydro | E13: PJ/yr. | F13: {=SUMPRODUCT(ISNUMBER(SEARCH("EHYD-DAM",[1]OUT_Electricity_CHP!$B$1:$B$10000))*1,([1]OUT_Electricity_CHP!$C$1:$C$10000="Var_Fout")*1,ISNUMBER(SEARCH("ELC",[1]OUT_Electricity_CHP!$D$1:$D$10000))*1,[1]OUT_Electricity_CHP!E$1:E$10000)} -> 66.74568 | G13: {=SUMPRODUCT(ISNUMBER(SEARCH("EHYD-DAM",[1]OUT_Electricity_CHP!$B$1:$B$10000))*1,([1]OUT_Electricity_CHP!$C$1:$C$10000="Var_Fout")*1,ISNUMBER(SEARCH("ELC",[1]OUT_Electricity_CHP!$D$1:$D$10000))*1,[1]OUT_Electricity_CHP!F$1:F$10000)} -> 49.798798 | H13: {=SUMPRODUCT(ISNUMBER(SEARCH("EHYD-DAM",[1]OUT_Electricity_CHP!$B$1:$B$10000))*1,([1]OUT_Electricity_CHP!$C$1:$C$10000="Var_Fout")*1,ISNUMBER(SEARCH("ELC",[1]OUT_Electricity_CHP!$D$1:$D$10000))*1,[1]OUT_Electricity_CHP!G$1:G$10000)} -> 69.090669 | I13: {=SUMPRODUCT(ISNUMBER(SEARCH("EHYD-DAM",[1]OUT_Electricity_CHP!$B$1:$B$10000))*1,([1]OUT_Electricity_CHP!$C$1:$C$10000="Var_Fout")*1,ISNUMBER(SEARCH("ELC",[1]OUT_Electricity_CHP!$D$1:$D$10000))*1,[1]OUT_Electricity_CHP!H$1:H$10000)} -> 70.809473 | J13: {=SUMPRODUCT(ISNUMBER(SEARCH("EHYD-DAM",[2]OUT_Electricity_CHP!$B$1:$B$10000))*1,([2]OUT_Electricity_CHP!$C$1:$C$10000="Var_Fout")*1,ISNUMBER(SEARCH("ELC",[2]OUT_Electricity_CHP!$D$1:$D$10000))*1,[2]OUT_Electricity_CHP!I$1:I$10000)} -> 71.532026 | K13: {=SUMPRODUCT(ISNUMBER(SEARCH("EHYD-DAM",[2]OUT_Electricity_CHP!$B$1:$B$10000))*1,([2]OUT_Electricity_CHP!$C$1:$C$10000="Var_Fout")*1,ISNUMBER(SEARCH("ELC",[2]OUT_Electricity_CHP!$D$1:$D$10000))*1,[2]OUT_Electricity_CHP!J$1:J$10000)} -> 72.588147 | L13: {=SUMPRODUCT(ISNUMBER(SEARCH("EHYD-DAM",[2]OUT_Electricity_CHP!$B$1:$B$10000))*1,([2]OUT_Electricity_CHP!$C$1:$C$10000="Var_Fout")*1,ISNUMBER(SEARCH("ELC",[2]OUT_Electricity_CHP!$D$1:$D$10000))*1,[2]OUT_Electricity_CHP!K$1:K$10000)} -> 74.749323
A14: =A13 -> STEM | B14: =B13 -> SPS1 | C14: =C13 -> CH | D14: Primary Production|Hydro|Run-of-river hydro | E14: PJ/yr. | F14: {=SUMPRODUCT(ISNUMBER(SEARCH("EHYD-RUN",[1]OUT_Electricity_CHP!$B$1:$B$10000))*1,([1]OUT_Electricity_CHP!$C$1:$C$10000="Var_Fout")*1,ISNUMBER(SEARCH("ELC",[1]OUT_Electricity_CHP!$D$1:$D$10000))*1,[1]OUT_Electricity_CHP!E$1:E$10000)} -> 66.632401 | G14: {=SUMPRODUCT(ISNUMBER(SEARCH("EHYD-RUN",[1]OUT_Electricity_CHP!$B$1:$B$10000))*1,([1]OUT_Electricity_CHP!$C$1:$C$10000="Var_Fout")*1,ISNUMBER(SEARCH("ELC",[1]OUT_Electricity_CHP!$D$1:$D$10000))*1,[1]OUT_Electricity_CHP!F$1:F$10000)} -> 55.763999 | H14: {=SUMPRODUCT(ISNUMBER(SEARCH("EHYD-RUN",[1]OUT_Electricity_CHP!$B$1:$B$10000))*1,([1]OUT_Electricity_CHP!$C$1:$C$10000="Var_Fout")*1,ISNUMBER(SEARCH("ELC",[1]OUT_Electricity_CHP!$D$1:$D$10000))*1,[1]OUT_Electricity_CHP!G$1:G$10000)} -> 65.556939 | I14: {=SUMPRODUCT(ISNUMBER(SEARCH("EHYD-RUN",[1]OUT_Electricity_CHP!$B$1:$B$10000))*1,([1]OUT_Electricity_CHP!$C$1:$C$10000="Var_Fout")*1,ISNUMBER(SEARCH("ELC",[1]OUT_Electricity_CHP!$D$1:$D$10000))*1,[1]OUT_Electricity_CHP!H$1:H$10000)} -> 64.50954 | J14: {=SUMPRODUCT(ISNUMBER(SEARCH("EHYD-RUN",[2]OUT_Electricity_CHP!$B$1:$B$10000))*1,([2]OUT_Electricity_CHP!$C$1:$C$10000="Var_Fout")*1,ISNUMBER(SEARCH("ELC",[2]OUT_Electricity_CHP!$D$1:$D$10000))*1,[2]OUT_Electricity_CHP!I$1:I$10000)} -> 63.812555 | K14: {=SUMPRODUCT(ISNUMBER(SEARCH("EHYD-RUN",[2]OUT_Electricity_CHP!$B$1:$B$10000))*1,([2]OUT_Electricity_CHP!$C$1:$C$10000="Var_Fout")*1,ISNUMBER(SEARCH("ELC",[2]OUT_Electricity_CHP!$D$1:$D$10000))*1,[2]OUT_Electricity_CHP!J$1:J$10000)} -> 62.756544 | L14: {=SUMPRODUCT(ISNUMBER(SEARCH("EHYD-RUN",[2]OUT_Electricity_CHP!$B$1:$B$10000))*1,([2]OUT_Electricity_CHP!$C$1:$C$10000="Var_Fout")*1,ISNUMBER(SEARCH("ELC",[2]OUT_Electricity_CHP!$D$1:$D$10000))*1,[2]OUT_Electricity_CHP!K$1:K$10000)} -> 60.5955
A15: =A14 -> STEM | B15: =B14 -> SPS1 | C15: =C14 -> CH | D15: Primary Production|Hydro|Pump storage | E15: PJ/yr. | F15: {=SUMPRODUCT(ISNUMBER(SEARCH("EHYD-PUM",[1]OUT_Electricity_CHP!$B$1:$B$10000))*1,([1]OUT_Electricity_CHP!$C$1:$C$10000="Var_Fin")*1,ISNUMBER(SEARCH("elc",[1]OUT_Electricity_CHP!$D$1:$D$10000))*1,[1]OUT_Electricity_CHP!E$1:E$10000)} -> 16.052403 | G15: {=SUMPRODUCT(ISNUMBER(SEARCH("EHYD-PUM",[1]OUT_Electricity_CHP!$B$1:$B$10000))*1,([1]OUT_Electricity_CHP!$C$1:$C$10000="Var_Fin")*1,ISNUMBER(SEARCH("elc",[1]OUT_Electricity_CHP!$D$1:$D$10000))*1,[1]OUT_Electricity_CHP!F$1:F$10000)} -> 20.044186 | H15: {=SUMPRODUCT(ISNUMBER(SEARCH("EHYD-PUM",[1]OUT_Electricity_CHP!$B$1:$B$10000))*1,([1]OUT_Electricity_CHP!$C$1:$C$10000="Var_Fin")*1,ISNUMBER(SEARCH("elc",[1]OUT_Electricity_CHP!$D$1:$D$10000))*1,[1]OUT_Electricity_CHP!G$1:G$10000)} -> 2.4937905 | I15: {=SUMPRODUCT(ISNUMBER(SEARCH("EHYD-PUM",[1]OUT_Electricity_CHP!$B$1:$B$10000))*1,([1]OUT_Electricity_CHP!$C$1:$C$10000="Var_Fin")*1,ISNUMBER(SEARCH("elc",[1]OUT_Electricity_CHP!$D$1:$D$10000))*1,[1]OUT_Electricity_CHP!H$1:H$10000)} -> 15.937777 | J15: {=SUMPRODUCT(ISNUMBER(SEARCH("EHYD-PUM",[2]OUT_Electricity_CHP!$B$1:$B$10000))*1,([2]OUT_Electricity_CHP!$C$1:$C$10000="Var_Fin")*1,ISNUMBER(SEARCH("elc",[2]OUT_Electricity_CHP!$D$1:$D$10000))*1,[2]OUT_Electricity_CHP!I$1:I$10000)} -> 15.996159 | K15: {=SUMPRODUCT(ISNUMBER(SEARCH("EHYD-PUM",[2]OUT_Electricity_CHP!$B$1:$B$10000))*1,([2]OUT_Electricity_CHP!$C$1:$C$10000="Var_Fin")*1,ISNUMBER(SEARCH("elc",[2]OUT_Electricity_CHP!$D$1:$D$10000))*1,[2]OUT_Electricity_CHP!J$1:J$10000)} -> 16.112588 | L15: {=SUMPRODUCT(ISNUMBER(SEARCH("EHYD-PUM",[2]OUT_Electricity_CHP!$B$1:$B$10000))*1,([2]OUT_Electricity_CHP!$C$1:$C$10000="Var_Fin")*1,ISNUMBER(SEARCH("elc",[2]OUT_Electricity_CHP!$D$1:$D$10000))*1,[2]OUT_Electricity_CHP!K$1:K$10000)} -> 16.429361
A16: =A15 -> STEM | B16: =B15 -> SPS1 | C16: =C15 -> CH | D16: Primary Production|Solar | E16: PJ/yr. | F16: {=SUMPRODUCT(ISNUMBER(SEARCH("SOL",[1]OUT_PrimaryEnergyCons!$C$1:$C$1000))*1,[1]OUT_PrimaryEnergyCons!D$1:D$1000)} -> 12.556477 | G16: {=SUMPRODUCT(ISNUMBER(SEARCH("SOL",[1]OUT_PrimaryEnergyCons!$C$1:$C$1000))*1,[1]OUT_PrimaryEnergyCons!E$1:E$1000)} -> 16.522292 | H16: {=SUMPRODUCT(ISNUMBER(SEARCH("SOL",[1]OUT_PrimaryEnergyCons!$C$1:$C$1000))*1,[1]OUT_PrimaryEnergyCons!F$1:F$1000)} -> 30.431207 | I16: {=SUMPRODUCT(ISNUMBER(SEARCH("SOL",[1]OUT_PrimaryEnergyCons!$C$1:$C$1000))*1,[1]OUT_PrimaryEnergyCons!G$1:G$1000)} -> 52.839375 | J16: {=SUMPRODUCT(ISNUMBER(SEARCH("SOL",[2]OUT_PrimaryEnergyCons!$C$1:$C$1000))*1,[2]OUT_PrimaryEnergyCons!H$1:H$1000)} -> 56.946944 | K16: {=SUMPRODUCT(ISNUMBER(SEARCH("SOL",[2]OUT_PrimaryEnergyCons!$C$1:$C$1000))*1,[2]OUT_PrimaryEnergyCons!I$1:I$1000)} -> 66.703361 | L16: {=SUMPRODUCT(ISNUMBER(SEARCH("SOL",[2]OUT_PrimaryEnergyCons!$C$1:$C$1000))*1,[2]OUT_PrimaryEnergyCons!J$1:J$1000)} -> 88.976199
A17: =A16 -> STEM | B17: =B16 -> SPS1 | C17: =C16 -> CH | D17: Primary Production|Wind | E17: PJ/yr. | F17: {=SUMPRODUCT(ISNUMBER(SEARCH("wnd",[1]OUT_PrimaryEnergyCons!$C$1:$C$1000))*1,[1]OUT_PrimaryEnergyCons!D$1:D$1000)} -> 0.52400705 | G17: {=SUMPRODUCT(ISNUMBER(SEARCH("wnd",[1]OUT_PrimaryEnergyCons!$C$1:$C$1000))*1,[1]OUT_PrimaryEnergyCons!E$1:E$1000)} -> 0.5452935 | H17: {=SUMPRODUCT(ISNUMBER(SEARCH("wnd",[1]OUT_PrimaryEnergyCons!$C$1:$C$1000))*1,[1]OUT_PrimaryEnergyCons!F$1:F$1000)} -> 0.5031661 | I17: {=SUMPRODUCT(ISNUMBER(SEARCH("wnd",[1]OUT_PrimaryEnergyCons!$C$1:$C$1000))*1,[1]OUT_PrimaryEnergyCons!G$1:G$1000)} -> 2.0502672 | J17: {=SUMPRODUCT(ISNUMBER(SEARCH("wnd",[2]OUT_PrimaryEnergyCons!$C$1:$C$1000))*1,[2]OUT_PrimaryEnergyCons!H$1:H$1000)} -> 2.5953974 | K17: {=SUMPRODUCT(ISNUMBER(SEARCH("wnd",[2]OUT_PrimaryEnergyCons!$C$1:$C$1000))*1,[2]OUT_PrimaryEnergyCons!I$1:I$1000)} -> 2.6721255 | L17: {=SUMPRODUCT(ISNUMBER(SEARCH("wnd",[2]OUT_PrimaryEnergyCons!$C$1:$C$1000))*1,[2]OUT_PrimaryEnergyCons!J$1:J$1000)} -> 3.5104442
A18: =A17 -> STEM | B18: =B17 -> SPS1 | C18: =C17 -> CH | D18: Primary Production|Ambient heat | E18: PJ/yr. | F18: =[1]Overview!B$9-F19 -> 18.873073 | G18: =[1]Overview!C$9-G19 -> 21.778145 | H18: =[1]Overview!D$9-H19 -> 31.839442 | I18: =[1]Overview!E$9-I19 -> 60.120259 | J18: =[2]Overview!F$9-J19 -> 76.168055 | K18: =[2]Overview!G$9-K19 -> 92.249937 | L18: =[2]Overview!H$9-L19 -> 100.33594
A19: =A18 -> STEM | B19: =B18 -> SPS1 | C19: =C18 -> CH | D19: Primary Production|Geothermal | E19: PJ/yr. | F19: =+[1]Overview!B$28 -> 0 | G19: =+[1]Overview!C$28 -> 0 | H19: =+[1]Overview!D$28 -> 0 | I19: =+[1]Overview!E$28 -> 0 | J19: =+[2]Overview!F$28 -> 0 | K19: =+[2]Overview!G$28 -> 0.9452459 | L19: =+[2]Overview!H$28 -> 7.8329289
A20: =A19 -> STEM | B20: =B19 -> SPS1 | C20: =C19 -> CH | D20: Imports | E20: PJ/yr. | F20: =SUM(F21:F22,F41,F50:F51,F56) -> 779.54682 | G20: =SUM(G21:G22,G41,G50:G51,G56) -> 700.24613 | H20: =SUM(H21:H22,H41,H50:H51,H56) -> 648.99723 | I20: =SUM(I21:I22,I41,I50:I51,I56) -> 505.13175 | J20: =SUM(J21:J22,J41,J50:J51,J56) -> 403.16892 | K20: =SUM(K21:K22,K41,K50:K51,K56) -> 338.16073 | L20: =SUM(L21:L22,L41,L50:L51,L56) -> 239.19106
A21: =A20 -> STEM | B21: =B20 -> SPS1 | C21: =C20 -> CH | D21: Imports|Coal | E21: PJ/yr. | F21: {=SUMPRODUCT(("COA"=[1]OUT_PrimaryEnergyCons!$C$4:$C$10000)*1,[1]OUT_PrimaryEnergyCons!D$4:D$10000)} -> 3.6600076 | G21: {=SUMPRODUCT(("COA"=[1]OUT_PrimaryEnergyCons!$C$4:$C$10000)*1,[1]OUT_PrimaryEnergyCons!E$4:E$10000)} -> 3.5647186 | H21: {=SUMPRODUCT(("COA"=[1]OUT_PrimaryEnergyCons!$C$4:$C$10000)*1,[1]OUT_PrimaryEnergyCons!F$4:F$10000)} -> 0.054973938 | I21: {=SUMPRODUCT(("COA"=[1]OUT_PrimaryEnergyCons!$C$4:$C$10000)*1,[1]OUT_PrimaryEnergyCons!G$4:G$10000)} -> 0.0010527247 | J21: {=SUMPRODUCT(("COA"=[2]OUT_PrimaryEnergyCons!$C$4:$C$10000)*1,[2]OUT_PrimaryEnergyCons!H$4:H$10000)} -> 0.020150877 | K21: {=SUMPRODUCT(("COA"=[2]OUT_PrimaryEnergyCons!$C$4:$C$10000)*1,[2]OUT_PrimaryEnergyCons!I$4:I$10000)} -> 0.28463759 | L21: {=SUMPRODUCT(("COA"=[2]OUT_PrimaryEnergyCons!$C$4:$C$10000)*1,[2]OUT_PrimaryEnergyCons!J$4:J$10000)} -> 0.029311515
A22: =A21 -> STEM | B22: =B21 -> SPS1 | C22: =C21 -> CH | D22: Imports|Oil | E22: PJ/yr. | F22: =F23+F29 -> 310.61884 | G22: =G23+G29 -> 285.86973 | H22: =H23+H29 -> 260.96912 | I22: =I23+I29 -> 166.66713 | J22: =J23+J29 -> 107.40377 | K22: =K23+K29 -> 75.396901 | L22: =L23+L29 -> 82.835222
A23: =A22 -> STEM | B23: =B22 -> SPS1 | C23: =C22 -> CH | D23: Imports|Oil|Fossil liquids | E23: PJ/yr. | F23: =SUM(F24:F28) -> 303.82415 | G23: =SUM(G24:G28) -> 279.19776 | H23: =SUM(H24:H28) -> 253.20273 | I23: =SUM(I24:I28) -> 154.77554 | J23: =SUM(J24:J28) -> 86.14251 | K23: =SUM(K24:K28) -> 43.536463 | L23: =SUM(L24:L28) -> 0
A24: =A22 -> STEM | B24: =B22 -> SPS1 | C24: =C22 -> CH | D24: Imports|Oil|Fossil liquids|Light fuel oil | E24: PJ/yr. | F24: {=SUMPRODUCT(("LFO"=[1]OUT_PrimaryEnergyCons!$C$4:$C$10000)*1,[1]OUT_PrimaryEnergyCons!D$4:D$10000)} -> 101.75572 | G24: {=SUMPRODUCT(("LFO"=[1]OUT_PrimaryEnergyCons!$C$4:$C$10000)*1,[1]OUT_PrimaryEnergyCons!E$4:E$10000)} -> 88.5325 | H24: {=SUMPRODUCT(("LFO"=[1]OUT_PrimaryEnergyCons!$C$4:$C$10000)*1,[1]OUT_PrimaryEnergyCons!F$4:F$10000)} -> 84.575681 | I24: {=SUMPRODUCT(("LFO"=[1]OUT_PrimaryEnergyCons!$C$4:$C$10000)*1,[1]OUT_PrimaryEnergyCons!G$4:G$10000)} -> 43.129145 | J24: {=SUMPRODUCT(("LFO"=[2]OUT_PrimaryEnergyCons!$C$4:$C$10000)*1,[2]OUT_PrimaryEnergyCons!H$4:H$10000)} -> 29.116465 | K24: {=SUMPRODUCT(("LFO"=[2]OUT_PrimaryEnergyCons!$C$4:$C$10000)*1,[2]OUT_PrimaryEnergyCons!I$4:I$10000)} -> 14.465885 | L24: {=SUMPRODUCT(("LFO"=[2]OUT_PrimaryEnergyCons!$C$4:$C$10000)*1,[2]OUT_PrimaryEnergyCons!J$4:J$10000)} -> 0
A25: =A24 -> STEM | B25: =B24 -> SPS1 | C25: =C24 -> CH | D25: Imports|Oil|Fossil liquids|Heavy fuel oil | E25: PJ/yr. | F25: {=SUMPRODUCT(("HFO"=[1]OUT_PrimaryEnergyCons!$C$4:$C$10000)*1,[1]OUT_PrimaryEnergyCons!D$4:D$10000)} -> 2.7763749 | G25: {=SUMPRODUCT(("HFO"=[1]OUT_PrimaryEnergyCons!$C$4:$C$10000)*1,[1]OUT_PrimaryEnergyCons!E$4:E$10000)} -> 2.4460037 | H25: {=SUMPRODUCT(("HFO"=[1]OUT_PrimaryEnergyCons!$C$4:$C$10000)*1,[1]OUT_PrimaryEnergyCons!F$4:F$10000)} -> 0.0041067018 | I25: {=SUMPRODUCT(("HFO"=[1]OUT_PrimaryEnergyCons!$C$4:$C$10000)*1,[1]OUT_PrimaryEnergyCons!G$4:G$10000)} -> 0.00073389114 | J25: {=SUMPRODUCT(("HFO"=[2]OUT_PrimaryEnergyCons!$C$4:$C$10000)*1,[2]OUT_PrimaryEnergyCons!H$4:H$10000)} -> 0.034993389 | K25: {=SUMPRODUCT(("HFO"=[2]OUT_PrimaryEnergyCons!$C$4:$C$10000)*1,[2]OUT_PrimaryEnergyCons!I$4:I$10000)} -> 0.14368631 | L25: {=SUMPRODUCT(("HFO"=[2]OUT_PrimaryEnergyCons!$C$4:$C$10000)*1,[2]OUT_PrimaryEnergyCons!J$4:J$10000)} -> 0
A26: =A25 -> STEM | B26: =B25 -> SPS1 | C26: =C25 -> CH | D26: Imports|Oil|Fossil liquids|Motor Diesel | E26: PJ/yr. | F26: {=SUMPRODUCT(("DSL"=[1]OUT_PrimaryEnergyCons!$C$4:$C$10000)*1,[1]OUT_PrimaryEnergyCons!D$4:D$10000)} -> 118.02136 | G26: {=SUMPRODUCT(("DSL"=[1]OUT_PrimaryEnergyCons!$C$4:$C$10000)*1,[1]OUT_PrimaryEnergyCons!E$4:E$10000)} -> 112.67289 | H26: {=SUMPRODUCT(("DSL"=[1]OUT_PrimaryEnergyCons!$C$4:$C$10000)*1,[1]OUT_PrimaryEnergyCons!F$4:F$10000)} -> 95.833137 | I26: {=SUMPRODUCT(("DSL"=[1]OUT_PrimaryEnergyCons!$C$4:$C$10000)*1,[1]OUT_PrimaryEnergyCons!G$4:G$10000)} -> 66.372911 | J26: {=SUMPRODUCT(("DSL"=[2]OUT_PrimaryEnergyCons!$C$4:$C$10000)*1,[2]OUT_PrimaryEnergyCons!H$4:H$10000)} -> 36.899654 | K26: {=SUMPRODUCT(("DSL"=[2]OUT_PrimaryEnergyCons!$C$4:$C$10000)*1,[2]OUT_PrimaryEnergyCons!I$4:I$10000)} -> 19.63074 | L26: {=SUMPRODUCT(("DSL"=[2]OUT_PrimaryEnergyCons!$C$4:$C$10000)*1,[2]OUT_PrimaryEnergyCons!J$4:J$10000)} -> 0
A27: =A26 -> STEM | B27: =B26 -> SPS1 | C27: =C26 -> CH | D27: Imports|Oil|Fossil liquids|Motor Gasoline | E27: PJ/yr. | F27: {=SUMPRODUCT(("GSL"=[1]OUT_PrimaryEnergyCons!$C$4:$C$10000)*1,[1]OUT_PrimaryEnergyCons!D$4:D$10000)} -> 80.162897 | G27: {=SUMPRODUCT(("GSL"=[1]OUT_PrimaryEnergyCons!$C$4:$C$10000)*1,[1]OUT_PrimaryEnergyCons!E$4:E$10000)} -> 74.141235 | H27: {=SUMPRODUCT(("GSL"=[1]OUT_PrimaryEnergyCons!$C$4:$C$10000)*1,[1]OUT_PrimaryEnergyCons!F$4:F$10000)} -> 70.941915 | I27: {=SUMPRODUCT(("GSL"=[1]OUT_PrimaryEnergyCons!$C$4:$C$10000)*1,[1]OUT_PrimaryEnergyCons!G$4:G$10000)} -> 42.689455 | J27: {=SUMPRODUCT(("GSL"=[2]OUT_PrimaryEnergyCons!$C$4:$C$10000)*1,[2]OUT_PrimaryEnergyCons!H$4:H$10000)} -> 17.572859 | K27: {=SUMPRODUCT(("GSL"=[2]OUT_PrimaryEnergyCons!$C$4:$C$10000)*1,[2]OUT_PrimaryEnergyCons!I$4:I$10000)} -> 7.1791395 | L27: {=SUMPRODUCT(("GSL"=[2]OUT_PrimaryEnergyCons!$C$4:$C$10000)*1,[2]OUT_PrimaryEnergyCons!J$4:J$10000)} -> 0
A28: =A27 -> STEM | B28: =B27 -> SPS1 | C28: =C27 -> CH | D28: Imports|Oil|Fossil liquids|Kerosene (excl. international aviation) | E28: PJ/yr. | F28: {=SUMPRODUCT(("KER"=[1]OUT_PrimaryEnergyCons!$C$4:$C$10000)*1,[1]OUT_PrimaryEnergyCons!D$4:D$10000)} -> 1.1078033 | G28: {=SUMPRODUCT(("KER"=[1]OUT_PrimaryEnergyCons!$C$4:$C$10000)*1,[1]OUT_PrimaryEnergyCons!E$4:E$10000)} -> 1.4051293 | H28: {=SUMPRODUCT(("KER"=[1]OUT_PrimaryEnergyCons!$C$4:$C$10000)*1,[1]OUT_PrimaryEnergyCons!F$4:F$10000)} -> 1.8478954 | I28: {=SUMPRODUCT(("KER"=[1]OUT_PrimaryEnergyCons!$C$4:$C$10000)*1,[1]OUT_PrimaryEnergyCons!G$4:G$10000)} -> 2.5832945 | J28: {=SUMPRODUCT(("KER"=[2]OUT_PrimaryEnergyCons!$C$4:$C$10000)*1,[2]OUT_PrimaryEnergyCons!H$4:H$10000)} -> 2.5185396 | K28: {=SUMPRODUCT(("KER"=[2]OUT_PrimaryEnergyCons!$C$4:$C$10000)*1,[2]OUT_PrimaryEnergyCons!I$4:I$10000)} -> 2.1170127 | L28: {=SUMPRODUCT(("KER"=[2]OUT_PrimaryEnergyCons!$C$4:$C$10000)*1,[2]OUT_PrimaryEnergyCons!J$4:J$10000)} -> 0
A29: =A50 -> STEM | B29: =B50 -> SPS1 | C29: =C50 -> CH | D29: Imports|Oil|Synthetic liquids | E29: PJ/yr. | F29: =SUM(F30:F32) -> 6.7946892 | G29: =SUM(G30:G32) -> 6.6719752 | H29: =SUM(H30:H32) -> 7.766388 | I29: =SUM(I30:I32) -> 11.89159 | J29: =SUM(J30:J32) -> 21.261262 | K29: =SUM(K30:K32) -> 31.860438 | L29: =SUM(L30:L32) -> 82.835222
A30: =A37 -> STEM | B30: =B37 -> SPS1 | C30: =C37 -> CH | D30: Imports|Oil|Synthetic liquids|Total|Motor diesel | E30: PJ/yr. | F30: {=SUMPRODUCT(ISNUMBER(SEARCH("IMPBDS",[1]OUT_SyntheticFuels!$C$4:$C$1000))*1,("Var_Fout"=[1]OUT_SyntheticFuels!$B$4:$B$1000)*1,[1]OUT_SyntheticFuels!E$4:E$1000)-F32} -> 2.3589789 | G30: {=SUMPRODUCT(ISNUMBER(SEARCH("IMPBDS",[1]OUT_SyntheticFuels!$C$4:$C$1000))*1,("Var_Fout"=[1]OUT_SyntheticFuels!$B$4:$B$1000)*1,[1]OUT_SyntheticFuels!F$4:F$1000)-G32} -> 2.3779262 | H30: {=SUMPRODUCT(ISNUMBER(SEARCH("IMPBDS",[1]OUT_SyntheticFuels!$C$4:$C$1000))*1,("Var_Fout"=[1]OUT_SyntheticFuels!$B$4:$B$1000)*1,[1]OUT_SyntheticFuels!G$4:G$1000)-H32} -> 3.8651797 | I30: {=SUMPRODUCT(ISNUMBER(SEARCH("IMPBDS",[1]OUT_SyntheticFuels!$C$4:$C$1000))*1,("Var_Fout"=[1]OUT_SyntheticFuels!$B$4:$B$1000)*1,[1]OUT_SyntheticFuels!H$4:H$1000)-I32} -> 4.4028643 | J30: {=SUMPRODUCT(ISNUMBER(SEARCH("IMPBDS",[2]OUT_SyntheticFuels!$C$4:$C$1000))*1,("Var_Fout"=[2]OUT_SyntheticFuels!$B$4:$B$1000)*1,[2]OUT_SyntheticFuels!I$4:I$1000)-J32} -> 3.6421168 | K30: {=SUMPRODUCT(ISNUMBER(SEARCH("IMPBDS",[2]OUT_SyntheticFuels!$C$4:$C$1000))*1,("Var_Fout"=[2]OUT_SyntheticFuels!$B$4:$B$1000)*1,[2]OUT_SyntheticFuels!J$4:J$1000)-K32} -> 3.6249416 | L30: {=SUMPRODUCT(ISNUMBER(SEARCH("IMPBDS",[2]OUT_SyntheticFuels!$C$4:$C$1000))*1,("Var_Fout"=[2]OUT_SyntheticFuels!$B$4:$B$1000)*1,[2]OUT_SyntheticFuels!K$4:K$1000)-L32} -> 4.3377205
A31: =A30 -> STEM | B31: =B30 -> SPS1 | C31: =C30 -> CH | D31: Imports|Oil|Synthetic liquids|Total|Motor Gasoline | E31: PJ/yr. | F31: {=SUMPRODUCT(ISNUMBER(SEARCH("IMPeth",[1]OUT_SyntheticFuels!$C$4:$C$1000))*1,("Var_Fout"=[1]OUT_SyntheticFuels!$B$4:$B$1000)*1,[1]OUT_SyntheticFuels!E$4:E$1000)} -> 4.4341504 | G31: {=SUMPRODUCT(ISNUMBER(SEARCH("IMPeth",[1]OUT_SyntheticFuels!$C$4:$C$1000))*1,("Var_Fout"=[1]OUT_SyntheticFuels!$B$4:$B$1000)*1,[1]OUT_SyntheticFuels!F$4:F$1000)} -> 4.2939626 | H31: {=SUMPRODUCT(ISNUMBER(SEARCH("IMPeth",[1]OUT_SyntheticFuels!$C$4:$C$1000))*1,("Var_Fout"=[1]OUT_SyntheticFuels!$B$4:$B$1000)*1,[1]OUT_SyntheticFuels!G$4:G$1000)} -> 3.9001597 | I31: {=SUMPRODUCT(ISNUMBER(SEARCH("IMPeth",[1]OUT_SyntheticFuels!$C$4:$C$1000))*1,("Var_Fout"=[1]OUT_SyntheticFuels!$B$4:$B$1000)*1,[1]OUT_SyntheticFuels!H$4:H$1000)} -> 2.4724734 | J31: {=SUMPRODUCT(ISNUMBER(SEARCH("IMPeth",[2]OUT_SyntheticFuels!$C$4:$C$1000))*1,("Var_Fout"=[2]OUT_SyntheticFuels!$B$4:$B$1000)*1,[2]OUT_SyntheticFuels!I$4:I$1000)} -> 1.0704943 | K31: {=SUMPRODUCT(ISNUMBER(SEARCH("IMPeth",[2]OUT_SyntheticFuels!$C$4:$C$1000))*1,("Var_Fout"=[2]OUT_SyntheticFuels!$B$4:$B$1000)*1,[2]OUT_SyntheticFuels!J$4:J$1000)} -> 0.43487139 | L31: {=SUMPRODUCT(ISNUMBER(SEARCH("IMPeth",[2]OUT_SyntheticFuels!$C$4:$C$1000))*1,("Var_Fout"=[2]OUT_SyntheticFuels!$B$4:$B$1000)*1,[2]OUT_SyntheticFuels!K$4:K$1000)} -> 0.91614003
B32: =B31 -> SPS1 | C32: =C31 -> CH | D32: Imports|Oil|Synthetic liquids|Total|Kerosene | E32: PJ/yr. | F32: =SUM([1]Transport_Aviation_Intl!B$12,[1]Transport!B$28) -> 0.0015598627 | G32: =SUM([1]Transport_Aviation_Intl!C$12,[1]Transport!C$28) -> 8.6437937e-05 | H32: =SUM([1]Transport_Aviation_Intl!D$12,[1]Transport!D$28) -> 0.0010485713 | I32: =SUM([1]Transport_Aviation_Intl!E$12,[1]Transport!E$28) -> 5.0162524 | J32: =SUM([2]Transport_Aviation_Intl!F$12,[2]Transport!F$28) -> 16.548651 | K32: =SUM([2]Transport_Aviation_Intl!G$12,[2]Transport!G$28) -> 27.800625 | L32: =SUM([2]Transport_Aviation_Intl!H$12,[2]Transport!H$28) -> 77.581361
A33: =A29 -> STEM | B33: =B29 -> SPS1 | C33: =C29 -> CH | D33: Imports|Oil|Synthetic liquids|Bioliquids|Total | E33: PJ/yr. | F33: =SUM(F34:F36) -> 6.7946892 | G33: =SUM(G34:G36) -> 6.6719752 | H33: =SUM(H34:H36) -> 7.766388 | I33: =SUM(I34:I36) -> 11.89159 | J33: =SUM(J34:J36) -> 9.7288635 | K33: =SUM(K34:K36) -> 20.608464 | L33: =SUM(L34:L36) -> 33.054485
A34: =A31 -> STEM | B34: =B31 -> SPS1 | C34: =C31 -> CH | D34: Imports|Oil|Synthetic liquids|Bioliquids|Biodiesel | E34: PJ/yr. | F34: =F30 -> 2.3589789 | G34: =G30 -> 2.3779262 | H34: =H30 -> 3.8651797 | I34: =I30 -> 4.4028643 | J34: =IF(J30-MAX(F30:I30)<0,J30,MAX(F30:I30)) -> 3.6421168 | K34: =IF(K30-MAX(F30:J30)<0,K30,MAX(F30:J30)) -> 3.6249416 | L34: =IF(L30-MAX(G30:K30)<0,L30,MAX(G30:K30)) -> 4.3377205
A35: =A34 -> STEM | B35: =B34 -> SPS1 | C35: =C34 -> CH | D35: Imports|Oil|Synthetic liquids|Bioliquids|Ethanol | E35: PJ/yr. | F35: =F31 -> 4.4341504 | G35: =G31 -> 4.2939626 | H35: =H31 -> 3.9001597 | I35: =I31 -> 2.4724734 | J35: =IF(J31-MAX(F31:I31)<0,J31,MAX(F31:I31)) -> 1.0704943 | K35: =IF(K31-MAX(F31:J31)<0,K31,MAX(F31:J31)) -> 0.43487139 | L35: =IF(L31-MAX(G31:K31)<0,L31,MAX(G31:K31)) -> 0.91614003
B36: =B35 -> SPS1 | C36: =C35 -> CH | D36: Imports|Oil|Synthetic liquids|Bioliquids|Biokerosene | E36: PJ/yr. | F36: =SUM([1]Transport!B$28,[1]Transport_Aviation_Intl!B$12) -> 0.0015598627 | G36: =SUM([1]Transport!C$28,[1]Transport_Aviation_Intl!C$12) -> 8.6437937e-05 | H36: =SUM([1]Transport!D$28,[1]Transport_Aviation_Intl!D$12) -> 0.0010485713 | I36: =SUM([1]Transport!E$28,[1]Transport_Aviation_Intl!E$12) -> 5.0162524 | J36: =IF(J32-MAX(F32:I32)<0,J32,MAX(F32:I32)) -> 5.0162524 | K36: =IF(K32-MAX(G32:J32)<0,K32,MAX(G32:J32)) -> 16.548651 | L36: =IF(L32-MAX(H32:K32)<0,L32,MAX(H32:K32)) -> 27.800625
A37: =A33 -> STEM | B37: =B33 -> SPS1 | C37: =C33 -> CH | D37: Imports|Oil|Synthetic liquids|PtL|Total | E37: PJ/yr. | F37: =SUM(F38:F40) -> 0 | G37: =SUM(G38:G40) -> 0 | H37: =SUM(H38:H40) -> 0 | I37: =SUM(I38:I40) -> 0 | J37: =SUM(J38:J40) -> 11.532398 | K37: =SUM(K38:K40) -> 11.251974 | L37: =SUM(L38:L40) -> 49.780736
A38: =A35 -> STEM | B38: =B35 -> SPS1 | C38: =C35 -> CH | D38: Imports|Oil|Synthetic liquids|PtL|PtL Diesel | E38: PJ/yr. | F38: 0 | G38: 0 | H38: 0 | I38: 0 | J38: =J30-J34 -> 0 | K38: =K30-K34 -> 0 | L38: =L30-L34 -> 0
A39: =A38 -> STEM | B39: =B38 -> SPS1 | C39: =C38 -> CH | D39: Imports|Oil|Synthetic liquids|PtL|PtL Gasoline | E39: PJ/yr. | F39: 0 | G39: 0 | H39: 0 | I39: 0 | J39: =J31-J35 -> 0 | K39: =K31-K35 -> 0 | L39: =L31-L35 -> 0
B40: =B39 -> SPS1 | C40: =C39 -> CH | D40: Imports|Oil|Synthetic liquids|PtL|PtL Kerosene | E40: PJ/yr. | F40: 0 | G40: 0 | H40: 0 | I40: 0 | J40: =J32-J36 -> 11.532398 | K40: =K32-K36 -> 11.251974 | L40: =L32-L36 -> 49.780736
...

Sheet check
C2: 2020 | D2: 2022 | E2: 2025 | F2: 2030 | G2: 2040 | H2: 2050
B3: Final energy consumption | C3: =SUM(C4:C7) -> 716.07429 | D3: =SUM(D4:D7) -> 704.33244 | E3: =SUM(E4:E7) -> 688.8453 | F3: =SUM(F4:F7) -> 613.27313 | G3: =SUM(G4:G7) -> 563.94143 | H3: =SUM(H4:H7) -> 533.2286
B4: Industry | C4: =SPS1_NUC_Low!F763 -> 142.21747 | D4: =SPS1_NUC_Low!G763 -> 142.38203 | E4: =SPS1_NUC_Low!H763 -> 147.28191 | F4: =SPS1_NUC_Low!I763 -> 144.69018 | G4: =SPS1_NUC_Low!J763 -> 145.07087 | H4: =SPS1_NUC_Low!K763 -> 145.18222
B5: Services | C5: =SPS1_NUC_Low!F882 -> 140.10112 | D5: =SPS1_NUC_Low!G882 -> 139.62165 | E5: =SPS1_NUC_Low!H882 -> 132.90645 | F5: =SPS1_NUC_Low!I882 -> 121.43806 | G5: =SPS1_NUC_Low!J882 -> 115.21577 | H5: =SPS1_NUC_Low!K882 -> 108.7197
B6: Residential | C6: =SPS1_NUC_Low!F972 -> 219.89599 | D6: =SPS1_NUC_Low!G972 -> 217.90797 | E6: =SPS1_NUC_Low!H972 -> 219.91416 | F6: =SPS1_NUC_Low!I972 -> 200.58035 | G6: =SPS1_NUC_Low!J972 -> 190.87651 | H6: =SPS1_NUC_Low!K972 -> 182.13459
B7: Transport | C7: =SPS1_NUC_Low!F1136+SPS1_NUC_Low!F1315+SPS1_NUC_Low!F1399+SPS1_NUC_Low!F1483+SPS1_NUC_Low!F1490+SPS1_NUC_Low!F1497+SPS1_NUC_Low!F1546+SPS1_NUC_Low!F1593+SPS1_NUC_Low!F1640 -> 213.85972 | D7: =SPS1_NUC_Low!G1136+SPS1_NUC_Low!G1315+SPS1_NUC_Low!G1399+SPS1_NUC_Low!G1483+SPS1_NUC_Low!G1490+SPS1_NUC_Low!G1497+SPS1_NUC_Low!G1546+SPS1_NUC_Low!G1593+SPS1_NUC_Low!G1640 -> 204.42078 | E7: =SPS1_NUC_Low!H1136+SPS1_NUC_Low!H1315+SPS1_NUC_Low!H1399+SPS1_NUC_Low!H1483+SPS1_NUC_Low!H1490+SPS1_NUC_Low!H1497+SPS1_NUC_Low!H1546+SPS1_NUC_Low!H1593+SPS1_NUC_Low!H1640 -> 188.74278 | F7: =SPS1_NUC_Low!I1136+SPS1_NUC_Low!I1315+SPS1_NUC_Low!I1399+SPS1_NUC_Low!I1483+SPS1_NUC_Low!I1490+SPS1_NUC_Low!I1497+SPS1_NUC_Low!I1546+SPS1_NUC_Low!I1593+SPS1_NUC_Low!I1640 -> 146.56454 | G7: =SPS1_NUC_Low!J1136+SPS1_NUC_Low!J1315+SPS1_NUC_Low!J1399+SPS1_NUC_Low!J1483+SPS1_NUC_Low!J1490+SPS1_NUC_Low!J1497+SPS1_NUC_Low!J1546+SPS1_NUC_Low!J1593+SPS1_NUC_Low!J1640 -> 112.77828 | H7: =SPS1_NUC_Low!K1136+SPS1_NUC_Low!K1315+SPS1_NUC_Low!K1399+SPS1_NUC_Low!K1483+SPS1_NUC_Low!K1490+SPS1_NUC_Low!K1497+SPS1_NUC_Low!K1546+SPS1_NUC_Low!K1593+SPS1_NUC_Low!K1640 -> 97.192089
B8: Fuel input to energy conversion and DAC | C8: =SUM(C9:C12) -> 509.7174 | D8: =SUM(D9:D12) -> 494.96785 | E8: =SUM(E9:E12) -> 502.86503 | F8: =SUM(F9:F12) -> 523.51466 | G8: =SUM(G9:G12) -> 527.46588 | H8: =SUM(H9:H12) -> 539.16959
B9: Electricity and heat | C9: =SPS1_NUC_Low!F291+SPS1_NUC_Low!F409 -> 493.53799 | D9: =SPS1_NUC_Low!G291+SPS1_NUC_Low!G409 -> 472.86874 | E9: =SPS1_NUC_Low!H291+SPS1_NUC_Low!H409 -> 477.70736 | F9: =SPS1_NUC_Low!I291+SPS1_NUC_Low!I409 -> 498.93478 | G9: =SPS1_NUC_Low!J291+SPS1_NUC_Low!J409 -> 490.63826 | H9: =SPS1_NUC_Low!K291+SPS1_NUC_Low!K409 -> 501.00537
B10: Biofuel production | C10: =SPS1_NUC_Low!F590+SPS1_NUC_Low!F604+SPS1_NUC_Low!F644 -> 16.174351 | D10: =SPS1_NUC_Low!G590+SPS1_NUC_Low!G604+SPS1_NUC_Low!G644 -> 22.09116 | E10: =SPS1_NUC_Low!H590+SPS1_NUC_Low!H604+SPS1_NUC_Low!H644 -> 25.149853 | F10: =SPS1_NUC_Low!I590+SPS1_NUC_Low!I604+SPS1_NUC_Low!I644 -> 24.442029 | G10: =SPS1_NUC_Low!J590+SPS1_NUC_Low!J604+SPS1_NUC_Low!J644 -> 25.624644 | H10: =SPS1_NUC_Low!K590+SPS1_NUC_Low!K604+SPS1_NUC_Low!K644 -> 27.351945
B11: Hydrogen production | C11: =SPS1_NUC_Low!F679 -> 0.005059399 | D11: =SPS1_NUC_Low!G679 -> 0.007948347 | E11: =SPS1_NUC_Low!H679 -> 0.0078176785 | F11: =SPS1_NUC_Low!I679 -> 0.13784878 | G11: =SPS1_NUC_Low!J679 -> 11.202976 | H11: =SPS1_NUC_Low!K679 -> 10.809769
B12: DAC | C12: =SPS1_NUC_Low!F1707 -> 0 | D12: =SPS1_NUC_Low!G1707 -> 0 | E12: =SPS1_NUC_Low!H1707 -> 0 | F12: =SPS1_NUC_Low!I1707 -> 0 | G12: =SPS1_NUC_Low!J1707 -> 0 | H12: =SPS1_NUC_Low!K1707 -> 0.0025044437
B13: Total Primary energy consumption | C13: =SPS1_NUC_Low!F2+SPS1_NUC_Low!F20-SPS1_NUC_Low!F57 -> 962.56289 | D13: =SPS1_NUC_Low!G2+SPS1_NUC_Low!G20-SPS1_NUC_Low!G57 -> 957.97354 | E13: =SPS1_NUC_Low!H2+SPS1_NUC_Low!H20-SPS1_NUC_Low!H57 -> 907.77865 | F13: =SPS1_NUC_Low!I2+SPS1_NUC_Low!I20-SPS1_NUC_Low!I57 -> 835.25478 | G13: =SPS1_NUC_Low!J2+SPS1_NUC_Low!J20-SPS1_NUC_Low!J57 -> 787.38076 | H13: =SPS1_NUC_Low!K2+SPS1_NUC_Low!K20-SPS1_NUC_Low!K57 -> 768.46883
B14: Domestic production | C14: =SPS1_NUC_Low!F2 -> 300.18609 | D14: =SPS1_NUC_Low!G2 -> 292.84408 | E14: =SPS1_NUC_Low!H2 -> 331.72196 | F14: =SPS1_NUC_Low!I2 -> 399.67808 | G14: =SPS1_NUC_Low!J2 -> 423.00398 | H14: =SPS1_NUC_Low!K2 -> 452.22188
B15: Imports | C15: =SPS1_NUC_Low!F20 -> 779.54682 | D15: =SPS1_NUC_Low!G20 -> 700.24613 | E15: =SPS1_NUC_Low!H20 -> 648.99723 | F15: =SPS1_NUC_Low!I20 -> 505.13175 | G15: =SPS1_NUC_Low!J20 -> 403.16892 | H15: =SPS1_NUC_Low!K20 -> 338.16073
B16: Exports | C16: =SPS1_NUC_Low!F57 -> 117.17001 | D16: =SPS1_NUC_Low!G57 -> 35.116679 | E16: =SPS1_NUC_Low!H57 -> 72.940551 | F16: =SPS1_NUC_Low!I57 -> 69.555053 | G16: =SPS1_NUC_Low!J57 -> 38.792136 | H16: =SPS1_NUC_Low!K57 -> 21.913789
